Workbook
Name copy: #REF!
Name copy1: #REF!
Name Go_To_Sheet: #REF!
Name loai_1: #REF!
Name loai_1_name: #REF!

Sheet File Sheets Summary
A1: STT | B1: Nội dung tài liệu | C1: Sheet
A2: 1 | B2: Trang bìa tài liệu | C2: Cover
A3: 2 | B3: Danh sách và mô tả tất cả các sheet trong file | C3: File Sheets Summary
A4: 3 | B4: Tổng hợp tiến độ thiết kế toàn bộ Data Vault | C4: Summary Tracking
A5: 4 | B5: Tracking tiến độ mapping và phát triển Data Vault | C5: Tracking Mapping&Dev Vault
A6: 5 | B6: Danh sách các bảng dữ liệu nguồn được đưa lên Silver | C6: Source Table
A7: 6 | B7: Tổng hợp danh sách các bảng Raw Vault | C7: Summary Raw Vault
A8: 7 | B8: Tổng hợp danh sách các bảng Business Vault | C8: Summary Business Vault
A9: 8 | B9: Nguyên tắc và quy tắc thiết kế mô hình dữ liệu Data Vault | C9: Rules
A10: 9 | B10: Thống kê chi tiết trạng thái Mapping | C10: Mapping Statistics
A11: 10 | B11: Mapping chi tiết từ T24 sang Data Vault (hiện tại) | C11: T24 Vault Mapping
A12: 11 | B12: Mapping chi tiết từ WAY4 sang Data Vault | C12: WAY4 Vault Mapping
A13: 12 | B13: Mapping chi tiết từ OMNI sang Data Vault | C13: OMNI Vault Mapping
... A20: 19 | B20: Thống kê chi tiết trạng thái Mapping (bản bổ sung) | C20: Mapping Statistics
B22: Bổ sung thêm sheet khảo sát chi tiết các bảng lỗi từ source | C22: Hỏi Linh, thêm các sheet làm việc với T24 để làm rõ cacsc bảng bị lỗi dữ liệu từ nguồn
B23: Bổ sung thêm sheet v_stg_ | C23: hashdiff | D23: HA làm
C24: filter
C25: Note

Sheet Summary Raw Vault_old
A6: Source | B6: Group | C6: Table Name | D6: Description
A7: T24, Way4, Omni, BPM | B7: REFERENCE | C7: reference | D7: Bảng tổng hợp tất cả các bảng danh mục chứa thông tin mô tả và phân loại từ các nguồn T24, Way4, Omni, BPM
A8: T24 | B8: COLLATERAL | C8: hub_collateral | D8: Bảng định danh mã tài sản đảm bảo (TSĐB)
A9: T24 | B9: COLLATERAL | C9: sat_collateral_information | D9: Thông tin chung tài sản đảm bảo (Loại, mô tả, mã, trạng thái tài sản,...)
A10: T24 | B10: COLLATERAL | C10: sat_collateral_valuation | D10: Thông tin định giá tài sản đảm bảo (Loại tiền, giá trị danh nghĩa, đảm bảo, ghi sổ,...)
A11: T24 | B11: COLLATERAL | C11: sat_collateral_insurance | D11: Thông tin hợp đồng bảo hiểm của TSĐB (Tài sản phải mua bảo hiểm, số hợp đồng bảo hiểm, sản phẩm bảo hiểm,...)
A12: T24 | B12: COLLATERAL | C12: sat_collateral_vehicle | D12: Thông tin tài sản đảm bảo là phương tiện
A13: T24 | B13: COLLATERAL | C13: sat_collateral_instrument | D13: Thông tin tài sản đảm bảo là chứng khoán
A14: T24 | B14: COLLATERAL | C14: sat_collateral_real_estate | D14: Thông tin tài sản đảm bảo là bất động sản
A15: T24 | B15: COLLATERAL | C15: sat_collateral_other | D15: Thông tin khác về TSĐB (Địa điểm lưu kho, Số tài khoản tham chiếu, Số hợp đồng thế chấp TSĐB)
A16: T24 | B16: COLLATERAL | C16: link_collateral_branch | D16: Liên kết tài sản đảm bảo với chi nhánh
A17: T24 | B17: COLLATERAL | C17: link_collateral_man_branch | D17: Liên kết tài sản đảm bảo với chi nhánh quản lý tài sản
... A522: BPM | B522: TSBD | C522: link_tsbd_giaodich_chinh_khach_hang | D522: Liên kết giữa khách hàng và giao dịch tài sản bảo đảm

Sheet Source Table
A1: Source | B1: Table Name in Source | C1: Description | D1: Phase | E1: Reference | F1: Note
A2: T24 | B2: t24_customer | C2: Bảng master thông tin khách hàng | D2: Phase 1
A3: T24 | B3: t24_account | C3: Bảng master thông tin tài khoản (bao gồm tài khoản CASA, tài khoản deposits, tài khoản nội bộ của OCB,...) | D3: Phase 1
A4: T24 | B4: t24_account_closed | C4: Bảng tài khoản đã đóng (các tài khoản khách hàng đã đóng) | D4: Phase 1
A5: T24 | B5: t24_account_credit_int | C5: Bảng lãi suất trên số dư nợ cho từng tài khoản | D5: Phase 1
A6: T24 | B6: t24_account_debit_int | C6: Bảng lãi suất trên số dư có cho từng tài khoản | D6: Phase 1
A7: T24 | B7: t24_accr_acct_cr | C7: Bảng khai báo lãi suất trên số dư có cho từng tài khoản | D7: Phase 2
A8: T24 | B8: t24_accr_acct_dr | C8: Bảng khai báo lãi suất trên số dư nợ cho từng tài khoản | D8: Phase 2
A9: T24 | B9: t24_acct_activity | C9: Bảng lưu biến động số dư tài khoản trong 1 tháng - ghi nhận các giao dịch phát sinh làm thay đổi số dư nợ, số dư có của tài khoản khách hàng | D9: Phase 2
A10: T24 | B10: t24_acct_gen_condition | C10: Bảng khai báo nhóm sản phẩm tài khoản | D10: Phase 2 | E10: Y
A11: T24 | B11: t24_acct_group_condition | C11: Bảng khai báo nhóm số dư tối thiểu tài khoản | D11: Phase 2 | E11: Y
A12: T24 | B12: t24_ac_locked_events | C12: Bảng tài khoản bị phong tỏa | D12: Phase 1
A13: T24 | B13: t24_apportion_acct_categ | C13: Bảng dùng để xử lý VAT và thu nhập (bảng local riêng) | D13: Phase 2
A14: T24 | B14: t24_auto_name | C14: Bảng danh mục nhãn hiệu xe (liên quan đến hợp đồng LD) | D14: Phase 2 | E14: Y
A15: T24 | B15: t24_az_account | C15: Bảng thông tin hợp đồng tiền gửi có kì hạn/Số tài khoản tiết kiệm (Tất cả những IDs trong AZ_ACCOUNT đều nằm trong bảng ACCOUNT) | D15: Phase 1
A16: T24 | B16: t24_az_product_parameter | C16: Bảng danh mục phân loại sản phẩm của hợp đồng tiền gửi có kì hạn/Số tài khoản tiết kiệm | D16: Phase 1 | E16: Y
A17: T24 | B17: t24_bank_assure_inp | C17: Bảng lưu thông tin bảo hiểm khoản vay (không còn sử dụng) | D17: Phase 2
A18: T24 | B18: t24_bc_sort_code | C18: Bảng danh sách ngân hàng tham gia CITAD/VCB/BIDV | D18: Phase 1 | E18: Y
A19: T24 | B19: t24_basic_interest | C19: Bảng danh sách key lãi suất | D19: Phase 1 | E19: Y
A20: T24 | B20: t24_bosc_comp_reg | C20: Bảng danh mục công ty chứng khoán liên quan đến hợp đồng LD | D20: Phase 2 | E20: Y
A21: T24 | B21: t24_categ_entry | C21: Bảng bút toán thu nhập/chi phí | D21: Phase 1
A22: T24 | B22: t24_category | C22: Bảng danh sách phân loại category | D22: Phase 1 | E22: Y
A23: T24 | B23: t24_collateral | C23: Bảng master thông tin TSĐB | D23: Phase 1
A24: T24 | B24: t24_collateral_code | C24: Bảng danh sách mã TSĐB cụ thể | D24: Phase 1 | E24: Y
A25: T24 | B25: t24_collateral_right | C25: Bảng liên kết quyền TSĐB | D25: Phase 1
A26: T24 | B26: t24_collateral_type | C26: Bảng danh mục loại TSĐB | D26: Phase 1 | E26: Y
A27: T24 | B27: t24_crb | C27: Bảng CRB | D27: Phase 1
A28: T24 | B28: t24_ocbh_coll_bpm_store | C28: Bảng tạm đối soát trạng thái TSBĐ giữa hệ thống BPM và hệ thống T24 | D28: Phase 2
A29: T24 | B29: t24_ocbh_coll_rev_agent | C29: Bảng thông tin đơn vị định giá TSĐB (OCB customed) | D29: Phase 1
A30: T24 | B30: t24_company | C30: Bảng danh mục chi nhánh | D30: Phase 1
A31: T24 | B31: t24_comp_level_group | C31: Bảng lưu phân cấp Mã chi nhánh | D31: Phase 2
A32: T24 | B32: t24_consolidate_prft_loss | C32: Bảng chi phí/lợi nhuận toàn hàng | D32: Phase 1
A33: T24 | B33: t24_country | C33: Bảng danh mục quốc gia | D33: Phase 1 | E33: Y
A34: T24 | B34: t24_currency | C34: Bảng thông tin về các loại đồng tiền, tỉ giá | D34: Phase 1
A35: T24 | B35: t24_cus_pkg | C35: Bảng thông tin các gói ưu đãi cho khách hàng | D35: Phase 1
A36: T24 | B36: t24_dealer_desk | C36: Bảng danh mục dealer | D36: Phase 1 | E36: Y
A37: T24 | B37: t24_de_bic | C37: Bảng danh mục ngân hàng tham gia Swift | D37: Phase 1 | E37: Y
A38: T24 | B38: t24_denom_exchange | C38: Bảng lưu tỷ giá cho đồng có mệnh giá nhỏ | D38: Phase 2 | E38: Y
A39: T24 | B39: t24_department | C39: Bảng danh mục phòng ban | D39: Phase 1 | E39: Y
A40: T24 | B40: t24_dept_acct_officer | C40: Bảng thông tin nhân viên bán hàng | D40: Phase 1
...

Sheet Summary Business Vault
A1: Summary Business Vault
A2: Source | B2: Group | C2: Table Name | D2: Description | E2: Các bảng raw vault sử dụng cho BV | F2: Note
A3: Raw Vault | B3: Point in time | C3: pit_loan | D3: Bảng Point-in-Time tổng hợp các điểm thời gian hiệu lực của các Satellite thuộc hợp đồng tín dụng | E3: hub_loan sat_loans_information sat_loans_classification sat_loans_rate sat_loans_terms
A4: Raw Vault | B4: Point in time | C4: pit_account | D4: Bảng Point-in-Time tổng hợp các điểm thời gian hiệu lực của các Satellite thuộc tài khoản | E4: hub_account sat_deposits_rate sat_deposits_information sat_deposits_terms sat_account_balance sat_account_information sat_account_classification
A5: Raw Vault | B5: Point in time | C5: pit_customer | D5: Bảng Point-in-Time tổng hợp các điểm thời gian hiệu lực của các Satellite thuộc khách hàng | E5: hub_customer sat_customer_information sat_customer_extra_information sat_customer_contract sat_customer_classification sat_customer_kyc sat_customer_financial_statement sat_cust_package
A6: Raw Vault | B6: Point in time | C6: pit_acnt_contract | D6: Bảng Point-in-Time tổng hợp các điểm thời gian hiệu lực của các Satellite thuộc hợp đồng tài khoản (WAY4) | E6: hub_acnt_contract sat_acnt_contract_cs_status_log sat_acnt_contract_information sat_acnt_contract_type sat_acnt_contract_add_data sat_acnt_contract_other
A7: Raw Vault | B7: Bridge | C7: bridge_loan | D7: Bảng Bridge kết hợp các Hashkey liên quan đến hợp đồng tín dụng (khoản vay trong hạn, quá hạn, tài khoản thấu chi). Nguồn gốc của bridge loan lấy từ CRB , chỉ lọc gl like 2% và loại bỏ những tieu khoan = TOTAL, ROUNDING.ADJUSTMENT | E7: hub_loans link_crb_loans hub_loans_payment_due link_crb_loans_payment_due hub_account link_crb_account hub_crb link_crb_branch link_crb_customer link_loans_dept_acct_officer_NVQL link_loans_salesid
A8: Raw Vault | B8: Bridge | C8: bridge_account | D8: Bảng Bridge kết hợp các Hashkey liên quan đến tài khoản (khách hàng, chi nhánh, nhân viên) | E8: link_crb_account hub_crb link_crb_loans link_crb_branch link_crb_customer link_account_dept_acct_officer hub_account hub_loans hub_branch hub_customer hub_acct_officer
A9: Raw Vault | B9: Bridge | C9: bridge_card | D9: Bảng Bridge kết hợp các Hashkey liên quan đến thẻ (hợp đồng tài khoản, khách hàng, cấp liability, cấp account, cấp card). Nguồn gốc của bridge loan lấy từ CRB , chỉ lọc gl like 4% và loại bỏ những tieu khoan = TOTAL, ROUNDING.ADJUSTMENT | E9: link_account_contract_card effsat_link_account_contract_card link_acnt_contract_client link_client_customer link_acnt_contract_branch link_acnt_contract_product hub_acnt_contract hub_client hub_customer hub_branch hub_product
A10: Raw Vault | B10: Bridge | C10: bridge_ft | D10: Bảng Bridge kết hợp các Hashkey liên quan đến giao dịch chuyển tiền trên t24 (account debit, credit, customer,v.v) | E10: hub_funds_transfer link_funds_transfer_debit_account link_funds_transfer_credit_account link_account_customer link_funds_transfer_branch link_funds_transfer_clearing_citad hub_account hub_customer hub_clearing_citad
A11: Raw Vault | B11: Bridge | C11: bridge_doc | D11: Bảng Bridge kết hợp các Hashkey liên quan đến giao dịch của way4 (hợp đồng tài khoản nguồn/đích, m_transaction) | E11: link_doc_fin_auth hub_document link_doc_m_transaction link_doc_target_acnt_contract link_acnt_contract_client link_client_customer hub_m_transaction hub_acnt_contract hub_client hub_customer
A12: Raw Vault | B12: asOfDate | C12: calendar | D12: Bảng lịch tạo ra các ngày snapshot dùng để join với bảng PIT và Bridge (Bảng Calendar xác định danh sách ngày làm việc trong năm, ngày làm việc cuối tháng, ngày làm việc đầu tháng, ngày làm việc tiếp theo, ngày làm việc trước đó, ngày làm việc đầu năm, ngày làm việc cuối năm, được dùng làm trục thời gian chuẩn trong các câu truy vấn) | E12: ref_holiday

Sheet Mapping Stat.
A1: Source | B1: Table Name in Source | C1: Phase | D1: Số trường | E1: Số trường đã mapping phase 1 + 2 | F1: Còn lại | G1: Mô tả | H1: Note
A2: WAY4 | B2: account_type | C2: Phase 1 | D2: 17 | G2: Reference table
A3: WAY4 | B3: acnt_contract | C3: Phase 1 | D3: 101 | E3: 101 | F3: =D3-E3 -> 0
A4: WAY4 | B4: appl_product | C4: Phase 1 | D4: 50 | E4: 50 | F4: =D4-E4 -> 0
A5: WAY4 | B5: billing_log | C5: Phase 1 | D5: 17 | E5: 17 | F5: =D5-E5 -> 0
A6: WAY4 | B6: client | C6: Phase 1 | D6: 67 | E6: 65 | F6: =D6-E6 -> 2 | G6: 2 trường không sử dụng: ENABLE_AFFILIATION, AFFILIATION_TYPE Một số trường quan trọng thì đã thống nhất lấy từ bảng client_address: TITLE, SALUTATION_SUFFIX, BIRTH_NAM, COUNTRY, ADDRESS_ZIP, ADDRESS_LINE_1, ADDRESS_LINE_2, ADDRESS_LINE_3, ADDRESS_LINE_4, PHONE, PHONE_H, PHONE_M, FAX, FAX_H, E_MAIL, URL, STATE, CITY
A7: WAY4 | B7: contr_status | C7: Phase 1 | D7: 16 | G7: Reference table
A8: WAY4 | B8: country | C8: Phase 1 | D8: 20 | G8: Reference table
A9: WAY4 | B9: cs_status_log | C9: Phase 1 | D9: 23 | E9: 23 | F9: =D9-E9 -> 0
A10: WAY4 | B10: cs_status_type | C10: Phase 1 | D10: 21 | G10: Reference table
A11: WAY4 | B11: cs_status_value | C11: Phase 1 | D11: 18 | G11: Reference table
A12: WAY4 | B12: currency | C12: Phase 1 | D12: 11 | G12: Reference table
A13: WAY4 | B13: device_rec | C13: Phase 1 | D13: 39 | E13: 39 | F13: =D13-E13 -> 0
A14: WAY4 | B14: doc | C14: Phase 1 | D14: 89 | E14: 89 | F14: =D14-E14 -> 0
A15: WAY4 | B15: entry | C15: Phase 1 | D15: 33 | E15: 33 | F15: =D15-E15 -> 0
A16: WAY4 | B16: m_transaction | C16: Phase 1 | D16: 34 | E16: 34 | F16: =D16-E16 -> 0
A17: WAY4 | B17: mess_channel | C17: Phase 1 | D17: 11 | G17: Reference table
A18: WAY4 | B18: sic | C18: Phase 1 | D18: 12 | G18: Reference table
A19: WAY4 | B19: templ_approved | C19: Phase 1 | D19: 58 | E19: 57 | F19: =D19-E19 -> 1 | G19: 1 trường không sử dụng, ko có data ACCOUNT_NUMERATION
A20: WAY4 | B20: trans_type | C20: Phase 1 | D20: 27 | G20: Reference table
A21: WAY4 | B21: balance | C21: Phase 1 | D21: 39 | E21: 39 | F21: =D21-E21 -> 0
A22: WAY4 | B22: acq_dev_cycle | C22: Phase 1 | D22: 14 | E22: 14 | F22: =D22-E22 -> 0
A23: WAY4 | B23: billing | C23: Phase 1 | D23: 42 | E23: 42 | F23: =D23-E23 -> 0
A24: WAY4 | B24: payment | C24: Phase 1 | D24: 20 | E24: 20 | F24: =D24-E24 -> 0
A25: WAY4 | B25: acc_templ | C25: Phase 2 | D25: 67 | E25: 67 | F25: =D25-E25 -> 0
A26: WAY4 | B26: account | C26: Phase 2 | D26: 40 | F26: =D26-E26 -> 40
A27: WAY4 | B27: add_data | C27: Phase 2 | D27: 10 | G27: Reference table
A28: WAY4 | B28: bank_unit | C28: Phase 2 | D28: 13 | G28: Reference table
A29: WAY4 | B29: bin_table | C29: Phase 2 | D29: 34 | G29: Reference table
A30: WAY4 | B30: branch | C30: Phase 2 | D30: 14 | F30: =D30-E30 -> 14
A31: WAY4 | B31: card_info | C31: Phase 2 | D31: 45 | F31: =D31-E31 -> 45
A32: WAY4 | B32: client_address | C32: Phase 2 | D32: 41 | F32: =D32-E32 -> 41
A33: WAY4 | B33: event_type | C33: Phase 2 | D33: 25 | G33: Reference table
A34: WAY4 | B34: evnt_action | C34: Phase 2 | D34: 7 | G34: Reference table
A35: WAY4 | B35: gl_trace | C35: Phase 2 | D35: 24 | F35: =D35-E35 -> 24
A36: WAY4 | B36: invoice_log | C36: Phase 2 | D36: 35 | F36: =D36-E36 -> 35
A37: WAY4 | B37: item | C37: Phase 2 | D37: 27 | F37: =D37-E37 -> 27
A38: WAY4 | B38: resp_code | C38: Phase 2 | D38: 10 | G38: Reference table
A39: WAY4 | B39: td_auth_sch | C39: Phase 2 | D39: 22 | E39: 22 | F39: =D39-E39 -> 0
A40: WAY4 | B40: td_auth_type | C40: Phase 2 | D40: 12 | G40: Reference table
...

Sheet Mapping Statistics
A1: Note: Những bảng được liệt kê là những bảng thuộc Phase 1, đã được OCB cung cấp dữ liệu trong file Metadata và có ở Vault Mapping. Những bảng còn lại không được liệt kê dưới đây thuộc bảng Reference
A2: Source | B2: Bảng | C2: Số lượng trường đã mapping | D2: Số lượng trường trong metadata | E2: Số trường còn lại (lưu ý: không tính những trường data_date vì đó là những trường load dữ liệu vào nguồn) | F2: Tên trường không đưa vào Raw vault | G2: Mô tả ở Metadata file | H2: Note
A3: T24 | B3: T24_CUSTOMER | C3: 97 | D3: 99 | E3: 2 | F3: SP_RATING | G3: STANDARD&POOR Loại xếp hạng | H3: trường nãy sẽ được đưa vào sau khi bổ sung thêm các trường xếp hạng theo basel lên bronze
F4: FITCH_RATING | G4: FITCH Loại xếp hạng | H4: trường nãy sẽ được đưa vào sau khi bổ sung thêm các trường xếp hạng theo basel lên bronze
A5: T24 | B5: T24_OCBH_CUS_EXT_INFO | C5: 15 | D5: 15 | E5: 0 | F5: N/A | G5: N/A
A6: T24 | B6: T24_DEPT_ACCT_OFFICER | C6: 34 | D6: 34 | E6: 0 | F6: N/A | G6: N/A
A7: T24 | B7: T24_CUS_PKG | C7: 13 | D7: 13 | E7: 0 | F7: N/A | G7: N/A
A8: T24 | B8: T24_OCBH_PROD_PACKAGE_PARTNER | C8: 16 | D8: 16 | E8: 0 | F8: N/A | G8: N/A
A9: T24 | B9: T24_USER | C9: 42 | D9: 43 | E9: 1 | F9: IP_ID | G9: Không có field này trong nguồn | H9: không thể bổ sung do không có ở nguồn
A10: T24 | B10: T24_COLLATERAL | C10: 91 | D10: 91 | E10: 0 | F10: N/A | G10: N/A
A11: T24 | B11: T24_COLLATERAL_RIGHT | C11: 12 | D11: 12 | E11: 0 | F11: N/A | G11: N/A
A12: T24 | B12: T24_OCBH_COLL_BASEL | C12: 25 | D12: 25 | E12: 0 | F12: N/A | G12: N/A
A13: T24 | B13: T24_ACCOUNT | C13: 53 | D13: 53 | E13: 0 | F13: N/A | G13: N/A
A14: T24 | B14: T24_ACCOUNT_DEBIT_INT | C14: 10 | D14: 12 | E14: 2 | F14: EFF_DT | G14: Không có field này trong nguồn | H14: không thể bổ sung do không có ở nguồn
F15: IS_MAX_EFF_DT | G15: Không có field này trong nguồn | H15: không thể bổ sung do không có ở nguồn
A16: T24 | B16: T24_ACCOUNT_CREDIT_INT | C16: 8 | D16: 8 | E16: 0 | F16: N/A | G16: N/A
A17: T24 | B17: T24_AC_LOCKED_EVENTS | C17: 11 | D17: 11 | E17: 0 | F17: N/A | G17: N/A
A18: T24 | B18: T24_OCBH_SUB_VIRTUAL_ACCOUNT | C18: 10 | D18: 10 | E18: 0 | F18: N/A | G18: N/A
A19: T24 | B19: T24_CRB | C19: 24 | D19: 24 | E19: 0 | F19: N/A | G19: N/A
A20: T24 | B20: T24_LOANS_AND_DEPOSITS | C20: 104 | D20: 104 | E20: 0 | F20: N/A | G20: N/A
A21: T24 | B21: T24_LD_SCHEDULE_DEFINE | C21: 10 | D21: 10 | E21: 0 | F21: N/A | G21: N/A
A22: T24 | B22: T24_PAYMENT_DUE | C22: 56 | D22: 56 | E22: 0 | F22: N/A | G22: N/A
A23: T24 | B23: T24_LD_APRV_INFO | C23: 10 | D23: 10 | E23: 0 | F23: N/A | G23: N/A
A24: T24 | B24: T24_LMM_ACCOUNT_BALANCES | C24: 23 | D24: 25 | E24: 2 | F24: AR_ID | G24: Không có field này trong nguồn | H24: không thể bổ sung do không có ở nguồn
F25: CRT_TM | G25: Không có field này trong nguồn | H25: không thể bổ sung do không có ở nguồn
A26: T24 | B26: T24_LN_CUST_REVS_DTLS | C26: 15 | D26: 15 | E26: 0 | F26: N/A | G26: N/A
A27: T24 | B27: T24_OCBH_LD_BASEL | C27: 15 | D27: 15 | E27: 0 | F27: N/A | G27: N/A
A28: T24 | B28: T24_LD_EXTRA_INFO | C28: 31 | D28: 31 | E28: 0 | F28: N/A | G28: N/A
A29: T24 | B29: T24_LIMIT | C29: 35 | D29: 37 | E29: 2 | F29: T_RATE | G29: Không có field này trong nguồn | H29: không thể bổ sung do không có ở nguồn
F30: AR_ID | G30: Không có field này trong nguồn | H30: không thể bổ sung do không có ở nguồn
A31: T24 | B31: T24_AZ_ACCOUNT | C31: 54 | D31: 56 | E31: 2 | F31: T_TERM_RATE | G31: Không có field này trong nguồn | H31: không thể bổ sung do không có ở nguồn
F32: T_ONLINE_ACTUAL_BAL | G32: Không có field này trong nguồn | H32: không thể bổ sung do không có ở nguồn
A33: T24 | B33: T24_CATEG_ENTRY | C33: 26 | D33: 26 | E33: 0 | F33: N/A | G33: N/A
A34: T24 | B34: T24_RE_STAT_LINE_BAL | C34: 17 | D34: 17 | E34: 0 | F34: N/A | G34: N/A
A35: T24 | B35: T24_PC_RE_STAT_LINE_BAL | C35: 18 | D35: 18 | E35: 0 | F35: N/A | G35: N/A
A36: T24 | B36: T24_CONSOLIDATE_PRFT_LOSS | C36: 6 | D36: 6 | E36: 0 | F36: N/A | G36: N/A
A37: T24 | B37: T24_LINE_MVMT_TOANHANG | C37: 15 | D37: 15 | E37: 0 | F37: N/A | G37: N/A
A38: T24 | B38: T24_RE_CONSOL_SPEC_ENTRY | C38: 30 | D38: 30 | E38: 0 | F38: N/A | G38: N/A
A39: T24 | B39: T24_STMT_ENTRY | C39: 35 | D39: 35 | E39: 0 | F39: N/A | G39: N/A
A40: T24 | B40: T24_CURRENCY | C40: 14 | D40: 14 | E40: 0 | F40: N/A | G40: N/A
...

Sheet Cover
B6: Chuyển giao tài liệu
B7: SP2. Tài liệu phân tích nguồn dữ liệu và thiết kế luồng dữ liệu
B9: Dự án: | C9: TRIỂN KHAI HỆ THỐNG VÙNG DỮ LIỆU SILVER TRÊN NỀN TẢNG DATABRICKS
B10: Thông tin liên hệ:
B11: Cuong Huy Nguyen
B12: Director
B13: Raffles VN Co. Ltd.
B14: Level 5, Sentinel Place, 41A Ly Thai To, Hoan Kiem Dt., Hanoi, Vietnam
B15: Tel: +84 4 39388826
B16: Cell: +65 9879 1959 / + 84 912153459
B17: Email: cuongnguyen@raffles.com.vn
B19: Long Quang Nguyen
B20: Manager
B21: Raffles VN Co. Ltd.
B22: Level 5, Sentinel Place, 41A Ly Thai To, Hoan Kiem Dt., Hanoi, Vietnam
... B29: Thực hiện bởi Raffles VN Co. Ltd

Sheet Rules
A1: Nhóm nguyên tắc | B1: Nội dung | C1: Mô tả / Quy định áp dụng | D1: Ví dụ / Thông tin chi tiết
A2: Nguyên tắc chung | B2: Định hướng thiết kế | C2: Áp dụng mô hình Data Vault 2.0 để tích hợp dữ liệu đa nguồn, lưu lịch sử đầy đủ, đảm bảo khả năng mở rộng và truy vết dữ liệu.
B3: Phạm vi dữ liệu | C3: Chỉ đưa vào Data Vault các nguồn dữ liệu phục vụ cho SOR, BCN, Basel và Feature Store. | D3: T24: 15 Groups (Entity, Loan, Security, Account, Accounting, Transaction, Trade Finance, Money Market, Collateral, Forex, Deposit, Currency, Limit, Calendar, Deposit) WAY4: 8 Groups (Contract, Accounting, Transaction, Entity, Device, Card, Product, Issuing) OMNI: 15 Groups (Omni_Service, Payment_Order, Cc_Registration, Od_Registration, Voucher, Transfer Bill, Party, Account_Information, Notification, Device, User_Omni, Data_Sharing_Consent, Onboarding_Report, Clevertap_Tracking, Customer) BPM: 5 Groups (Entity, Giải ngân, Giao dịch, Phê duyệt, TSBD) Appsflyer: 5 Groups (Installs, Reinstalls, In_App_Events, Uninstall, Appsflyer) CRM&CallCenter: 4 Groups (Contact, User, Callcenter, Campaign) Clevertap: 2 Groups (Campaign, Event)
A4: Nguyên tắc thiết kế | B4: Business Object | C4: Business Object được xác định theo tên bảng nguồn (Source Table). Chỉ chuẩn hoá và đặt lại tên khi tên nguồn không phản ánh rõ đối tượng nghiệp vụ.
B5: Business Key | C5: Sử dụng khóa nghiệp vụ (Business Key) làm cơ sở định danh, không phụ thuộc khóa kỹ thuật nguồn. | D5: T24_ACCOUNT.ID, T24_COLLATERAL.ID Đặc biệt: T24_CRB có BK = T24_CRB.TIEUKHOAN + T24_CRB.GL (composite key)
B6: Content | C6: Phân loại nhóm thông tin hoặc ngữ cảnh dữ liệu. | D6: information, classification, amount, status_log, type, status,...
B7: Cấu trúc tên bảng | C7: Hub: hub_<Business Object> Sat: sat_<Business Object>_<Content> Link: link_<Business Object Main>_<Business Object Other> Sts: sts_hub_<Business Object> Effsat: effsat_link_<Business Object Main>_<Business Object Other> | D7: hub_billing_log sat_billing_log_information link_billing_log_account_contract sts_hub_billing_log effsat_link_billing_log_account_contract
B8: Hashkey | C8: Mỗi Hub/Link có cột <entity>_hashkey [PK] tạo ra từ hàm hash từ Business Key. Bảng Sat tham chiếu hashkey của Hub tương ứng làm FK. | D8: hub_account.account_hashkey = hash(T24_ACCOUNT.ID) link_card_client.lnk_card_client_hashkey = hash(card_id || client_id)
B9: Cấu trúc tên cột | C9: Tên cột từ cột tương ứng của Business Object.
B10: Data Type | C10: Kiểu dữ liệu từ cột tương ứng của Business Object (được thống nhất từ metadata). | D10: string, number, date
B11: Cú pháp mapping | C11: <Source Table>.<Column> | D11: T24_ACCOUNT.T_ACCOUNT_TITLE_1
B12: Bộ lọc bản ghi nguồn | C12: Chỉ lấy bản ghi đang hoạt động. Áp dụng điều kiện lọc phù hợp với từng hệ thống nguồn.
B13: Các trường nghiệp vụ bắt buộc | C13: • source_event_date: Ngày sự kiện nguồn phát sinh bản ghi, dùng làm thành phần xác định phiên bản dữ liệu. • hashdiff: Giá trị hash tổng hợp của toàn bộ cột nội dung (payload), dùng để phát hiện thay đổi. • record_source: Tên hệ thống nguồn phát sinh dữ liệu. | D13: sat_loans_information: source_event_date = ngày ETL chạy (ví dụ: 2025-01-01) hashdiff = MD5(t_loan_amount || t_maturity || t_interest_rate || ...) record_source = 'T24'
B14: Quy tắc đặt tên bảng cho Business Vault (BV) | C14: Các bảng Business Vault đặt tên theo loại bảng và business object liên quan: • Point-in-Time (PIT): pit_<Business Object> • Bridge: bridge_<Business Object chính> • AsOfDate: calendar (bảng lịch dùng chung) Tên bảng BV không thêm tiền tố nguồn (không dùng hub_/sat_/link_). Business Object trong BV lấy từ Hub trung tâm mà PIT hoặc Bridge tham chiếu. | D14: pit_loan → PIT cho hub_loans pit_account → PIT cho hub_account pit_customer → PIT cho hub_customer bridge_loan → Bridge tổng hợp từ hub_crb, hub_loans, hub_account, hub_customer, hub_branch bridge_card → Bridge tổng hợp cho nghiệp vụ thẻ calendar → Bảng lịch (asOfDate)
B15: Quy tắc xác định khóa nghiệp vụ (Business Key - BK) theo từng loại bảng Raw Vault | C15: Business Key (BK) là khóa nghiệp vụ từ hệ thống nguồn, dùng để định danh duy nhất một thực thể. Hashkey được tạo bằng hàm hash (SHA256) từ BK, không thay thế BK. • Hub: BK là khóa tự nhiên của bảng nguồn (thường là trường ID). Composite BK khi một thực thể cần nhiều trường để định danh duy nhất. • Link: BK là tập hợp BK của các Hub tham gia liên kết. Hashkey của Link được tính từ tổ hợp BK này. • Sat: Không có BK riêng. Loại bảng này thừa kế BK từ Hub liên kết qua hashkey (FK). • Effsat: Không có BK riêng. Loại bảng này thừa kế BK từ Link liên kết qua hashkey (FK). • Sts: BK giống Hub tương ứng, dùng để ghi nhận trạng thái xóa / tái xuất hiện của một thực thể Hub. | D15: Hub có BK: hub_client.business_key = ows_client.id hub_acnt_contract.business_key = ows_acnt_contract.id Hub có composite BK: hub_crb.business_key = T24_CRB.TIEUKHOAN + T24_CRB.GL Link BK (tổ hợp BK các Hub): link_client_customer.link_client_customer_hashkey = hash(ows_client.id || ows_client.client_number) link_device_acnt_contract.link_device_acnt_contract_hashkey = hash(ows_device_rec.id || ows_device_rec.acnt_contract__oid) Sat - kế thừa BK từ Hub: sat_client_classification.client_hashkey = hash(ows_client.id) → BK = hub_client.business_key Sts - kế thừa BK từ Hub: sts_hub_client.client_hashkey = hash(ows_client.id) → BK = hub_client.business_key

Sheet T24 Vault Mapping_Phase1
A1: Source_system | B1: Group | C1: Table Name | D1: Column Name | E1: Description | F1: Data Type | G1: Mapping | H1: Key | I1: Phase
A2: T24 | B2: ACCOUNT | C2: hub_virtual_account | D2: virtual_account_hashkey | E2: Hub Virtual Account | F2: string | G2: T24_OCBH_SUB_VIRTUAL_ACCOUNT.ID | H2: [PK] | I2: Phase 1
A3: T24 | B3: ACCOUNT | C3: hub_virtual_account | D3: business_key | E3: Business Key | F3: string | G3: T24_OCBH_SUB_VIRTUAL_ACCOUNT.ID | I3: Phase 1
A4: T24 | B4: ACCOUNT | C4: sts_hub_virtual_account | D4: account_hashkey | E4: Hub Hash Key tài khoản | F4: string | G4: hub_virtual_account.virtual_account_hashkey | H4: [PK] | I4: Phase 1
A5: T24 | B5: ACCOUNT | C5: sts_hub_virtual_account | D5: source_event_date | E5: Ngày sự kiện nguồn | F5: date | G5: N/A | I5: Phase 1
A6: T24 | B6: ACCOUNT | C6: sts_hub_virtual_account | D6: cdc_status | E6: Trạng thái CDC - Change Data Capture (D = Deleted, I = Insert/ Reinsert) • D (Deleted): ID đã tồn tại trong Hub nhưng bị mất dấu (xóa vật lý) ở bảng nguồn trong ngày tương ứng source_event_date • I (Inserted/Reinserted): ID từng bị xóa trong quá khứ, nay xuất hiện trở lại ở bảng nguồn trong ngày tương ứng source_event_date | F6: string | G6: N/A | I6: Phase 1
A7: T24 | B7: ACCOUNT | C7: hub_account_locked_events | D7: ac_locked_events_hashkey | E7: Hub Hash Key Account Locked | F7: string | G7: T24_AC_LOCKED_EVENTS.ID | H7: [PK] | I7: Phase 1
A8: T24 | B8: ACCOUNT | C8: hub_account_locked_events | D8: business_key | E8: Business Key | F8: string | G8: T24_AC_LOCKED_EVENTS.ID | I8: Phase 1
A9: T24 | B9: ACCOUNT | C9: sts_hub_account_locked_events | D9: ac_locked_events_hashkey | E9: Hub Hash Key Account Locked | F9: string | G9: hub_account_locked_events.ac_locked_events_hashkey | H9: [PK] | I9: Phase 1
A10: T24 | B10: ACCOUNT | C10: sts_hub_account_locked_events | D10: source_event_date | E10: Ngày sự kiện nguồn | F10: date | G10: N/A | I10: Phase 1
A11: T24 | B11: ACCOUNT | C11: sts_hub_account_locked_events | D11: cdc_status | E11: Trạng thái CDC - Change Data Capture (D = Deleted, I = Insert/ Reinsert) • D (Deleted): ID đã tồn tại trong Hub nhưng bị mất dấu (xóa vật lý) ở bảng nguồn trong ngày tương ứng source_event_date • I (Inserted/Reinserted): ID từng bị xóa trong quá khứ, nay xuất hiện trở lại ở bảng nguồn trong ngày tương ứng source_event_date | F11: string | G11: N/A | I11: Phase 1
A12: T24 | B12: ACCOUNT | C12: hub_account | D12: account_hashkey | E12: Hub Hash Key tài khoản | F12: string | G12: T24_ACCOUNT.ID | H12: [PK] | I12: Phase 1
A13: T24 | B13: ACCOUNT | C13: hub_account | D13: business_key | E13: Business Key: Mã tài khoản | F13: string | G13: T24_ACCOUNT.ID | I13: Phase 1
A14: T24 | B14: ACCOUNT | C14: sts_hub_account | D14: account_hashkey | E14: Hub Hash Key tài khoản | F14: string | G14: hub_account.account_hashkey | H14: [PK] | I14: Phase 1
A15: T24 | B15: ACCOUNT | C15: sts_hub_account | D15: source_event_date | E15: Ngày sự kiện nguồn | F15: date | G15: N/A | I15: Phase 1
A16: T24 | B16: ACCOUNT | C16: sts_hub_account | D16: cdc_status | E16: Trạng thái CDC - Change Data Capture (D = Deleted, I = Insert/ Reinsert) • D (Deleted): ID đã tồn tại trong Hub nhưng bị mất dấu (xóa vật lý) ở bảng nguồn trong ngày tương ứng source_event_date • I (Inserted/Reinserted): ID từng bị xóa trong quá khứ, nay xuất hiện trở lại ở bảng nguồn trong ngày tương ứng source_event_date | F16: string | G16: N/A | I16: Phase 1
A17: T24 | B17: ACCOUNT | C17: sat_virtual_account | D17: virtual_account_hashkey | E17: Hub Virtual Account | F17: string | G17: T24_OCBH_SUB_VIRTUAL_ACCOUNT.ID | H17: [PK] | I17: Phase 1
A18: T24 | B18: ACCOUNT | C18: sat_virtual_account | D18: t_va_id | E18: Prefix của ID TK định danh | F18: string | G18: T24_OCBH_SUB_VIRTUAL_ACCOUNT.T_VA_ID | I18: Phase 1
A19: T24 | B19: ACCOUNT | C19: sat_virtual_account | D19: t_sub_id | E19: Surfix của ID TK định danh | F19: string | G19: T24_OCBH_SUB_VIRTUAL_ACCOUNT.T_SUB_ID | I19: Phase 1
A20: T24 | B20: ACCOUNT | C20: sat_virtual_account | D20: t_sub_va_name | E20: Tên TK định danh | F20: string | G20: T24_OCBH_SUB_VIRTUAL_ACCOUNT.T_SUB_VA_NAME | I20: Phase 1
A21: T24 | B21: ACCOUNT | C21: sat_virtual_account | D21: t_credit_acct_spa | E21: TK ghi có của TK định danh | F21: string | G21: T24_OCBH_SUB_VIRTUAL_ACCOUNT.T_CREDIT_ACCT_SPA | I21: Phase 1
A22: T24 | B22: ACCOUNT | C22: sat_virtual_account | D22: t_sva_record_status | E22: Tình trạng bản ghi ( Duyệt/chờ duyệt) | F22: string | G22: T24_OCBH_SUB_VIRTUAL_ACCOUNT.T_SVA_RECORD_STATUS | I22: Phase 1
A23: T24 | B23: ACCOUNT | C23: sat_virtual_account | D23: t_sva_status | E23: Tình trạng ( Active/Inative_ | F23: string | G23: T24_OCBH_SUB_VIRTUAL_ACCOUNT.T_SVA_STATUS | I23: Phase 1
A24: T24 | B24: ACCOUNT | C24: sat_virtual_account | D24: t_date_time_input | E24: Ngày nhập | F24: string | G24: T24_OCBH_SUB_VIRTUAL_ACCOUNT.T_DATE_TIME_INPUT | I24: Phase 1
A25: T24 | B25: ACCOUNT | C25: sat_virtual_account | D25: t_date_time_approval | E25: Ngày duyệt | F25: string | G25: T24_OCBH_SUB_VIRTUAL_ACCOUNT.T_DATE_TIME_APPROVAL | I25: Phase 1
A26: T24 | B26: ACCOUNT | C26: sat_account_system | D26: account_hashkey | E26: Hub Hash Key tài khoản | F26: string | G26: T24_ACCOUNT.ID | H26: [PK] | I26: Phase 1
A27: T24 | B27: ACCOUNT | C27: sat_account_system | D27: t_inputter | E27: Người nhập | F27: string | G27: T24_ACCOUNT.T_INPUTTER | I27: Phase 1
A28: T24 | B28: ACCOUNT | C28: sat_account_system | D28: t_authoriser | E28: Người duyệt | F28: string | G28: T24_ACCOUNT.T_AUTHORISER | I28: Phase 1
A29: T24 | B29: ACCOUNT | C29: sat_account_system | D29: t_date_time | E29: Ngày giờ cập nhật thông tin TK | F29: string | G29: T24_ACCOUNT.T_DATE_TIME | I29: Phase 1
A30: T24 | B30: ACCOUNT | C30: sat_account_system | D30: t_date_last_update | E30: Ngày phát sinh giao dịch sau cùng | F30: string | G30: T24_ACCOUNT.T_DATE_LAST_UPDATE | I30: Phase 1
A31: T24 | B31: ACCOUNT | C31: sat_account_system | D31: t_package_date | E31: Mã gói ưu đãi KHDN (Smart) | F31: string | G31: T24_ACCOUNT.T_PACKAGE_DATE | I31: Phase 1
A32: T24 | B32: ACCOUNT | C32: sat_account_system | D32: t_curr_no | E32: Số lần thay đổi | F32: string | G32: T24_ACCOUNT.T_CURR_NO | I32: Phase 1
A33: T24 | B33: ACCOUNT | C33: sat_account_system | D33: t_ocb_reason_rest | E33: Lý do hạn chế TK | F33: string | G33: T24_ACCOUNT.T_OCB_REASON_REST | I33: Phase 1
A34: T24 | B34: ACCOUNT | C34: sat_account_other | D34: account_hashkey | E34: Hub Hash Key tài khoản | F34: string | G34: T24_ACCOUNT.ID | H34: [PK] | I34: Phase 1
A35: T24 | B35: ACCOUNT | C35: sat_account_other | D35: t_open_cleared_bal | E35: Không dùng | F35: decimal(23,4) | G35: T24_ACCOUNT.T_OPEN_CLEARED_BAL | I35: Phase 1
A36: T24 | B36: ACCOUNT | C36: sat_account_other | D36: t_online_cleared_bal | E36: Không dùng | F36: decimal(23,4) | G36: T24_ACCOUNT.T_ONLINE_CLEARED_BAL | I36: Phase 1
A37: T24 | B37: ACCOUNT | C37: sat_account_other | D37: t_int_balance | E37: Không dùng | F37: decimal(15,4) | G37: T24_ACCOUNT.T_INT_BALANCE | I37: Phase 1
A38: T24 | B38: ACCOUNT | C38: sat_account_other | D38: t_ref_officer | E38: Không dùng | F38: string | G38: T24_ACCOUNT.T_REF_OFFICER | I38: Phase 1
A39: T24 | B39: ACCOUNT | C39: sat_account_other | D39: t_master_account | E39: Không dùng | F39: string | G39: T24_ACCOUNT.T_MASTER_ACCOUNT | I39: Phase 1
A40: T24 | B40: ACCOUNT | C40: sat_account_other | D40: t_int_liqu_acct | E40: Không dùng | F40: string | G40: T24_ACCOUNT.T_INT_LIQU_ACCT | I40: Phase 1
...

Sheet sts hub
C1: lọc
A2: 1 | B2: sts_hub_account
A3: 2 | B3: sts_hub_account_credit_int | C3: sts cho sat
A4: 3 | B4: sts_hub_account_debit_int | C4: sts cho sat
A5: 4 | B5: sts_hub_account_locked_events
A6: 5 | B6: sts_hub_acct_officer
A7: 6 | B7: sts_hub_branch
A8: 7 | B8: sts_hub_clearing_citad
A9: 8 | B9: sts_hub_collateral
A10: 9 | B10: sts_hub_collateral_basel | C10: sts cho sat
A11: 10 | B11: sts_hub_collateral_right
A12: 11 | B12: sts_hub_consolidate_profit_n_loss
A13: 12 | B13: sts_hub_crb
A14: 13 | B14: sts_hub_customer
A15: 14 | B15: sts_hub_deposits
A16: 15 | B16: sts_hub_drawings
A17: 16 | B17: sts_hub_forex
A18: 17 | B18: sts_hub_gci
A19: 18 | B19: sts_hub_gdi
A20: 19 | B20: sts_hub_letter_of_credit
A21: 20 | B21: sts_hub_limit
A22: 21 | B22: sts_hub_loans
A23: 22 | B23: sts_hub_loans_ld_aprv_info | C23: sts cho sat
A24: 23 | B24: sts_hub_loans_ld_basel | C24: sts cho sat
A25: 24 | B25: sts_hub_loans_ld_extra_info | C25: sts cho sat
A26: 25 | B26: sts_hub_loans_ld_schedule_define | C26: sts cho sat
A27: 26 | B27: sts_hub_loans_lmm_account_balances | C27: sts cho sat
A28: 27 | B28: sts_hub_loans_ln_cust_revs | C28: sts cho sat
A29: 28 | B29: sts_hub_loans_payment_due
A30: 29 | B30: sts_hub_md_deal
A31: 30 | B31: sts_hub_money_market
A32: 31 | B32: sts_hub_money_market_lmm_account_balances
A33: 32 | B33: sts_hub_product_package_partner
A34: 33 | B34: sts_hub_repo
A35: 34 | B35: sts_hub_sc_trading_position
A36: 35 | B36: sts_hub_sec_trade
A37: 36 | B37: sts_hub_security
A38: 37 | B38: sts_hub_user
A39: 38 | B39: sts_hub_virtual_account

Sheet T24 Vault Mapping_old
A1: Source_system | B1: Group | C1: Table Name | D1: Column Name | E1: Description | F1: Data Type | G1: Mapping | H1: Key
A2: T24 | B2: ACCOUNT | C2: hub_virtual_account | D2: virtual_account_hashkey | E2: Hub Virtual Account | F2: string | G2: T24_OCBH_SUB_VIRTUAL_ACCOUNT.ID | H2: [PK]
A3: T24 | B3: ACCOUNT | C3: hub_virtual_account | D3: business_key | E3: Business Key | F3: string | G3: T24_OCBH_SUB_VIRTUAL_ACCOUNT.ID
A4: T24 | B4: ACCOUNT | C4: hub_account_locked_events | D4: ac_locked_events_hashkey | E4: Hub Hash Key Account Locked | F4: string | G4: T24_AC_LOCKED_EVENTS.ID | H4: [PK]
A5: T24 | B5: ACCOUNT | C5: hub_account_locked_events | D5: business_key | E5: Business Key | F5: string | G5: T24_AC_LOCKED_EVENTS.ID
A6: T24 | B6: ACCOUNT | C6: hub_account | D6: account_hashkey | E6: Hub Hash Key tài khoản | F6: string | G6: T24_ACCOUNT.ID | H6: [PK]
A7: T24 | B7: ACCOUNT | C7: hub_account | D7: business_key | E7: Business Key: Mã tài khoản | F7: string | G7: T24_ACCOUNT.ID
A8: T24 | B8: ACCOUNT | C8: sat_virtual_account | D8: virtual_account_hashkey | E8: Hub Virtual Account | F8: string | G8: T24_OCBH_SUB_VIRTUAL_ACCOUNT.ID | H8: [PK]
A9: T24 | B9: ACCOUNT | C9: sat_virtual_account | D9: t_va_id | E9: Prefix của ID TK định danh | F9: string | G9: T24_OCBH_SUB_VIRTUAL_ACCOUNT.T_VA_ID
A10: T24 | B10: ACCOUNT | C10: sat_virtual_account | D10: t_sub_id | E10: Surfix của ID TK định danh | F10: string | G10: T24_OCBH_SUB_VIRTUAL_ACCOUNT.T_SUB_ID
A11: T24 | B11: ACCOUNT | C11: sat_virtual_account | D11: t_sub_va_name | E11: Tên TK định danh | F11: string | G11: T24_OCBH_SUB_VIRTUAL_ACCOUNT.T_SUB_VA_NAME
A12: T24 | B12: ACCOUNT | C12: sat_virtual_account | D12: t_credit_acct_spa | E12: TK ghi có của TK định danh | F12: string | G12: T24_OCBH_SUB_VIRTUAL_ACCOUNT.T_CREDIT_ACCT_SPA
A13: T24 | B13: ACCOUNT | C13: sat_virtual_account | D13: t_sva_record_status | E13: Tình trạng bản ghi ( Duyệt/chờ duyệt) | F13: string | G13: T24_OCBH_SUB_VIRTUAL_ACCOUNT.T_SVA_RECORD_STATUS
A14: T24 | B14: ACCOUNT | C14: sat_virtual_account | D14: t_sva_status | E14: Tình trạng ( Active/Inative_ | F14: string | G14: T24_OCBH_SUB_VIRTUAL_ACCOUNT.T_SVA_STATUS
A15: T24 | B15: ACCOUNT | C15: sat_virtual_account | D15: t_date_time_input | E15: Ngày nhập | F15: string | G15: T24_OCBH_SUB_VIRTUAL_ACCOUNT.T_DATE_TIME_INPUT
A16: T24 | B16: ACCOUNT | C16: sat_virtual_account | D16: t_date_time_approval | E16: Ngày duyệt | F16: string | G16: T24_OCBH_SUB_VIRTUAL_ACCOUNT.T_DATE_TIME_APPROVAL
A17: T24 | B17: ACCOUNT | C17: sat_account_system | D17: account_hashkey | E17: Hub Hash Key tài khoản | F17: string | G17: T24_ACCOUNT.ID | H17: [PK]
A18: T24 | B18: ACCOUNT | C18: sat_account_system | D18: t_inputter | E18: Người nhập | F18: string | G18: T24_ACCOUNT.T_INPUTTER
A19: T24 | B19: ACCOUNT | C19: sat_account_system | D19: t_authoriser | E19: Người duyệt | F19: string | G19: T24_ACCOUNT.T_AUTHORISER
A20: T24 | B20: ACCOUNT | C20: sat_account_system | D20: t_date_time | E20: Ngày giờ cập nhật thông tin TK | F20: string | G20: T24_ACCOUNT.T_DATE_TIME
A21: T24 | B21: ACCOUNT | C21: sat_account_system | D21: t_date_last_update | E21: Ngày phát sinh giao dịch sau cùng | F21: string | G21: T24_ACCOUNT.T_DATE_LAST_UPDATE
A22: T24 | B22: ACCOUNT | C22: sat_account_system | D22: t_package_date | E22: Mã gói ưu đãi KHDN (Smart) | F22: string | G22: T24_ACCOUNT.T_PACKAGE_DATE
A23: T24 | B23: ACCOUNT | C23: sat_account_system | D23: t_curr_no | E23: Số lần thay đổi | F23: string | G23: T24_ACCOUNT.T_CURR_NO
A24: T24 | B24: ACCOUNT | C24: sat_account_system | D24: t_ocb_reason_rest | E24: Lý do hạn chế TK | F24: string | G24: T24_ACCOUNT.T_OCB_REASON_REST
A25: T24 | B25: ACCOUNT | C25: sat_account_other | D25: account_hashkey | E25: Hub Hash Key tài khoản | F25: string | G25: T24_ACCOUNT.ID | H25: [PK]
A26: T24 | B26: ACCOUNT | C26: sat_account_other | D26: t_open_cleared_bal | E26: Không dùng | F26: decimal(23,4) | G26: T24_ACCOUNT.T_OPEN_CLEARED_BAL
A27: T24 | B27: ACCOUNT | C27: sat_account_other | D27: t_online_cleared_bal | E27: Không dùng | F27: decimal(23,4) | G27: T24_ACCOUNT.T_ONLINE_CLEARED_BAL
A28: T24 | B28: ACCOUNT | C28: sat_account_other | D28: t_int_balance | E28: Không dùng | F28: decimal(15,4) | G28: T24_ACCOUNT.T_INT_BALANCE
A29: T24 | B29: ACCOUNT | C29: sat_account_other | D29: t_ref_officer | E29: Không dùng | F29: string | G29: T24_ACCOUNT.T_REF_OFFICER
A30: T24 | B30: ACCOUNT | C30: sat_account_other | D30: t_master_account | E30: Không dùng | F30: string | G30: T24_ACCOUNT.T_MASTER_ACCOUNT
A31: T24 | B31: ACCOUNT | C31: sat_account_other | D31: t_int_liqu_acct | E31: Không dùng | F31: string | G31: T24_ACCOUNT.T_INT_LIQU_ACCT
A32: T24 | B32: ACCOUNT | C32: sat_account_other | D32: t_accr_dr_amount | E32: Không dùng | F32: string | G32: T24_ACCOUNT.T_ACCR_DR_AMOUNT
A33: T24 | B33: ACCOUNT | C33: sat_account_other | D33: t_dpi_fin_date | E33: Không dùng (ptud 744 ) | F33: string | G33: T24_ACCOUNT.T_DPI_FIN_DATE
A34: T24 | B34: ACCOUNT | C34: sat_account_other | D34: t_tran_last_cr_cust | E34: Không dùng | F34: string | G34: T24_ACCOUNT.T_TRAN_LAST_CR_CUST
A35: T24 | B35: ACCOUNT | C35: sat_account_other | D35: t_tran_last_dr_cust | E35: Không dùng | F35: string | G35: T24_ACCOUNT.T_TRAN_LAST_DR_CUST
A36: T24 | B36: ACCOUNT | C36: sat_account_locked_events | D36: ac_locked_events_hashkey | E36: Hub Hash Key Account Locked | F36: string | G36: T24_AC_LOCKED_EVENTS.ID | H36: [PK]
A37: T24 | B37: ACCOUNT | C37: sat_account_locked_events | D37: t_account_number | E37: Số tài khoản | F37: string | G37: T24_AC_LOCKED_EVENTS.T_ACCOUNT_NUMBER
A38: T24 | B38: ACCOUNT | C38: sat_account_locked_events | D38: t_description | E38: Diễn giải | F38: string | G38: T24_AC_LOCKED_EVENTS.T_DESCRIPTION
A39: T24 | B39: ACCOUNT | C39: sat_account_locked_events | D39: t_from_date | E39: Từ ngày | F39: string | G39: T24_AC_LOCKED_EVENTS.T_FROM_DATE
A40: T24 | B40: ACCOUNT | C40: sat_account_locked_events | D40: t_to_date | E40: Đến ngày | F40: string | G40: T24_AC_LOCKED_EVENTS.T_TO_DATE
...

Sheet Summary Raw Vault
A1: Source | B1: Group | C1: Table Name | D1: Description | E1: Relationship of Links | F1: Satellite Content Classification | G1: Note
A2: All | B2: REFERENCE | C2: reference | D2: Bảng tổng hợp tất cả các bảng danh mục chứa thông tin mô tả và phân loại từ các nguồn T24, Way4, Omni, BPM
A3: T24 | B3: ACCOUNT | C3: hub_virtual_account | D3: Bảng định danh số tài khoản của KHDN (tài khoản ảo để thanh toán hóa đơn, thu hộ,...)
A4: T24 | B4: ACCOUNT | C4: sts_hub_virtual_account | D4: Bảng theo dõi trạng thái I (Insert - Thêm mới/Tái nhập) và D (Delete - Xóa) của các Key nằm trong bảng T24_ocbh_sub_virtual_account khi được load vào hub_virtual_account
A5: T24 | B5: ACCOUNT | C5: hub_account_locked_events | D5: Bảng định danh mã phong tỏa tài khoản
A6: T24 | B6: ACCOUNT | C6: sts_hub_account_locked_events | D6: Bảng theo dõi trạng thái I (Insert - Thêm mới/Tái nhập) và D (Delete - Xóa) của các Key nằm trong bảng T24_account_locked_events khi được load vào hub_account_locked_events
A7: T24 | B7: ACCOUNT | C7: hub_account | D7: Bảng định danh số tài khoản: toàn bộ tài khoản của KH và tài khoản nội bộ, tài khoản working account
A8: T24 | B8: ACCOUNT | C8: sts_hub_account | D8: Bảng theo dõi trạng thái I (Insert - Thêm mới/Tái nhập) và D (Delete - Xóa) của các Key nằm trong bảng T24_account khi được load vào hub_account | G8: Union thêm bảng T24_ACCOUNT_CLOSED để lấy ra những trường hợp mà tài khoản tạo rồi xóa luôn trong ngày Các bảng phụ của T24_ACCOUNT được load vào: t24_account_debit_int t24_account_credit_int t24_accr_acct_cr t24_accr_acct_dr t24_ocbh_ac_restrict t24_stmt_acct_cr t24_stmt_acct_dr t24_acct_activity
A9: T24 | B9: ACCOUNT | C9: sat_virtual_account | D9: Thông tin thanh toán hóa đơn, thu hộ,... của các tài khoản ảo của KHDN (tạo từ bảng T24_ocbh_sub_virtual_account) | F9: information
A10: T24 | B10: ACCOUNT | C10: sat_account_system | D10: Thông tin hệ thống (người nhập, người duyệt, số lần thay đổi,...) | F10: system
A11: T24 | B11: ACCOUNT | C11: sat_account_other | D11: Bảng bổ sung cho các trường không sử dụng | F11: other
A12: T24 | B12: ACCOUNT | C12: sat_account_locked_events | D12: Thông tin các tài khoản bị phong tỏa số dư | F12: information
A13: T24 | B13: ACCOUNT | C13: sat_account_information | D13: Thông tin chung tài khoản (Tên TK, ngày mở TK, ngày tạo,...) | F13: information
A14: T24 | B14: ACCOUNT | C14: sat_account_debit_int | D14: Thông tin về lãi suất cho số dư nợ trên từng tài khoản (mã code phí, cơ sở tính lãi, cách tính số dư ghi nợ,...) (tạo từ bảng t24_account_debit_int) | F14: information
A15: T24 | B15: ACCOUNT | C15: sts_hub_account_debit_int | D15: Bảng theo dõi trạng thái I (Insert - Thêm mới/Tái nhập) và D (Delete - Xóa) của các Key được bổ sung từ bảng phụ T24_account_debit_int vào hub_account (các ID tồn tại trong T24_account_debit_int nhưng không có trong bảng chính T24_account)
A16: T24 | B16: ACCOUNT | C16: sat_account_credit_int | D16: Thông tin lãi suất trên số dư có cho từng tài khoản (cơ sở tính lãi, loại số dư tính lãi ghi có, phương pháp tính lãi ghi có, lãi suất ghi có,..) (tạo từ bảng t24_account_credit_int) | F16: information
A17: T24 | B17: ACCOUNT | C17: sts_hub_account_credit_int | D17: Bảng theo dõi trạng thái I (Insert - Thêm mới/Tái nhập) và D (Delete - Xóa) của các Key được bổ sung từ bảng phụ T24_account_credit_int vào hub_account (các ID tồn tại trong T24_account_credit_int nhưng không có trong bảng chính T24_account)
A18: T24 | B18: ACCOUNT | C18: sat_account_classification | D18: Thông tin phân loại tài khoản (mã phân loại, mã nhóm, mã gói, mã hạn mức,...) | F18: classification
A19: T24 | B19: ACCOUNT | C19: sat_account_balance | D19: Thông tin số dư tài khoản (số dư đầu ngày, số dư hiện tại, số dư khả dụng, số dư bị phong tỏa...) | F19: balance
A20: T24 | B20: ACCOUNT | C20: link_virtual_account_customer | D20: Liên kết số tài khoản của KHDN (tài khoản ảo) với khách hàng là chủ tài khoản
A21: T24 | B21: ACCOUNT | C21: link_virtual_account_account_t24 | D21: Liên kết số tài khoản của KHDN (tài khoản ảo) với tài khoản ghi có ở hệ thống T24
A22: T24 | B22: ACCOUNT | C22: link_account_locked_events_branch | D22: Liên kết mã phong tỏa tài khoản với chi nhánh quản lý phong tỏa
A23: T24 | B23: ACCOUNT | C23: link_account_locked_events_account | D23: Liên kết mã phong tỏa tài khoản với số tài khoản ở T24_ACCOUNT
A24: T24 | B24: ACCOUNT | C24: link_account_limit | D24: Liên kết tài khoản với hạn mức gắn với tài khoản
A25: T24 | B25: ACCOUNT | C25: effsat_link_account_limit | D25: Bảng thông tin theo dõi hiệu lực của mối quan hệ liên kết giữa tài khoản và mã hạn mức
A26: T24 | B26: ACCOUNT | C26: link_account_dept_acct_officer | D26: Liên kết tài khoản với NV bán hàng
A27: T24 | B27: ACCOUNT | C27: effsat_link_account_dept_acct_officer | D27: Bảng thông tin theo dõi hiệu lực của mối quan hệ liên kết giữa tài khoản và nhân viên bán hàng
A28: T24 | B28: ACCOUNT | C28: link_account_customer | D28: Liên kết tài khoản với khách hàng là chủ tài khoản
A29: T24 | B29: ACCOUNT | C29: link_account_branch | D29: Liên kết tài khoản với chi nhánh quản lý tài khoản
A30: T24 | B30: ACCOUNT | C30: sat_accr_acct_cr_information | D30: Bảng thông tin khai báo lãi suất trên số dư Có cho từng tài khoản (tạo từ bảng T24_ACCR_ACCT_CR) | F30: information
A31: T24 | B31: ACCOUNT | C31: sat_accr_acct_cr_dynamic | D31: Bảng chứa những trường có tần suất thay đổi nhiều của bảng khai báo lãi suất trên số dư Có cho từng tài khoản (gồm Ngày cuối kì tính lãi, Ngày post tính lãi cuối, Số ngày tính lãi, Số tiền lãi, Tổng tiền lãi) | F31: dynamic
A32: T24 | B32: ACCOUNT | C32: sat_accr_acct_cr_other | D32: Bảng bổ sung cho các trường không sử dụng của bảng nguồn T24_ACCR_ACCT_CR | F32: other
A33: T24 | B33: ACCOUNT | C33: sts_hub_account_accr_acct_cr | D33: Bảng theo dõi trạng thái I (Insert - Thêm mới/Tái nhập) và D (Delete - Xóa) của các Key nằm trong bảng T24_accr_acct_cr khi được load vào hub_account (các ID tồn tại trong bảng T24_accr_acct_cr nhưng không có trong bảng chính T24_account)
A34: T24 | B34: ACCOUNT | C34: sat_accr_acct_dr_information | D34: Bảng thông tin khai báo lãi suất trên số dư Nợ cho từng tài khoản (tạo từ bảng T24_ACCR_ACCT_DR) | F34: information
A35: T24 | B35: ACCOUNT | C35: sat_accr_acct_dr_dynamic | D35: Bảng chứa những trường có tần suất thay đổi nhiều của bảng khai báo lãi suất trên số dư Nợ cho từng tài khoản (gồm Ngày cuối kì tính lãi, Số ngày) | F35: dynamic
A36: T24 | B36: ACCOUNT | C36: sts_hub_account_accr_acct_dr | D36: Bảng theo dõi trạng thái I (Insert - Thêm mới/Tái nhập) và D (Delete - Xóa) của các Key nằm trong bảng T24_accr_acct_dr khi được load vào hub_account (các ID tồn tại trong bảng T24_accr_acct_dr nhưng không có trong bảng chính T24_account)
A37: T24 | B37: ACCOUNT | C37: sat_acct_activity | D37: Bảng thông tin lưu biến động số dư tài khoản trong 1 tháng - ghi nhận các giao dịch phát sinh làm thay đổi số dư nợ, số dư có của tài khoản khách hàng. | F37: information
A38: T24 | B38: ACCOUNT | C38: sts_hub_account_acct_activity | D38: Bảng theo dõi trạng thái I (Insert - Thêm mới/Tái nhập) và D (Delete - Xóa) của các Key nằm trong bảng T24_acct_activity khi được load vào hub_account (các ID tồn tại trong bảng T24_acct_activity nhưng không có trong bảng chính T24_account)
A39: T24 | B39: ACCOUNT | C39: sat_ac_restrict | D39: Bảng thông tin đăng kí tài khoản hạn chế của tài khoản thấu chi và đăng kí thu hộ (tạo từ bảng T24_OCBH_AC_RESTRICT) | F39: information
A40: T24 | B40: ACCOUNT | C40: sts_hub_account_ac_restrict | D40: Bảng theo dõi trạng thái I (Insert - Thêm mới/Tái nhập) và D (Delete - Xóa) của các Key nằm trong bảng T24_ocbh_ac_restrict khi được load vào hub_account (các ID tồn tại trong bảng T24_ocbh_ac_restrict nhưng không có trong bảng chính T24_account)
...

Sheet Summary Tracking Zone C
A1: Zone C Vault Mapping - Tracking by Source Table
A2: Source | B2: Mapping PIC | C2: Dev PIC | D2: Total Source Tables | E2: Source Mapping Completed | F2: % Mapping | G2: hub + sts | H2: link | I2: sat + effsat + non_his_sat | J2: ref_ | K2: Total Vault Tables | L2: Vault Mapping Completed | M2: % Mapping | N2: Dev Completed | O2: % Dev (vs Mapping) | P2: Note
A3: COMB | B3: {=IFERROR(INDEX(_xlfn._xlws.FILTER('Tracking Mapping&Dev Zone C'!$C:$C,('Tracking Mapping&Dev Zone C'!$A:$A=$A3)*('Tracking Mapping&Dev Zone C'!$C:$C<>"")),1),"")} -> TrangNT | C3: {=IFERROR(_xlfn.TEXTJOIN(", ",TRUE,_xlfn.UNIQUE(_xlfn._xlws.FILTER('Tracking Mapping&Dev Zone C'!$E:$E,('Tracking Mapping&Dev Zone C'!$A:$A=$A3)*('Tracking Mapping&Dev Zone C'!$E:$E<>"")))),"")} -> Huy | D3: =COUNTIF('Source Tables Zone C'!$A$2:$A$200,$A3) -> 5 | E3: =COUNTIFS('Source Tables Zone C'!$A$2:$A$200,$A3,'Source Tables Zone C'!$C$2:$C$200,"Done") -> 5 | F3: =IFERROR(E3/D3,"") -> 1 | G3: {=ROUND(SUMPRODUCT((('ZONE C Vault Mapping'!$A$2:$A$10174=$A3)*((LEFT('ZONE C Vault Mapping'!$B$2:$B$10174,4)="hub_")+(LEFT('ZONE C Vault Mapping'!$B$2:$B$10174,4)="sts_"))*('ZONE C Vault Mapping'!$H$2:$H$10174<>"Cancel"))/COUNTIFS('ZONE C Vault Mapping'!$B$2:$B$10174,'ZONE C Vault Mapping'!$B$2:$B$10174&"")),0)} -> 5 | H3: {=ROUND(SUMPRODUCT(('ZONE C Vault Mapping'!$A$2:$A$10174=$A3)*(LEFT('ZONE C Vault Mapping'!$B$2:$B$10174,5)="link_")*('ZONE C Vault Mapping'!$H$2:$H$10174<>"Cancel")/COUNTIFS('ZONE C Vault Mapping'!$B$2:$B$10174,'ZONE C Vault Mapping'!$B$2:$B$10174&"")),0)} -> 2 | I3: {=ROUND(SUMPRODUCT((('ZONE C Vault Mapping'!$A$2:$A$10174=$A3)*((LEFT('ZONE C Vault Mapping'!$B$2:$B$10174,4)="sat_")+(LEFT('ZONE C Vault Mapping'!$B$2:$B$10174,7)="effsat_")+(LEFT('ZONE C Vault Mapping'!$B$2:$B$10174,12)="non_his_sat_"))*('ZONE C Vault Mapping'!$H$2:$H$10174<>"Cancel"))/COUNTIFS('ZONE C Vault Mapping'!$B$2:$B$10174,'ZONE C Vault Mapping'!$B$2:$B$10174&"")),0)} -> 11 | J3: {=ROUND(SUMPRODUCT((('ZONE C Vault Mapping'!$A$2:$A$10174=$A3)*(LEFT('ZONE C Vault Mapping'!$B$2:$B$10174,4)="ref_")*(IFERROR(_xlfn.XLOOKUP('ZONE C Vault Mapping'!$B$2:$B$10174,'Tracking Mapping&Dev Zone C'!$B:$B,'Tracking Mapping&Dev Zone C'!$D:$D),"")<>"Cancel"))/COUNTIFS('ZONE C Vault Mapping'!$B$2:$B$10174,'ZONE C Vault Mapping'!$B$2:$B$10174&"")),0)} -> 1 | K3: =SUM(G3:J3) -> 19 | L3: {=ROUND(SUMPRODUCT((('ZONE C Vault Mapping'!$A$2:$A$10174=$A3)*((LEFT('ZONE C Vault Mapping'!$B$2:$B$10174,4)="hub_")+(LEFT('ZONE C Vault Mapping'!$B$2:$B$10174,4)="sts_")+(LEFT('ZONE C Vault Mapping'!$B$2:$B$10174,5)="link_")+(LEFT('ZONE C Vault Mapping'!$B$2:$B$10174,4)="sat_")+(LEFT('ZONE C Vault Mapping'!$B$2:$B$10174,7)="effsat_")+(LEFT('ZONE C Vault Mapping'!$B$2:$B$10174,4)="ref_")+(LEFT('ZONE C Vault Mapping'!$B$2:$B$10174,12)="non_his_sat_"))*('ZONE C Vault Mapping'!$H$2:$H$10174="Done"))/COUNTIFS('ZONE C Vault Mapping'!$B$2:$B$10174,'ZONE C Vault Mapping'!$B$2:$B$10174&"")),0)} -> 19 | M3: =IFERROR(L3/K3,"") -> 1 | N3: {=ROUND(SUMPRODUCT((('ZONE C Vault Mapping'!$A$2:$A$10174=$A3)*((LEFT('ZONE C Vault Mapping'!$B$2:$B$10174,4)="hub_")+(LEFT('ZONE C Vault Mapping'!$B$2:$B$10174,4)="sts_")+(LEFT('ZONE C Vault Mapping'!$B$2:$B$10174,5)="link_")+(LEFT('ZONE C Vault Mapping'!$B$2:$B$10174,4)="sat_")+(LEFT('ZONE C Vault Mapping'!$B$2:$B$10174,7)="effsat_")+(LEFT('ZONE C Vault Mapping'!$B$2:$B$10174,4)="ref_")+(LEFT('ZONE C Vault Mapping'!$B$2:$B$10174,12)="non_his_sat_"))*('ZONE C Vault Mapping'!$H$2:$H$10174<>"Cancel")*(IFERROR(_xlfn.XLOOKUP('ZONE C Vault Mapping'!$B$2:$B$10174,'Tracking Mapping&Dev Zone C'!$B:$B,'Tracking Mapping&Dev Zone C'!$F:$F),"")="Done"))/COUNTIFS('ZONE C Vault Mapping'!$B$2:$B$10174,'ZONE C Vault Mapping'!$B$2:$B$10174&"")),0)} -> 11 | O3: =IFERROR(N3/L3,"") -> 0.57894737
A4: OCBCHANNEL | B4: {=IFERROR(INDEX(_xlfn._xlws.FILTER('Tracking Mapping&Dev Zone C'!$C:$C,('Tracking Mapping&Dev Zone C'!$A:$A=$A4)*('Tracking Mapping&Dev Zone C'!$C:$C<>"")),1),"")} -> TrangNT | C4: {=IFERROR(_xlfn.TEXTJOIN(", ",TRUE,_xlfn.UNIQUE(_xlfn._xlws.FILTER('Tracking Mapping&Dev Zone C'!$E:$E,('Tracking Mapping&Dev Zone C'!$A:$A=$A4)*('Tracking Mapping&Dev Zone C'!$E:$E<>"")))),"")} -> Thụ | D4: =COUNTIF('Source Tables Zone C'!$A$2:$A$200,$A4) -> 27 | E4: =COUNTIFS('Source Tables Zone C'!$A$2:$A$200,$A4,'Source Tables Zone C'!$C$2:$C$200,"Done") -> 26 | F4: =IFERROR(E4/D4,"") -> 0.96296296 | G4: {=ROUND(SUMPRODUCT((('ZONE C Vault Mapping'!$A$2:$A$10174=$A4)*((LEFT('ZONE C Vault Mapping'!$B$2:$B$10174,4)="hub_")+(LEFT('ZONE C Vault Mapping'!$B$2:$B$10174,4)="sts_"))*('ZONE C Vault Mapping'!$H$2:$H$10174<>"Cancel"))/COUNTIFS('ZONE C Vault Mapping'!$B$2:$B$10174,'ZONE C Vault Mapping'!$B$2:$B$10174&"")),0)} -> 17 | H4: {=ROUND(SUMPRODUCT(('ZONE C Vault Mapping'!$A$2:$A$10174=$A4)*(LEFT('ZONE C Vault Mapping'!$B$2:$B$10174,5)="link_")*('ZONE C Vault Mapping'!$H$2:$H$10174<>"Cancel")/COUNTIFS('ZONE C Vault Mapping'!$B$2:$B$10174,'ZONE C Vault Mapping'!$B$2:$B$10174&"")),0)} -> 38 | I4: {=ROUND(SUMPRODUCT((('ZONE C Vault Mapping'!$A$2:$A$10174=$A4)*((LEFT('ZONE C Vault Mapping'!$B$2:$B$10174,4)="sat_")+(LEFT('ZONE C Vault Mapping'!$B$2:$B$10174,7)="effsat_")+(LEFT('ZONE C Vault Mapping'!$B$2:$B$10174,12)="non_his_sat_"))*('ZONE C Vault Mapping'!$H$2:$H$10174<>"Cancel"))/COUNTIFS('ZONE C Vault Mapping'!$B$2:$B$10174,'ZONE C Vault Mapping'!$B$2:$B$10174&"")),0)} -> 35 | J4: {=ROUND(SUMPRODUCT((('ZONE C Vault Mapping'!$A$2:$A$10174=$A4)*(LEFT('ZONE C Vault Mapping'!$B$2:$B$10174,4)="ref_")*(IFERROR(_xlfn.XLOOKUP('ZONE C Vault Mapping'!$B$2:$B$10174,'Tracking Mapping&Dev Zone C'!$B:$B,'Tracking Mapping&Dev Zone C'!$D:$D),"")<>"Cancel"))/COUNTIFS('ZONE C Vault Mapping'!$B$2:$B$10174,'ZONE C Vault Mapping'!$B$2:$B$10174&"")),0)} -> 4 | K4: =SUM(G4:J4) -> 94 | L4: {=ROUND(SUMPRODUCT((('ZONE C Vault Mapping'!$A$2:$A$10174=$A4)*((LEFT('ZONE C Vault Mapping'!$B$2:$B$10174,4)="hub_")+(LEFT('ZONE C Vault Mapping'!$B$2:$B$10174,4)="sts_")+(LEFT('ZONE C Vault Mapping'!$B$2:$B$10174,5)="link_")+(LEFT('ZONE C Vault Mapping'!$B$2:$B$10174,4)="sat_")+(LEFT('ZONE C Vault Mapping'!$B$2:$B$10174,7)="effsat_")+(LEFT('ZONE C Vault Mapping'!$B$2:$B$10174,4)="ref_")+(LEFT('ZONE C Vault Mapping'!$B$2:$B$10174,12)="non_his_sat_"))*('ZONE C Vault Mapping'!$H$2:$H$10174="Done"))/COUNTIFS('ZONE C Vault Mapping'!$B$2:$B$10174,'ZONE C Vault Mapping'!$B$2:$B$10174&"")),0)} -> 94 | M4: =IFERROR(L4/K4,"") -> 1 | N4: {=ROUND(SUMPRODUCT((('ZONE C Vault Mapping'!$A$2:$A$10174=$A4)*((LEFT('ZONE C Vault Mapping'!$B$2:$B$10174,4)="hub_")+(LEFT('ZONE C Vault Mapping'!$B$2:$B$10174,4)="sts_")+(LEFT('ZONE C Vault Mapping'!$B$2:$B$10174,5)="link_")+(LEFT('ZONE C Vault Mapping'!$B$2:$B$10174,4)="sat_")+(LEFT('ZONE C Vault Mapping'!$B$2:$B$10174,7)="effsat_")+(LEFT('ZONE C Vault Mapping'!$B$2:$B$10174,4)="ref_")+(LEFT('ZONE C Vault Mapping'!$B$2:$B$10174,12)="non_his_sat_"))*('ZONE C Vault Mapping'!$H$2:$H$10174<>"Cancel")*(IFERROR(_xlfn.XLOOKUP('ZONE C Vault Mapping'!$B$2:$B$10174,'Tracking Mapping&Dev Zone C'!$B:$B,'Tracking Mapping&Dev Zone C'!$F:$F),"")="Done"))/COUNTIFS('ZONE C Vault Mapping'!$B$2:$B$10174,'ZONE C Vault Mapping'!$B$2:$B$10174&"")),0)} -> 52 | O4: =IFERROR(N4/L4,"") -> 0.55319149
A5: T24 | B5: {=IFERROR(INDEX(_xlfn._xlws.FILTER('Tracking Mapping&Dev Zone C'!$C:$C,('Tracking Mapping&Dev Zone C'!$A:$A=$A5)*('Tracking Mapping&Dev Zone C'!$C:$C<>"")),1),"")} -> TrangNT | C5: {=IFERROR(_xlfn.TEXTJOIN(", ",TRUE,_xlfn.UNIQUE(_xlfn._xlws.FILTER('Tracking Mapping&Dev Zone C'!$E:$E,('Tracking Mapping&Dev Zone C'!$A:$A=$A5)*('Tracking Mapping&Dev Zone C'!$E:$E<>"")))),"")} -> Thụ, Huy | D5: =COUNTIF('Source Tables Zone C'!$A$2:$A$200,$A5) -> 8 | E5: =COUNTIFS('Source Tables Zone C'!$A$2:$A$200,$A5,'Source Tables Zone C'!$C$2:$C$200,"Done") -> 8 | F5: =IFERROR(E5/D5,"") -> 1 | G5: {=ROUND(SUMPRODUCT((('ZONE C Vault Mapping'!$A$2:$A$10174=$A5)*((LEFT('ZONE C Vault Mapping'!$B$2:$B$10174,4)="hub_")+(LEFT('ZONE C Vault Mapping'!$B$2:$B$10174,4)="sts_"))*('ZONE C Vault Mapping'!$H$2:$H$10174<>"Cancel"))/COUNTIFS('ZONE C Vault Mapping'!$B$2:$B$10174,'ZONE C Vault Mapping'!$B$2:$B$10174&"")),0)} -> 0 | H5: {=ROUND(SUMPRODUCT(('ZONE C Vault Mapping'!$A$2:$A$10174=$A5)*(LEFT('ZONE C Vault Mapping'!$B$2:$B$10174,5)="link_")*('ZONE C Vault Mapping'!$H$2:$H$10174<>"Cancel")/COUNTIFS('ZONE C Vault Mapping'!$B$2:$B$10174,'ZONE C Vault Mapping'!$B$2:$B$10174&"")),0)} -> 0 | I5: {=ROUND(SUMPRODUCT((('ZONE C Vault Mapping'!$A$2:$A$10174=$A5)*((LEFT('ZONE C Vault Mapping'!$B$2:$B$10174,4)="sat_")+(LEFT('ZONE C Vault Mapping'!$B$2:$B$10174,7)="effsat_")+(LEFT('ZONE C Vault Mapping'!$B$2:$B$10174,12)="non_his_sat_"))*('ZONE C Vault Mapping'!$H$2:$H$10174<>"Cancel"))/COUNTIFS('ZONE C Vault Mapping'!$B$2:$B$10174,'ZONE C Vault Mapping'!$B$2:$B$10174&"")),0)} -> 3 | J5: {=ROUND(SUMPRODUCT((('ZONE C Vault Mapping'!$A$2:$A$10174=$A5)*(LEFT('ZONE C Vault Mapping'!$B$2:$B$10174,4)="ref_")*(IFERROR(_xlfn.XLOOKUP('ZONE C Vault Mapping'!$B$2:$B$10174,'Tracking Mapping&Dev Zone C'!$B:$B,'Tracking Mapping&Dev Zone C'!$D:$D),"")<>"Cancel"))/COUNTIFS('ZONE C Vault Mapping'!$B$2:$B$10174,'ZONE C Vault Mapping'!$B$2:$B$10174&"")),0)} -> 2 | K5: =SUM(G5:J5) -> 5 | L5: {=ROUND(SUMPRODUCT((('ZONE C Vault Mapping'!$A$2:$A$10174=$A5)*((LEFT('ZONE C Vault Mapping'!$B$2:$B$10174,4)="hub_")+(LEFT('ZONE C Vault Mapping'!$B$2:$B$10174,4)="sts_")+(LEFT('ZONE C Vault Mapping'!$B$2:$B$10174,5)="link_")+(LEFT('ZONE C Vault Mapping'!$B$2:$B$10174,4)="sat_")+(LEFT('ZONE C Vault Mapping'!$B$2:$B$10174,7)="effsat_")+(LEFT('ZONE C Vault Mapping'!$B$2:$B$10174,4)="ref_")+(LEFT('ZONE C Vault Mapping'!$B$2:$B$10174,12)="non_his_sat_"))*('ZONE C Vault Mapping'!$H$2:$H$10174="Done"))/COUNTIFS('ZONE C Vault Mapping'!$B$2:$B$10174,'ZONE C Vault Mapping'!$B$2:$B$10174&"")),0)} -> 5 | M5: =IFERROR(L5/K5,"") -> 1 | N5: {=ROUND(SUMPRODUCT((('ZONE C Vault Mapping'!$A$2:$A$10174=$A5)*((LEFT('ZONE C Vault Mapping'!$B$2:$B$10174,4)="hub_")+(LEFT('ZONE C Vault Mapping'!$B$2:$B$10174,4)="sts_")+(LEFT('ZONE C Vault Mapping'!$B$2:$B$10174,5)="link_")+(LEFT('ZONE C Vault Mapping'!$B$2:$B$10174,4)="sat_")+(LEFT('ZONE C Vault Mapping'!$B$2:$B$10174,7)="effsat_")+(LEFT('ZONE C Vault Mapping'!$B$2:$B$10174,4)="ref_")+(LEFT('ZONE C Vault Mapping'!$B$2:$B$10174,12)="non_his_sat_"))*('ZONE C Vault Mapping'!$H$2:$H$10174<>"Cancel")*(IFERROR(_xlfn.XLOOKUP('ZONE C Vault Mapping'!$B$2:$B$10174,'Tracking Mapping&Dev Zone C'!$B:$B,'Tracking Mapping&Dev Zone C'!$F:$F),"")="Done"))/COUNTIFS('ZONE C Vault Mapping'!$B$2:$B$10174,'ZONE C Vault Mapping'!$B$2:$B$10174&"")),0)} -> 4 | O5: =IFERROR(N5/L5,"") -> 0.8
