Workbook

Sheet Hướng dẫn
B2: CHECKLIST REVIEW CODE MAPPING SILVER (DATA VAULT 2.0) SANG GOLD (DATA MART) – ZONE C OCB
B4: Mục đích
B5: Đội Data Engineer của Raffles dùng checklist này để tự rà soát code và mapping của từng bảng/khung nhìn Zone C trước khi gửi OCB review. Nội dung checklist lấy từ hai nguồn: các tiêu chí đã thống nhất với OCB (sheet "Checklist - Raffles" và "Quality check") và các lỗi thực tế ghi nhận trong quá trình review Batch 1 (Issue log). Cách kiểm tra của từng tiêu chí tham chiếu trực tiếp đến tài liệu OCB_DBX_ZONEC – Technical Document v1.1, mục III.4.2 "Quy tắc khi xử lí các bảng từ Silver".
B6: Cách sử dụng
B7: 1. Sheet "Checklist tiêu chí": mô tả điều kiện đạt và cách kiểm tra của từng tiêu chí, kèm mục tài liệu tham chiếu.
B8: 2. Sheet "Review theo bảng": mỗi dòng là một bảng/khung nhìn Gold. Với từng tiêu chí, DE chọn Pass / Fail / N/A từ danh sách chọn. Tiêu chí Fail phải ghi bằng chứng tại cột "Ghi chú / Bằng chứng lỗi" theo dạng: mã tiêu chí, tên file script, dòng code hoặc tên CTE liên quan.
B9: 3. Tỷ lệ lỗi tính tự động theo trọng số đã thống nhất với OCB: Nhóm 1 – Summary/Mapping 10%, Nhóm 2 – Logic 80%, Nhóm 3 – Optimization 10%. Một tiêu chí Fail thì cả nhóm đó tính là lỗi cho bảng đang xét.
B10: 4. Sheet "Tổng hợp Dashboard": tổng hợp số bảng Đạt / Không đạt theo batch và so với ngưỡng lỗi cho phép (Batch 1: 30%; Batch 2 và Batch 3: 20%).
B11: 5. Chỉ gửi code và mapping sang OCB khi bảng có kết luận "Đạt". Bảng "Không đạt" phải sửa theo pattern chuẩn nêu tại cột "Điều kiện đạt / Cách kiểm tra" rồi review lại.
B12: Bốn lỗi phải kiểm tra kỹ (rút từ Issue log Batch 1)
B13: - Điều kiện source_event_date <= :DATADT bị bỏ sót ở một vài bảng trong cùng script, hoặc đặt thêm cận dưới (>= start_date) làm bỏ sót bản ghi trạng thái mới nhất – Issue log #1.
B14: - Cùng một mục đích lấy bản ghi hiệu lực nhưng mỗi script lọc cdc_status một kiểu khác nhau – Issue log #2. Toàn bộ Zone C dùng một pattern duy nhất tại mục III.4.2.1.
... B16: - Bảng DIM sinh surrogate key bằng MAX(<DIM_ID>) + ROW_NUMBER(), trùng khóa khi chạy song song hoặc nạp lại lịch sử – Issue log #4. Dùng APPLY CHANGES … STORED AS SCD TYPE 2.

Sheet Checklist tiêu chí
A1: Nhóm | B1: Trọng số nhóm | C1: Mã | D1: Tiêu chí kiểm tra | E1: Điều kiện đạt / Cách kiểm tra | F1: Tham chiếu (Technical Document / Issue log / Checklist RVN-OCB)
A2: Nhóm 1 - Summary / Mapping | B2: 0.1 | C2: 1.1 | D2: Mapping đầy đủ từ Silver và nguồn upload sang Gold | E2: Đối chiếu tài liệu mapping source-to-target với script: đủ cột đầu ra, đủ bảng nguồn cần dùng, không thêm cột ngoài đặc tả. Ghi dữ liệu vào đúng catalog/schema đích ocb_datavault_${env}_curated.<schema>, không hard-code tên catalog. | F2: TDD mục III.4.1 Quy ước chung; Quality check tiêu chí 1
A3: Nhóm 1 - Summary / Mapping | B3: 0.1 | C3: 1.2 | D3: Danh sách bảng và khung nhìn khớp tài liệu thiết kế | E3: Danh sách đối tượng triển khai trong batch khớp danh sách đã thống nhất với OCB. Thay đổi phạm vi hoặc mô hình dữ liệu phải được thống nhất và cập nhật vào tài liệu trước khi triển khai. | F3: TDD v1.1 mục I.3 Phạm vi tài liệu; Plan điều chỉnh 5.3.3
A4: Nhóm 2 - Logic | B4: 0.8 | C4: 2.1 | D4: Chỉ lấy bản ghi Hub đang có hiệu lực | E4: Join hub_* với sts_hub_* theo pattern tại mục III.4.2.1: GROUP BY hashkey, HAVING max_by(cdc_status, source_event_date) = 'D' để lấy tập khóa đã xóa, sau đó LEFT JOIN và loại các khóa này khỏi kết quả. Chỉ giữ bản ghi đã xóa khi có yêu cầu nghiệp vụ và phải ghi rõ trong mapping. | F4: TDD v1.1 mục III.4.2.1; Checklist RVN-OCB #1; Issue log #3
A5: Nhóm 2 - Logic | B5: 0.8 | C5: 2.2 | D5: Dùng một pattern thống nhất để lấy bản ghi hiệu lực | E5: Toàn bộ script Zone C dùng chung một pattern max_by(cdc_status, source_event_date) trên sts_hub. Không để hai script cùng xử lý một loại logic theo hai cách khác nhau, ví dụ một script lọc cdc_status <> 'D' trực tiếp trên satellite, script khác lọc = 'D' trên sts_hub. | F5: TDD v1.1 mục III.4.2.1; Issue log #2
A6: Nhóm 2 - Logic | B6: 0.8 | C6: 2.3 | D6: Điều kiện trạng thái đặt ở lớp ngoài, không đặt trong ON của LEFT JOIN | E6: Điều kiện lọc trạng thái và điều kiện lấy bản ghi mới nhất đặt tại WHERE hoặc QUALIFY của lớp ngoài. Đặt trong ON của LEFT JOIN sẽ sai kết quả khi không match. Ngoại lệ được phép: join PIT với satellite theo source_event_date = <sat>_src_ev_dt là equi-join nên đặt trong ON. | F6: TDD v1.1 mục III.4.2.3 và III.4.2.4; Issue log #3
A7: Nhóm 2 - Logic | B7: 0.8 | C7: 2.4 | D7: Điều kiện source_event_date áp dụng nhất quán trong cùng script | E7: Mọi hub, satellite, link, effsat trong cùng một script đều chặn source_event_date <= TO_DATE(:DATADT,'yyyyMMdd'), không đặt cận dưới. Riêng nhóm bảng transaction tại mục "Các trường hợp đặc biệt" lọc source_event_date = :DATADT. Bảng PIT lọc theo snapshot_date. | F7: TDD v1.1 mục III.4.2 và mục "Các trường hợp đặc biệt"; Issue log #1
A8: Nhóm 2 - Logic | B8: 0.8 | C8: 2.5 | D8: Không lặp lại lỗi logic đã được xử lý trước đó | E8: Đối chiếu với các lỗi mà DA Data Vault đã xác nhận sửa ở các lần review trước; script viết lại trên nền tảng mới không quay lại logic cũ. Ghi rõ trong ghi chú các điểm đã từng bị sửa để reviewer đối chiếu nhanh. | F8: Issue log #1
A9: Nhóm 2 - Logic | B9: 0.8 | C9: 2.6 | D9: Bảng DIM áp dụng SCD Type 2 theo cơ chế APPLY CHANGES | E9: Bảng DIM dùng APPLY CHANGES INTO … KEYS (…) SEQUENCE BY … STORED AS SCD TYPE 2 trên streaming table. Không tự sinh surrogate key bằng MAX(<DIM_ID>) + ROW_NUMBER() vì trùng khóa khi chạy song song hoặc nạp lại dữ liệu lịch sử. | F9: TDD v1.1 mục III.2.3 và III.2.4; Issue log #4
A10: Nhóm 2 - Logic | B10: 0.8 | C10: 2.7 | D10: CASE WHEN đủ nhánh so với job hiện hữu | E10: So từng nhánh CASE WHEN với job on-prem tương ứng, gồm cả nhánh ELSE và giá trị mặc định. Giữ nguyên logic cũ nếu chưa có thay đổi được thống nhất; thay đổi phải ghi vào tài liệu mapping. | F10: Checklist RVN-OCB #10
A11: Nhóm 2 - Logic | B11: 0.8 | C11: 2.8 | D11: Cột SUM và COUNT xử lý giá trị NULL đúng | E11: Cột tổng hợp coalesce về 0 khi nghiệp vụ yêu cầu. Nếu code hiện hữu không dùng NVL thì giữ nguyên hành vi của code cũ và bổ sung NVL ở script đối soát để không lệch khi lấy hiệu số. | F11: Checklist RVN-OCB #11
A12: Nhóm 2 - Logic | B12: 0.8 | C12: 2.9 | D12: Subquery, custom function và điều kiện LIKE đúng ý nghĩa nghiệp vụ | E12: Đọc lại logic bên trong subquery, custom function và các điều kiện LIKE, xác nhận đúng ý nghĩa nghiệp vụ so với job hiện hữu, không chỉ đúng cú pháp. Ghi lại cách hiểu nghiệp vụ trong mapping để OCB xác nhận. | F12: Checklist RVN-OCB #6
A13: Nhóm 2 - Logic | B13: 0.8 | C13: 2.10 | D13: Aggregation lọc đúng kỳ dữ liệu | E13: Điều kiện lọc kỳ báo cáo đi kèm SUM/COUNT/AVG đúng phạm vi ngày hoặc tháng cần xử lý. Bảng nạp theo tháng lọc theo kỳ đang chạy, không quét toàn bộ lịch sử. | F13: Checklist RVN-OCB #7
... A21: Nhóm 3 - Optimization | B21: 0.1 | C21: 3.6 | D21: Window function dùng có chủ đích và có comment | E21: Chỉ dùng window function khi max_by hoặc QUALIFY không đáp ứng được yêu cầu nghiệp vụ. Khi dùng phải ghi comment nêu lý do ngay tại chỗ dùng. | F21: Checklist RVN-OCB #8

Sheet Review theo bảng
A1: STT | B1: Tên bảng / khung nhìn (Gold) | C1: Batch | D1: PIC review | E1: Ngày review | F1: NHÓM 1 - SUMMARY / MAPPING (trọng số 10%) | H1: NHÓM 2 - LOGIC (trọng số 80%) | T1: NHÓM 3 - OPTIMIZATION (trọng số 10%) | Z1: KẾT QUẢ TỔNG HỢP (tự động tính)
F2: Đủ mapping Silver → Gold (1.1) | G2: Danh sách bảng khớp thiết kế (1.2) | H2: Hub hiệu lực qua sts_hub (2.1) | I2: Một pattern lấy bản ghi hiệu lực (2.2) | J2: Điều kiện trạng thái ở lớp ngoài (2.3) | K2: source_event_date nhất quán (2.4) | L2: Không lặp lỗi đã xử lý (2.5) | M2: DIM SCD2 bằng APPLY CHANGES (2.6) | N2: CASE WHEN đủ nhánh (2.7) | O2: SUM/COUNT xử lý NULL (2.8) | P2: Subquery/function/ LIKE đúng nghiệp vụ (2.9) | Q2: Aggregation đúng kỳ dữ liệu (2.10) | R2: Join đúng key, link về hiện hành (2.11) | S2: Build từ CTE snapshot Silver (2.12) | T2: Không SELECT * (3.1) | U2: CTE không tính lại nhiều lần (3.2) | V2: Lọc trước join, partition pruning (3.3) | W2: Cache truy vấn dùng lại (3.4) | X2: MAX_BY thay ROW_NUMBER (3.5) | Y2: Window function có comment (3.6) | Z2: N1 Fail? | AA2: N2 Fail? | AB2: N3 Fail? | AC2: Tỷ lệ lỗi bảng | AD2: Ngưỡng cho phép | AE2: Kết luận | AF2: Ghi rõ: mã tiêu chí – file script – dòng/CTE | AG2: Đồng bộ tài liệu (script khác bản chính)
A3: 1 | B3: BPM_SPTC | C3: Batch 2 | E3: 2026-08-12 | F3: WARN | G3: Fail | H3: Pass | I3: Pass | J3: Pass | K3: Pass | L3: Pass | M3: Pass | N3: Fail | O3: WARN | P3: Pass | Q3: Pass | R3: Pass | S3: Pass | T3: Pass | U3: WARN | V3: Pass | W3: WARN | X3: WARN | Y3: Pass | Z3: =IF(B3="","",IF(COUNTIF(F3:G3,"Fail")>0,1,0)) -> 1 | AA3: =IF(B3="","",IF(COUNTIF(H3:S3,"Fail")>0,1,0)) -> 1 | AB3: =IF(B3="","",IF(COUNTIF(T3:Y3,"Fail")>0,1,0)) -> 0 | AC3: =IF(B3="","",0.1*Z3+0.8*AA3+0.1*AB3) -> 0.9 | AD3: =IF(B3="","",IF(C3="Batch 1",0.3,0.2)) -> 0.2 | AE3: =IF(B3="","",IF(AC3<=AD3,"Đạt","Không đạt")) -> Không đạt | AF3: ╔══ FAIL: 2 tiêu chí — 1.2, 2.7 ▼ 1.2 — Danh sách bảng/view Gold khớp tài liệu thiết kế đã duyệt • Lý do: BPM_SPTC không có workbook thiết kế tương ứng trong thư mục mapping → Cách sửa: Đảm bảo object có workbook thiết kế tương ứng trong thư mục --mapping-dir. Muốn đối chiếu với danh sách đã duyệt thì chạy thêm tham số --gold-list "<file danh sách Gold>.xlsx". ▼ 2.7 — CASE WHEN cover đủ nhánh như job on-prem • Lý do: 60/105 CASE KHÔNG có nhánh ELSE -> rơi ra ngoài mọi WHEN sẽ trả NULL âm thầm, tại dòng [] • Lý do: bổ sung ELSE (giá trị mặc định hoặc giá trị nghiệp vụ đúng như job on-prem) → Cách sửa: Mở job on-prem tương ứng (DataStage DSX hoặc SQL cũ), đối chiếu từng nhánh WHEN và cả nhánh ELSE. CASE không có ELSE sẽ trả NULL âm thầm — xác nhận đó là ý muốn hay thiếu nhánh. ╔══ WARN: 5 tiêu chí — 1.1, 2.8, 3.2, 3.4, 3.5 ▼ 1.1 — Đầy đủ mapping từ Silver/manual sang Gold • KHÔNG TÌM THẤY workbook thiết kế cho object BPM_SPTC nên không đối chiếu được danh sách cột (SQL có 127 cột đầu ra) ▼ 2.8 — Cột SUM/COUNT được COALESCE/NVL hợp lý • 7 biểu thức tổng hợp chưa coalesce: SUM(CASE WHEN loai = 0 THEN 1.0 ELSE loai END); SUM(loai); count_ycbs_gn = SUM(CASE WHEN b.trang_thai_ban_dau IN (7855, 7859, 7856) THE; count_ycbs_pd = SUM(CASE WHEN b.trang_thai_ban_dau IN (5353, 7828, 8463) THE; count_ycbs_st = SUM(CASE WHEN b.trang_thai_ban_dau IN (7829, 7848) THEN 1 EL; dg_trans_get_return = SUM(CASE WHEN ls.thao_tac_id = 1010 THEN 1 ELSE 0 END) • khi đối soát với hệ thống cũ phải bọc NVL/ISNULL CẢ HAI phía để không lệch khi trừ (Checklist RVN-OCB #11) ▼ 3.2 — CTE không bị scan lại nhiều lần • CTE bị tham chiếu lại nhiều lần: gd_hub x2, kh_hub x3, ts_hub x2, s_gd_tdcn x3, r_dm x11 ▼ 3.4 — Sử dụng CACHE cho query lặp lại trong cùng luồng • 5 CTE nặng dùng lại >= 2 lần mà không có CACHE: gd_hub, kh_hub, r_dm, s_gd_tdcn, ts_hub ▼ 3.5 — Ưu tiên MAX_BY + QUALIFY thay ROW_NUMBER() + WHERE rn = 1 • 5 khối dùng MAX_BY độc lập cho >5 cột (dòng 15, [10, 6, 8, 8, 7] cột/khối) — nên đổi sang ROW_NUMBER()+QUALIFY để tối ưu hơn: N phép MAX_BY độc lập với tie-break yếu (thường chỉ source_event_date) dễ ghép lệch dòng giữa các cột khi trùng ngày, còn ROW_NUMBER chọn 1 dòng rồi lấy hết cột một lúc
A4: 2 | B4: BPM_TAT_PDTD | C4: Batch 2 | E4: 2026-08-12 | F4: WARN | G4: Fail | H4: Pass | I4: Pass | J4: Pass | K4: Pass | L4: Pass | M4: Pass | N4: Fail | O4: WARN | P4: Pass | Q4: Pass | R4: Pass | S4: Pass | T4: Pass | U4: WARN | V4: Pass | W4: WARN | X4: WARN | Y4: Pass | Z4: =IF(B4="","",IF(COUNTIF(F4:G4,"Fail")>0,1,0)) -> 1 | AA4: =IF(B4="","",IF(COUNTIF(H4:S4,"Fail")>0,1,0)) -> 1 | AB4: =IF(B4="","",IF(COUNTIF(T4:Y4,"Fail")>0,1,0)) -> 0 | AC4: =IF(B4="","",0.1*Z4+0.8*AA4+0.1*AB4) -> 0.9 | AD4: =IF(B4="","",IF(C4="Batch 1",0.3,0.2)) -> 0.2 | AE4: =IF(B4="","",IF(AC4<=AD4,"Đạt","Không đạt")) -> Không đạt | AF4: ╔══ FAIL: 2 tiêu chí — 1.2, 2.7 ▼ 1.2 — Danh sách bảng/view Gold khớp tài liệu thiết kế đã duyệt • Lý do: BPM_TAT_PDTD không có workbook thiết kế tương ứng trong thư mục mapping → Cách sửa: Đảm bảo object có workbook thiết kế tương ứng trong thư mục --mapping-dir. Muốn đối chiếu với danh sách đã duyệt thì chạy thêm tham số --gold-list "<file danh sách Gold>.xlsx". ▼ 2.7 — CASE WHEN cover đủ nhánh như job on-prem • Lý do: 45/85 CASE KHÔNG có nhánh ELSE -> rơi ra ngoài mọi WHEN sẽ trả NULL âm thầm, tại dòng [] • Lý do: bổ sung ELSE (giá trị mặc định hoặc giá trị nghiệp vụ đúng như job on-prem) → Cách sửa: Mở job on-prem tương ứng (DataStage DSX hoặc SQL cũ), đối chiếu từng nhánh WHEN và cả nhánh ELSE. CASE không có ELSE sẽ trả NULL âm thầm — xác nhận đó là ý muốn hay thiếu nhánh. ╔══ WARN: 5 tiêu chí — 1.1, 2.8, 3.2, 3.4, 3.5 ▼ 1.1 — Đầy đủ mapping từ Silver/manual sang Gold • KHÔNG TÌM THẤY workbook thiết kế cho object BPM_TAT_PDTD nên không đối chiếu được danh sách cột (SQL có 74 cột đầu ra) ▼ 2.8 — Cột SUM/COUNT được COALESCE/NVL hợp lý • 14 biểu thức tổng hợp chưa coalesce: SUM(CASE WHEN (a.trang_thai_bat_dau IN (460, 466, 468, 474, ; SUM(CASE WHEN (a.trang_thai_bat_dau IN (465, 0, 491, 0, 499,; SUM(CASE WHEN (a.trang_thai_bat_dau IN (465, 467, 0, 0, 0, 4; SUM(CASE WHEN (a.trang_thai_bat_dau IN (466, 476, 0, 488, 48; SUM(CASE WHEN loai = 0 THEN 1.0 ELSE loai END); SUM(CASE WHEN ls.role_id IN (1, 2, 5, 6, 7, 10) THEN ls.wmin • khi đối soát với hệ thống cũ phải bọc NVL/ISNULL CẢ HAI phía để không lệch khi trừ (Checklist RVN-OCB #11) ▼ 3.2 — CTE không bị scan lại nhiều lần • CTE bị tham chiếu lại nhiều lần: pd_hub x2, ks_hub x3, s_pd_sp x2, s_ks_qt x2, r_dm x10 ▼ 3.4 — Sử dụng CACHE cho query lặp lại trong cùng luồng • 5 CTE nặng dùng lại >= 2 lần mà không có CACHE: ks_hub, pd_hub, r_dm, s_ks_qt, s_pd_sp ▼ 3.5 — Ưu tiên MAX_BY + QUALIFY thay ROW_NUMBER() + WHERE rn = 1 • 4 khối dùng MAX_BY độc lập cho >5 cột (dòng 15, [6, 7, 7, 8] cột/khối) — nên đổi sang ROW_NUMBER()+QUALIFY để tối ưu hơn: N phép MAX_BY độc lập với tie-break yếu (thường chỉ source_event_date) dễ ghép lệch dòng giữa các cột khi trùng ngày, còn ROW_NUMBER chọn 1 dòng rồi lấy hết cột một lúc
A5: 3 | B5: BPM_TAT_TDCN | C5: Batch 2 | E5: 2026-08-12 | F5: WARN | G5: Fail | H5: Pass | I5: Pass | J5: Pass | K5: Pass | L5: Pass | M5: Pass | N5: Fail | O5: WARN | P5: Pass | Q5: Pass | R5: Pass | S5: Pass | T5: Pass | U5: WARN | V5: Pass | W5: WARN | X5: WARN | Y5: Pass | Z5: =IF(B5="","",IF(COUNTIF(F5:G5,"Fail")>0,1,0)) -> 1 | AA5: =IF(B5="","",IF(COUNTIF(H5:S5,"Fail")>0,1,0)) -> 1 | AB5: =IF(B5="","",IF(COUNTIF(T5:Y5,"Fail")>0,1,0)) -> 0 | AC5: =IF(B5="","",0.1*Z5+0.8*AA5+0.1*AB5) -> 0.9 | AD5: =IF(B5="","",IF(C5="Batch 1",0.3,0.2)) -> 0.2 | AE5: =IF(B5="","",IF(AC5<=AD5,"Đạt","Không đạt")) -> Không đạt | AF5: ╔══ FAIL: 2 tiêu chí — 1.2, 2.7 ▼ 1.2 — Danh sách bảng/view Gold khớp tài liệu thiết kế đã duyệt • Lý do: BPM_TAT_TDCN không có workbook thiết kế tương ứng trong thư mục mapping → Cách sửa: Đảm bảo object có workbook thiết kế tương ứng trong thư mục --mapping-dir. Muốn đối chiếu với danh sách đã duyệt thì chạy thêm tham số --gold-list "<file danh sách Gold>.xlsx". ▼ 2.7 — CASE WHEN cover đủ nhánh như job on-prem • Lý do: 68/107 CASE KHÔNG có nhánh ELSE -> rơi ra ngoài mọi WHEN sẽ trả NULL âm thầm, tại dòng [] • Lý do: bổ sung ELSE (giá trị mặc định hoặc giá trị nghiệp vụ đúng như job on-prem) → Cách sửa: Mở job on-prem tương ứng (DataStage DSX hoặc SQL cũ), đối chiếu từng nhánh WHEN và cả nhánh ELSE. CASE không có ELSE sẽ trả NULL âm thầm — xác nhận đó là ý muốn hay thiếu nhánh. ╔══ WARN: 5 tiêu chí — 1.1, 2.8, 3.2, 3.4, 3.5 ▼ 1.1 — Đầy đủ mapping từ Silver/manual sang Gold • KHÔNG TÌM THẤY workbook thiết kế cho object BPM_TAT_TDCN nên không đối chiếu được danh sách cột (SQL có 73 cột đầu ra) ▼ 2.8 — Cột SUM/COUNT được COALESCE/NVL hợp lý • 16 biểu thức tổng hợp chưa coalesce: SUM(CASE WHEN ((a.trang_thai_bat_dau IN (460, 466, 468, 474,; SUM(CASE WHEN (a.trang_thai_bat_dau IN (465, 0, 491, 0, 499,; SUM(CASE WHEN (a.trang_thai_bat_dau IN (465, 467, 0, 0, 0, 4; SUM(CASE WHEN (a.trang_thai_bat_dau IN (466, 476, 0, 488, 48; SUM(CASE WHEN loai = 0 THEN 1.0 ELSE loai END); SUM(loai) • khi đối soát với hệ thống cũ phải bọc NVL/ISNULL CẢ HAI phía để không lệch khi trừ (Checklist RVN-OCB #11) ▼ 3.2 — CTE không bị scan lại nhiều lần • CTE bị tham chiếu lại nhiều lần: gd_hub x2, kh_hub x4, ks_hub x2, ts_hub x2, s_gd_tdcn x4, s_kh x2, s_kh_cn x2, r_dm x12, r_sk10 x2 ▼ 3.4 — Sử dụng CACHE cho query lặp lại trong cùng luồng • 9 CTE nặng dùng lại >= 2 lần mà không có CACHE: gd_hub, kh_hub, ks_hub, r_dm, r_sk10, s_gd_tdcn, s_kh, s_kh_cn, ts_hub ▼ 3.5 — Ưu tiên MAX_BY + QUALIFY thay ROW_NUMBER() + WHERE rn = 1 • 5 khối dùng MAX_BY độc lập cho >5 cột (dòng 15, [11, 10, 8, 8, 7] cột/khối) — nên đổi sang ROW_NUMBER()+QUALIFY để tối ưu hơn: N phép MAX_BY độc lập với tie-break yếu (thường chỉ source_event_date) dễ ghép lệch dòng giữa các cột khi trùng ngày, còn ROW_NUMBER chọn 1 dòng rồi lấy hết cột một lúc
A6: 8 | Z6: =IF(B6="","",IF(COUNTIF(F6:G6,"Fail")>0,1,0)) | AA6: =IF(B6="","",IF(COUNTIF(H6:S6,"Fail")>0,1,0)) | AB6: =IF(B6="","",IF(COUNTIF(T6:Y6,"Fail")>0,1,0)) | AC6: =IF(B6="","",0.1*Z6+0.8*AA6+0.1*AB6) | AD6: =IF(B6="","",IF(C6="Batch 1",0.3,0.2)) | AE6: =IF(B6="","",IF(AC6<=AD6,"Đạt","Không đạt"))
A7: 9 | Z7: =IF(B7="","",IF(COUNTIF(F7:G7,"Fail")>0,1,0)) | AA7: =IF(B7="","",IF(COUNTIF(H7:S7,"Fail")>0,1,0)) | AB7: =IF(B7="","",IF(COUNTIF(T7:Y7,"Fail")>0,1,0)) | AC7: =IF(B7="","",0.1*Z7+0.8*AA7+0.1*AB7) | AD7: =IF(B7="","",IF(C7="Batch 1",0.3,0.2)) | AE7: =IF(B7="","",IF(AC7<=AD7,"Đạt","Không đạt"))
A8: 10 | Z8: =IF(B8="","",IF(COUNTIF(F8:G8,"Fail")>0,1,0)) | AA8: =IF(B8="","",IF(COUNTIF(H8:S8,"Fail")>0,1,0)) | AB8: =IF(B8="","",IF(COUNTIF(T8:Y8,"Fail")>0,1,0)) | AC8: =IF(B8="","",0.1*Z8+0.8*AA8+0.1*AB8) | AD8: =IF(B8="","",IF(C8="Batch 1",0.3,0.2)) | AE8: =IF(B8="","",IF(AC8<=AD8,"Đạt","Không đạt"))
A9: 11 | Z9: =IF(B9="","",IF(COUNTIF(F9:G9,"Fail")>0,1,0)) | AA9: =IF(B9="","",IF(COUNTIF(H9:S9,"Fail")>0,1,0)) | AB9: =IF(B9="","",IF(COUNTIF(T9:Y9,"Fail")>0,1,0)) | AC9: =IF(B9="","",0.1*Z9+0.8*AA9+0.1*AB9) | AD9: =IF(B9="","",IF(C9="Batch 1",0.3,0.2)) | AE9: =IF(B9="","",IF(AC9<=AD9,"Đạt","Không đạt"))
A10: 12 | Z10: =IF(B10="","",IF(COUNTIF(F10:G10,"Fail")>0,1,0)) | AA10: =IF(B10="","",IF(COUNTIF(H10:S10,"Fail")>0,1,0)) | AB10: =IF(B10="","",IF(COUNTIF(T10:Y10,"Fail")>0,1,0)) | AC10: =IF(B10="","",0.1*Z10+0.8*AA10+0.1*AB10) | AD10: =IF(B10="","",IF(C10="Batch 1",0.3,0.2)) | AE10: =IF(B10="","",IF(AC10<=AD10,"Đạt","Không đạt"))
A11: 13 | Z11: =IF(B11="","",IF(COUNTIF(F11:G11,"Fail")>0,1,0)) | AA11: =IF(B11="","",IF(COUNTIF(H11:S11,"Fail")>0,1,0)) | AB11: =IF(B11="","",IF(COUNTIF(T11:Y11,"Fail")>0,1,0)) | AC11: =IF(B11="","",0.1*Z11+0.8*AA11+0.1*AB11) | AD11: =IF(B11="","",IF(C11="Batch 1",0.3,0.2)) | AE11: =IF(B11="","",IF(AC11<=AD11,"Đạt","Không đạt"))
A12: 14 | Z12: =IF(B12="","",IF(COUNTIF(F12:G12,"Fail")>0,1,0)) | AA12: =IF(B12="","",IF(COUNTIF(H12:S12,"Fail")>0,1,0)) | AB12: =IF(B12="","",IF(COUNTIF(T12:Y12,"Fail")>0,1,0)) | AC12: =IF(B12="","",0.1*Z12+0.8*AA12+0.1*AB12) | AD12: =IF(B12="","",IF(C12="Batch 1",0.3,0.2)) | AE12: =IF(B12="","",IF(AC12<=AD12,"Đạt","Không đạt"))
A13: 15 | Z13: =IF(B13="","",IF(COUNTIF(F13:G13,"Fail")>0,1,0)) | AA13: =IF(B13="","",IF(COUNTIF(H13:S13,"Fail")>0,1,0)) | AB13: =IF(B13="","",IF(COUNTIF(T13:Y13,"Fail")>0,1,0)) | AC13: =IF(B13="","",0.1*Z13+0.8*AA13+0.1*AB13) | AD13: =IF(B13="","",IF(C13="Batch 1",0.3,0.2)) | AE13: =IF(B13="","",IF(AC13<=AD13,"Đạt","Không đạt"))
A14: 16 | Z14: =IF(B14="","",IF(COUNTIF(F14:G14,"Fail")>0,1,0)) | AA14: =IF(B14="","",IF(COUNTIF(H14:S14,"Fail")>0,1,0)) | AB14: =IF(B14="","",IF(COUNTIF(T14:Y14,"Fail")>0,1,0)) | AC14: =IF(B14="","",0.1*Z14+0.8*AA14+0.1*AB14) | AD14: =IF(B14="","",IF(C14="Batch 1",0.3,0.2)) | AE14: =IF(B14="","",IF(AC14<=AD14,"Đạt","Không đạt"))
A15: 17 | Z15: =IF(B15="","",IF(COUNTIF(F15:G15,"Fail")>0,1,0)) | AA15: =IF(B15="","",IF(COUNTIF(H15:S15,"Fail")>0,1,0)) | AB15: =IF(B15="","",IF(COUNTIF(T15:Y15,"Fail")>0,1,0)) | AC15: =IF(B15="","",0.1*Z15+0.8*AA15+0.1*AB15) | AD15: =IF(B15="","",IF(C15="Batch 1",0.3,0.2)) | AE15: =IF(B15="","",IF(AC15<=AD15,"Đạt","Không đạt"))
A16: 18 | Z16: =IF(B16="","",IF(COUNTIF(F16:G16,"Fail")>0,1,0)) | AA16: =IF(B16="","",IF(COUNTIF(H16:S16,"Fail")>0,1,0)) | AB16: =IF(B16="","",IF(COUNTIF(T16:Y16,"Fail")>0,1,0)) | AC16: =IF(B16="","",0.1*Z16+0.8*AA16+0.1*AB16) | AD16: =IF(B16="","",IF(C16="Batch 1",0.3,0.2)) | AE16: =IF(B16="","",IF(AC16<=AD16,"Đạt","Không đạt"))
A17: 19 | Z17: =IF(B17="","",IF(COUNTIF(F17:G17,"Fail")>0,1,0)) | AA17: =IF(B17="","",IF(COUNTIF(H17:S17,"Fail")>0,1,0)) | AB17: =IF(B17="","",IF(COUNTIF(T17:Y17,"Fail")>0,1,0)) | AC17: =IF(B17="","",0.1*Z17+0.8*AA17+0.1*AB17) | AD17: =IF(B17="","",IF(C17="Batch 1",0.3,0.2)) | AE17: =IF(B17="","",IF(AC17<=AD17,"Đạt","Không đạt"))
... A196: 198 | Z196: =IF(B196="","",IF(COUNTIF(F196:G196,"Fail")>0,1,0)) | AA196: =IF(B196="","",IF(COUNTIF(H196:S196,"Fail")>0,1,0)) | AB196: =IF(B196="","",IF(COUNTIF(T196:Y196,"Fail")>0,1,0)) | AC196: =IF(B196="","",0.1*Z196+0.8*AA196+0.1*AB196) | AD196: =IF(B196="","",IF(C196="Batch 1",0.3,0.2)) | AE196: =IF(B196="","",IF(AC196<=AD196,"Đạt","Không đạt"))

Sheet Tổng hợp Dashboard
B2: TỔNG HỢP KẾT QUẢ REVIEW CODE THEO BATCH – ZONE C OCB
B4: Batch | C4: Ngưỡng lỗi cho phép | D4: Số bảng đã review | E4: Số bảng Đạt | F4: Số bảng Không đạt | G4: Tỷ lệ lỗi bình quân | H4: Tỷ lệ bảng Không đạt | I4: Kết luận Batch
B5: Batch 1 | C5: 0.3 | D5: =COUNTIF('Review theo bảng'!$C$3:$C$196,B5) -> 0 | E5: =COUNTIFS('Review theo bảng'!$C$3:$C$196,B5,'Review theo bảng'!$AE$3:$AE$196,"Đạt") -> 0 | F5: =COUNTIFS('Review theo bảng'!$C$3:$C$196,B5,'Review theo bảng'!$AE$3:$AE$196,"Không đạt") -> 0 | G5: =IFERROR(AVERAGEIF('Review theo bảng'!$C$3:$C$196,B5,'Review theo bảng'!$AC$3:$AC$196),0) -> 0 | H5: =IFERROR(F5/D5,0) -> 0 | I5: =IF(D5=0,"Chưa có dữ liệu",IF(H5<=C5,"Đạt yêu cầu","Không đạt yêu cầu")) -> Chưa có dữ liệu
B6: Batch 2 | C6: 0.2 | D6: =COUNTIF('Review theo bảng'!$C$3:$C$196,B6) -> 3 | E6: =COUNTIFS('Review theo bảng'!$C$3:$C$196,B6,'Review theo bảng'!$AE$3:$AE$196,"Đạt") -> 0 | F6: =COUNTIFS('Review theo bảng'!$C$3:$C$196,B6,'Review theo bảng'!$AE$3:$AE$196,"Không đạt") -> 3 | G6: =IFERROR(AVERAGEIF('Review theo bảng'!$C$3:$C$196,B6,'Review theo bảng'!$AC$3:$AC$196),0) -> 0.9 | H6: =IFERROR(F6/D6,0) -> 1 | I6: =IF(D6=0,"Chưa có dữ liệu",IF(H6<=C6,"Đạt yêu cầu","Không đạt yêu cầu")) -> Không đạt yêu cầu
B7: Batch 3 | C7: 0.2 | D7: =COUNTIF('Review theo bảng'!$C$3:$C$196,B7) -> 0 | E7: =COUNTIFS('Review theo bảng'!$C$3:$C$196,B7,'Review theo bảng'!$AE$3:$AE$196,"Đạt") -> 0 | F7: =COUNTIFS('Review theo bảng'!$C$3:$C$196,B7,'Review theo bảng'!$AE$3:$AE$196,"Không đạt") -> 0 | G7: =IFERROR(AVERAGEIF('Review theo bảng'!$C$3:$C$196,B7,'Review theo bảng'!$AC$3:$AC$196),0) -> 0 | H7: =IFERROR(F7/D7,0) -> 0 | I7: =IF(D7=0,"Chưa có dữ liệu",IF(H7<=C7,"Đạt yêu cầu","Không đạt yêu cầu")) -> Chưa có dữ liệu
B9: Ghi chú: Tỷ lệ lỗi bình quân và kết luận lấy tự động từ sheet "Review theo bảng" (cột AE và AG). Ngưỡng lỗi theo thống nhất với OCB: Batch 1 tối đa 30%, Batch 2 và Batch 3 tối đa 20% (sheet "Quality check").

Sheet Auto-check chi tiết
A1: Object Gold | B1: Profile | C1: Mã | D1: Nhóm | E1: Tiêu chí | F1: Kết quả máy | G1: Ghi vào Excel | H1: Bằng chứng / số dòng | I1: Cách sửa | J1: File
A2: BPM_SPTC | B2: SILVER_CONSUMER | C2: 1.1 | D2: Nhom 1 - Mapping | E2: Đầy đủ mapping từ Silver/manual sang Gold | F2: WARN | G2: WARN | H2: KHÔNG TÌM THẤY workbook thiết kế cho object BPM_SPTC nên không đối chiếu được danh sách cột (SQL có 127 cột đầu ra) | I2: Mở workbook thiết kế, đối chiếu block FIELD MAPPING với danh sách cột trong câu SELECT/INSERT của file SQL. Cột nào thiếu thì bổ sung vào SQL; cột nào SQL có mà thiết kế không có thì bổ sung vào workbook hoặc bỏ khỏi SQL. | J2: C:\ZoneC_DEV\zonec-datamart\tools\gold_review\input\sql\BPM_SPTC.sql
A3: BPM_SPTC | B3: SILVER_CONSUMER | C3: 1.2 | D3: Nhom 1 - Mapping | E3: Danh sách bảng/view Gold khớp tài liệu thiết kế đã duyệt | F3: FAIL | G3: Fail | H3: BPM_SPTC không có workbook thiết kế tương ứng trong thư mục mapping | I3: Đảm bảo object có workbook thiết kế tương ứng trong thư mục --mapping-dir. Muốn đối chiếu với danh sách đã duyệt thì chạy thêm tham số --gold-list "<file danh sách Gold>.xlsx". | J3: C:\ZoneC_DEV\zonec-datamart\tools\gold_review\input\sql\BPM_SPTC.sql
A4: BPM_SPTC | B4: SILVER_CONSUMER | C4: 2.1 | D4: Nhom 2 - Logic | E4: Chỉ lấy bản ghi active, loại bản ghi đã xóa (qua sts_hub) | F4: PASS | G4: Pass | H4: không dùng sts_hub_* (không có yêu cầu nghiệp vụ giữ bản ghi đã xóa) | I4: Theo Technical Document mục III.4.2.1: với mỗi hub_<ent> phải thêm 2 CTE — (1) <ent>_sts_del đọc sts_hub_<ent>, GROUP BY hashkey, HAVING max_by(cdc_status, source_event_date) = 'D'; (2) <ent>_active đọc hub_<ent> LEFT JOIN <ent>_sts_del rồi lọc d.<hashkey> IS NULL. Tuyệt đối KHÔNG lọc cdc_status trong satellite — trạng thái xóa chỉ lọc ở sts_hub. | J4: C:\ZoneC_DEV\zonec-datamart\tools\gold_review\input\sql\BPM_SPTC.sql
A5: BPM_SPTC | B5: SILVER_CONSUMER | C5: 2.2 | D5: Nhom 2 - Logic | E5: Thống nhất MỘT pattern duy nhất xác định bản ghi active mới nhất | F5: PASS | G5: Pass | H5: file này dùng: ['MAX_BY']; toàn batch dùng: ['MAX_BY'] | I5: Toàn bộ script trong batch phải dùng cùng một cách lấy bản ghi mới nhất: max_by(<cột>, source_event_date) + GROUP BY hashkey. Không để file này dùng ROW_NUMBER, file kia dùng max_by. Hướng lọc cdc_status cũng phải nhất quán (luôn là loại 'D', không có chỗ nào giữ 'D'). | J5: C:\ZoneC_DEV\zonec-datamart\tools\gold_review\input\sql\BPM_SPTC.sql
A6: BPM_SPTC | B6: SILVER_CONSUMER | C6: 2.3 | D6: Nhom 2 - Logic | E6: Điều kiện lọc trạng thái đặt SAU khi xác định bản ghi mới nhất | F6: PASS | G6: Pass | H6: không có điều kiện trạng thái nào lồng trong JOIN ON | I6: Chuyển các điều kiện cdc_status / rn = 1 ra khỏi phần ON của LEFT JOIN, đưa vào WHERE hoặc QUALIFY của chính subquery/CTE lấy dữ liệu. Đặt trong ON của LEFT JOIN thì khi không match sẽ ra NULL âm thầm, sai kết quả (Issue log #3). Riêng pattern PIT (sat.source_event_date = p.<sat>_src_ev_dt) và 49 bảng transaction được phép đặt trong ON. | J6: C:\ZoneC_DEV\zonec-datamart\tools\gold_review\input\sql\BPM_SPTC.sql
A7: BPM_SPTC | B7: SILVER_CONSUMER | C7: 2.4 | D7: Nhom 2 - Logic | E7: source_event_date áp dụng đúng dạng theo loại bảng | F7: PASS | G7: Pass | H7: 18 bảng đều đúng dạng điều kiện source_event_date | I7: Bảng thường: WHERE source_event_date <= TO_DATE(:DATADT,'yyyyMMdd') và KHÔNG đặt cận dưới (>= start_date) vì sẽ bỏ sót bản ghi mới nhất nằm trước khoảng thời gian. Riêng 49 bảng transaction ở mục 'Các trường hợp đặc biệt' của Technical Document (sat_stmt_entry_*, sat_categ_entry_*, sat_account_balance, sat_funds_transfer_*, sat_gl_trace_*, …) phải dùng source_event_date = :DATADT. Danh sách đầy đủ ở tools/gold_review/doc_standard.py. | J7: C:\ZoneC_DEV\zonec-datamart\tools\gold_review\input\sql\BPM_SPTC.sql
A8: BPM_SPTC | B8: SILVER_CONSUMER | C8: 2.5 | D8: Nhom 2 - Logic | E8: Không lặp lại lỗi logic cũ đã được DA Data Vault fix | F8: PASS | G8: Pass | H8: không trùng lỗi nào trong Issue log của DA Data Vault | I8: Sửa đúng các dòng được chỉ ra ở trên theo pattern chuẩn: lấy bản ghi mới nhất bằng max_by(<cột>, source_event_date) + GROUP BY hashkey; trạng thái xoá lọc ở sts_hub_* bằng HAVING max_by(cdc_status, source_event_date) = 'D' rồi anti-join IS NULL; không đặt cdc_status / rn = 1 trong ON hay trong subquery của JOIN; surrogate key DIM không sinh bằng MAX(<DIM_ID>) + ROW_NUMBER(). Danh sách lỗi lấy từ 'ZoneC Mapping - Iss log.xlsx' sheet Issue; OCB trả lỗi mới thì thêm 1 regex vào tools/gold_review/engine/known_issues.json để lần sau tự bắt được. | J8: C:\ZoneC_DEV\zonec-datamart\tools\gold_review\input\sql\BPM_SPTC.sql
A9: BPM_SPTC | B9: SILVER_CONSUMER | C9: 2.6 | D9: Nhom 2 - Logic | E9: SCD Type 2 cho bảng DIM áp dụng đúng kỹ thuật đã thống nhất | F9: N-A | G9: Pass | H9: object không phải bảng DIM nên không áp dụng SCD Type 2 | I9: Dùng APPLY CHANGES INTO <bảng>_scd FROM STREAM(stg_<ent>_changes) KEYS (<hashkey>) SEQUENCE BY source_event_date STORED AS SCD TYPE 2 TRACK HISTORY ON (...) — Databricks tự quản __START_AT/__END_AT. Nếu tự quản thì phải có cột effective_date/end_date/current_flag. TUYỆT ĐỐI không sinh surrogate key bằng MAX(<DIM_ID>) + ROW_NUMBER() vì trùng khi chạy song song hoặc load lại lịch sử (Issue log #4). | J9: C:\ZoneC_DEV\zonec-datamart\tools\gold_review\input\sql\BPM_SPTC.sql
A10: BPM_SPTC | B10: SILVER_CONSUMER | C10: 2.7 | D10: Nhom 2 - Logic | E10: CASE WHEN cover đủ nhánh như job on-prem | F10: FAIL | G10: Fail | H10: 60/105 CASE KHÔNG có nhánh ELSE -> rơi ra ngoài mọi WHEN sẽ trả NULL âm thầm, tại dòng []; bổ sung ELSE (giá trị mặc định hoặc giá trị nghiệp vụ đúng như job on-prem) | I10: Mở job on-prem tương ứng (DataStage DSX hoặc SQL cũ), đối chiếu từng nhánh WHEN và cả nhánh ELSE. CASE không có ELSE sẽ trả NULL âm thầm — xác nhận đó là ý muốn hay thiếu nhánh. | J10: C:\ZoneC_DEV\zonec-datamart\tools\gold_review\input\sql\BPM_SPTC.sql
A11: BPM_SPTC | B11: SILVER_CONSUMER | C11: 2.8 | D11: Nhom 2 - Logic | E11: Cột SUM/COUNT được COALESCE/NVL hợp lý | F11: WARN | G11: WARN | H11: 7 biểu thức tổng hợp chưa coalesce: SUM(CASE WHEN loai = 0 THEN 1.0 ELSE loai END); SUM(loai); count_ycbs_gn = SUM(CASE WHEN b.trang_thai_ban_dau IN (7855, 7859, 7856) THE; count_ycbs_pd = SUM(CASE WHEN b.trang_thai_ban_dau IN (5353, 7828, 8463) THE; count_ycbs_st = SUM(CASE WHEN b.trang_thai_ban_dau IN (7829, 7848) THEN 1 EL; dg_trans_get_return = SUM(CASE WHEN ls.thao_tac_id = 1010 THEN 1 ELSE 0 END); khi đối soát với hệ thống cũ phải bọc NVL/ISNULL CẢ HAI phía để không lệch khi trừ (Checklist RVN-OCB #11) | I11: Bọc COALESCE(SUM(...), 0) cho các cột tổng hợp cần trả 0 khi không có dòng. Nếu code cũ không bọc thì giữ nguyên logic nhưng khi đối soát số liệu với hệ thống cũ phải bọc NVL/ISNULL ở CẢ HAI phía để không lệch khi trừ. | J11: C:\ZoneC_DEV\zonec-datamart\tools\gold_review\input\sql\BPM_SPTC.sql
A12: BPM_SPTC | B12: SILVER_CONSUMER | C12: 2.9 | D12: Nhom 2 - Logic | E12: Subquery / custom function / điều kiện LIKE đúng ý nghĩa nghiệp vụ | F12: PASS | G12: Pass | H12: 1 điều kiện LIKE: a.gd_id NOT LIKE 'HSPTC%'; cú pháp hợp lệ; ý nghĩa nghiệp vụ cần người review đối chiếu job on-prem | I12: Đọc lại từng điều kiện LIKE và từng subquery, đối chiếu ý nghĩa nghiệp vụ với on-prem — đúng cú pháp không đủ. Chú ý pattern LIKE có ký tự % ở đầu/cuối và phân biệt chữ hoa/thường. | J12: C:\ZoneC_DEV\zonec-datamart\tools\gold_review\input\sql\BPM_SPTC.sql
... A24: BPM_SPTC | B24: SILVER_CONSUMER | C24: X.7 | D24: Nhom X - Bo sung Raffles | E24: [Bổ sung] Không hard-code catalog, dùng biến môi trường | F24: PASS | G24: Pass | H24: dùng biến môi trường cho catalog | I24: Thay tên catalog cứng bằng IDENTIFIER(:cleaned || '.raw_vault.<bảng>') / IDENTIFIER(:curated || '.tckh.<bảng>'), hoặc ${cleaned_catalog} / ${curated_catalog} trong Lakeflow Declarative Pipeline. Hard-code thì deploy sang môi trường khác phải sửa tay từng file. | J24: C:\ZoneC_DEV\zonec-datamart\tools\gold_review\input\sql\BPM_SPTC.sql
A25: BPM_SPTC | B25: SILVER_CONSUMER | C25: X.10 | D25: Nhom X - Bo sung Raffles | E25: Bang raw_vault/business_vault duoc doc phai TON TAI THAT trong Data Vault model | F25: PASS | G25: Pass | H25: 29 bảng Silver đều có thật trong Data Vault model | J25: C:\ZoneC_DEV\zonec-datamart\tools\gold_review\input\sql\BPM_SPTC.sql
A26: BPM_SPTC | B26: SILVER_CONSUMER | C26: X.11 | D26: Nhom X - Bo sung Raffles | E26: Cot doc tu satellite (sat_*) phai TON TAI THAT trong model | F26: PASS | G26: Pass | H26: mọi cột đọc từ sat_* đều tồn tại trong model thật | J26: C:\ZoneC_DEV\zonec-datamart\tools\gold_review\input\sql\BPM_SPTC.sql
A27: BPM_TAT_PDTD | B27: SILVER_CONSUMER | C27: 1.1 | D27: Nhom 1 - Mapping | E27: Đầy đủ mapping từ Silver/manual sang Gold | F27: WARN | G27: WARN | H27: KHÔNG TÌM THẤY workbook thiết kế cho object BPM_TAT_PDTD nên không đối chiếu được danh sách cột (SQL có 74 cột đầu ra) | I27: Mở workbook thiết kế, đối chiếu block FIELD MAPPING với danh sách cột trong câu SELECT/INSERT của file SQL. Cột nào thiếu thì bổ sung vào SQL; cột nào SQL có mà thiết kế không có thì bổ sung vào workbook hoặc bỏ khỏi SQL. | J27: C:\ZoneC_DEV\zonec-datamart\tools\gold_review\input\sql\BPM_TAT_PDTD.sql
A28: BPM_TAT_PDTD | B28: SILVER_CONSUMER | C28: 1.2 | D28: Nhom 1 - Mapping | E28: Danh sách bảng/view Gold khớp tài liệu thiết kế đã duyệt | F28: FAIL | G28: Fail | H28: BPM_TAT_PDTD không có workbook thiết kế tương ứng trong thư mục mapping | I28: Đảm bảo object có workbook thiết kế tương ứng trong thư mục --mapping-dir. Muốn đối chiếu với danh sách đã duyệt thì chạy thêm tham số --gold-list "<file danh sách Gold>.xlsx". | J28: C:\ZoneC_DEV\zonec-datamart\tools\gold_review\input\sql\BPM_TAT_PDTD.sql
A29: BPM_TAT_PDTD | B29: SILVER_CONSUMER | C29: 2.1 | D29: Nhom 2 - Logic | E29: Chỉ lấy bản ghi active, loại bản ghi đã xóa (qua sts_hub) | F29: PASS | G29: Pass | H29: không dùng sts_hub_* (không có yêu cầu nghiệp vụ giữ bản ghi đã xóa) | I29: Theo Technical Document mục III.4.2.1: với mỗi hub_<ent> phải thêm 2 CTE — (1) <ent>_sts_del đọc sts_hub_<ent>, GROUP BY hashkey, HAVING max_by(cdc_status, source_event_date) = 'D'; (2) <ent>_active đọc hub_<ent> LEFT JOIN <ent>_sts_del rồi lọc d.<hashkey> IS NULL. Tuyệt đối KHÔNG lọc cdc_status trong satellite — trạng thái xóa chỉ lọc ở sts_hub. | J29: C:\ZoneC_DEV\zonec-datamart\tools\gold_review\input\sql\BPM_TAT_PDTD.sql
A30: BPM_TAT_PDTD | B30: SILVER_CONSUMER | C30: 2.2 | D30: Nhom 2 - Logic | E30: Thống nhất MỘT pattern duy nhất xác định bản ghi active mới nhất | F30: PASS | G30: Pass | H30: file này dùng: ['MAX_BY']; toàn batch dùng: ['MAX_BY'] | I30: Toàn bộ script trong batch phải dùng cùng một cách lấy bản ghi mới nhất: max_by(<cột>, source_event_date) + GROUP BY hashkey. Không để file này dùng ROW_NUMBER, file kia dùng max_by. Hướng lọc cdc_status cũng phải nhất quán (luôn là loại 'D', không có chỗ nào giữ 'D'). | J30: C:\ZoneC_DEV\zonec-datamart\tools\gold_review\input\sql\BPM_TAT_PDTD.sql
A31: BPM_TAT_PDTD | B31: SILVER_CONSUMER | C31: 2.3 | D31: Nhom 2 - Logic | E31: Điều kiện lọc trạng thái đặt SAU khi xác định bản ghi mới nhất | F31: PASS | G31: Pass | H31: không có điều kiện trạng thái nào lồng trong JOIN ON | I31: Chuyển các điều kiện cdc_status / rn = 1 ra khỏi phần ON của LEFT JOIN, đưa vào WHERE hoặc QUALIFY của chính subquery/CTE lấy dữ liệu. Đặt trong ON của LEFT JOIN thì khi không match sẽ ra NULL âm thầm, sai kết quả (Issue log #3). Riêng pattern PIT (sat.source_event_date = p.<sat>_src_ev_dt) và 49 bảng transaction được phép đặt trong ON. | J31: C:\ZoneC_DEV\zonec-datamart\tools\gold_review\input\sql\BPM_TAT_PDTD.sql
A32: BPM_TAT_PDTD | B32: SILVER_CONSUMER | C32: 2.4 | D32: Nhom 2 - Logic | E32: source_event_date áp dụng đúng dạng theo loại bảng | F32: PASS | G32: Pass | H32: 18 bảng đều đúng dạng điều kiện source_event_date | I32: Bảng thường: WHERE source_event_date <= TO_DATE(:DATADT,'yyyyMMdd') và KHÔNG đặt cận dưới (>= start_date) vì sẽ bỏ sót bản ghi mới nhất nằm trước khoảng thời gian. Riêng 49 bảng transaction ở mục 'Các trường hợp đặc biệt' của Technical Document (sat_stmt_entry_*, sat_categ_entry_*, sat_account_balance, sat_funds_transfer_*, sat_gl_trace_*, …) phải dùng source_event_date = :DATADT. Danh sách đầy đủ ở tools/gold_review/doc_standard.py. | J32: C:\ZoneC_DEV\zonec-datamart\tools\gold_review\input\sql\BPM_TAT_PDTD.sql
A33: BPM_TAT_PDTD | B33: SILVER_CONSUMER | C33: 2.5 | D33: Nhom 2 - Logic | E33: Không lặp lại lỗi logic cũ đã được DA Data Vault fix | F33: PASS | G33: Pass | H33: không trùng lỗi nào trong Issue log của DA Data Vault | I33: Sửa đúng các dòng được chỉ ra ở trên theo pattern chuẩn: lấy bản ghi mới nhất bằng max_by(<cột>, source_event_date) + GROUP BY hashkey; trạng thái xoá lọc ở sts_hub_* bằng HAVING max_by(cdc_status, source_event_date) = 'D' rồi anti-join IS NULL; không đặt cdc_status / rn = 1 trong ON hay trong subquery của JOIN; surrogate key DIM không sinh bằng MAX(<DIM_ID>) + ROW_NUMBER(). Danh sách lỗi lấy từ 'ZoneC Mapping - Iss log.xlsx' sheet Issue; OCB trả lỗi mới thì thêm 1 regex vào tools/gold_review/engine/known_issues.json để lần sau tự bắt được. | J33: C:\ZoneC_DEV\zonec-datamart\tools\gold_review\input\sql\BPM_TAT_PDTD.sql
A34: BPM_TAT_PDTD | B34: SILVER_CONSUMER | C34: 2.6 | D34: Nhom 2 - Logic | E34: SCD Type 2 cho bảng DIM áp dụng đúng kỹ thuật đã thống nhất | F34: N-A | G34: Pass | H34: object không phải bảng DIM nên không áp dụng SCD Type 2 | I34: Dùng APPLY CHANGES INTO <bảng>_scd FROM STREAM(stg_<ent>_changes) KEYS (<hashkey>) SEQUENCE BY source_event_date STORED AS SCD TYPE 2 TRACK HISTORY ON (...) — Databricks tự quản __START_AT/__END_AT. Nếu tự quản thì phải có cột effective_date/end_date/current_flag. TUYỆT ĐỐI không sinh surrogate key bằng MAX(<DIM_ID>) + ROW_NUMBER() vì trùng khi chạy song song hoặc load lại lịch sử (Issue log #4). | J34: C:\ZoneC_DEV\zonec-datamart\tools\gold_review\input\sql\BPM_TAT_PDTD.sql
A35: BPM_TAT_PDTD | B35: SILVER_CONSUMER | C35: 2.7 | D35: Nhom 2 - Logic | E35: CASE WHEN cover đủ nhánh như job on-prem | F35: FAIL | G35: Fail | H35: 45/85 CASE KHÔNG có nhánh ELSE -> rơi ra ngoài mọi WHEN sẽ trả NULL âm thầm, tại dòng []; bổ sung ELSE (giá trị mặc định hoặc giá trị nghiệp vụ đúng như job on-prem) | I35: Mở job on-prem tương ứng (DataStage DSX hoặc SQL cũ), đối chiếu từng nhánh WHEN và cả nhánh ELSE. CASE không có ELSE sẽ trả NULL âm thầm — xác nhận đó là ý muốn hay thiếu nhánh. | J35: C:\ZoneC_DEV\zonec-datamart\tools\gold_review\input\sql\BPM_TAT_PDTD.sql
A36: BPM_TAT_PDTD | B36: SILVER_CONSUMER | C36: 2.8 | D36: Nhom 2 - Logic | E36: Cột SUM/COUNT được COALESCE/NVL hợp lý | F36: WARN | G36: WARN | H36: 14 biểu thức tổng hợp chưa coalesce: SUM(CASE WHEN (a.trang_thai_bat_dau IN (460, 466, 468, 474, ; SUM(CASE WHEN (a.trang_thai_bat_dau IN (465, 0, 491, 0, 499,; SUM(CASE WHEN (a.trang_thai_bat_dau IN (465, 467, 0, 0, 0, 4; SUM(CASE WHEN (a.trang_thai_bat_dau IN (466, 476, 0, 488, 48; SUM(CASE WHEN loai = 0 THEN 1.0 ELSE loai END); SUM(CASE WHEN ls.role_id IN (1, 2, 5, 6, 7, 10) THEN ls.wmin; khi đối soát với hệ thống cũ phải bọc NVL/ISNULL CẢ HAI phía để không lệch khi trừ (Checklist RVN-OCB #11) | I36: Bọc COALESCE(SUM(...), 0) cho các cột tổng hợp cần trả 0 khi không có dòng. Nếu code cũ không bọc thì giữ nguyên logic nhưng khi đối soát số liệu với hệ thống cũ phải bọc NVL/ISNULL ở CẢ HAI phía để không lệch khi trừ. | J36: C:\ZoneC_DEV\zonec-datamart\tools\gold_review\input\sql\BPM_TAT_PDTD.sql
A37: BPM_TAT_PDTD | B37: SILVER_CONSUMER | C37: 2.9 | D37: Nhom 2 - Logic | E37: Subquery / custom function / điều kiện LIKE đúng ý nghĩa nghiệp vụ | F37: PASS | G37: Pass | H37: 1 điều kiện LIKE: xll.ma_giao_dich_xl LIKE 'GN%'; cú pháp hợp lệ; ý nghĩa nghiệp vụ cần người review đối chiếu job on-prem | I37: Đọc lại từng điều kiện LIKE và từng subquery, đối chiếu ý nghĩa nghiệp vụ với on-prem — đúng cú pháp không đủ. Chú ý pattern LIKE có ký tự % ở đầu/cuối và phân biệt chữ hoa/thường. | J37: C:\ZoneC_DEV\zonec-datamart\tools\gold_review\input\sql\BPM_TAT_PDTD.sql
A38: BPM_TAT_PDTD | B38: SILVER_CONSUMER | C38: 2.10 | D38: Nhom 2 - Logic | E38: Aggregation kèm filter date range chính xác | F38: PASS | G38: Pass | H38: mọi khối tổng hợp đều có điều kiện theo kỳ dữ liệu | I38: Mỗi khối SUM/COUNT/AVG phải có điều kiện lọc theo kỳ dữ liệu (CDR_DT_ID, DATA_DATE, :DATADT…). Nếu điều kiện nằm ở CTE nguồn thì ghi rõ trong comment để người review không phải truy ngược. | J38: C:\ZoneC_DEV\zonec-datamart\tools\gold_review\input\sql\BPM_TAT_PDTD.sql
... A49: BPM_TAT_PDTD | B49: SILVER_CONSUMER | C49: X.7 | D49: Nhom X - Bo sung Raffles | E49: [Bổ sung] Không hard-code catalog, dùng biến môi trường | F49: PASS | G49: Pass | H49: dùng biến môi trường cho catalog | I49: Thay tên catalog cứng bằng IDENTIFIER(:cleaned || '.raw_vault.<bảng>') / IDENTIFIER(:curated || '.tckh.<bảng>'), hoặc ${cleaned_catalog} / ${curated_catalog} trong Lakeflow Declarative Pipeline. Hard-code thì deploy sang môi trường khác phải sửa tay từng file. | J49: C:\ZoneC_DEV\zonec-datamart\tools\gold_review\input\sql\BPM_TAT_PDTD.sql
A50: BPM_TAT_PDTD | B50: SILVER_CONSUMER | C50: X.10 | D50: Nhom X - Bo sung Raffles | E50: Bang raw_vault/business_vault duoc doc phai TON TAI THAT trong Data Vault model | F50: PASS | G50: Pass | H50: 29 bảng Silver đều có thật trong Data Vault model | J50: C:\ZoneC_DEV\zonec-datamart\tools\gold_review\input\sql\BPM_TAT_PDTD.sql
A51: BPM_TAT_PDTD | B51: SILVER_CONSUMER | C51: X.11 | D51: Nhom X - Bo sung Raffles | E51: Cot doc tu satellite (sat_*) phai TON TAI THAT trong model | F51: PASS | G51: Pass | H51: mọi cột đọc từ sat_* đều tồn tại trong model thật | J51: C:\ZoneC_DEV\zonec-datamart\tools\gold_review\input\sql\BPM_TAT_PDTD.sql
A52: BPM_TAT_TDCN | B52: SILVER_CONSUMER | C52: 1.1 | D52: Nhom 1 - Mapping | E52: Đầy đủ mapping từ Silver/manual sang Gold | F52: WARN | G52: WARN | H52: KHÔNG TÌM THẤY workbook thiết kế cho object BPM_TAT_TDCN nên không đối chiếu được danh sách cột (SQL có 73 cột đầu ra) | I52: Mở workbook thiết kế, đối chiếu block FIELD MAPPING với danh sách cột trong câu SELECT/INSERT của file SQL. Cột nào thiếu thì bổ sung vào SQL; cột nào SQL có mà thiết kế không có thì bổ sung vào workbook hoặc bỏ khỏi SQL. | J52: C:\ZoneC_DEV\zonec-datamart\tools\gold_review\input\sql\BPM_TAT_TDCN.sql
A53: BPM_TAT_TDCN | B53: SILVER_CONSUMER | C53: 1.2 | D53: Nhom 1 - Mapping | E53: Danh sách bảng/view Gold khớp tài liệu thiết kế đã duyệt | F53: FAIL | G53: Fail | H53: BPM_TAT_TDCN không có workbook thiết kế tương ứng trong thư mục mapping | I53: Đảm bảo object có workbook thiết kế tương ứng trong thư mục --mapping-dir. Muốn đối chiếu với danh sách đã duyệt thì chạy thêm tham số --gold-list "<file danh sách Gold>.xlsx". | J53: C:\ZoneC_DEV\zonec-datamart\tools\gold_review\input\sql\BPM_TAT_TDCN.sql
A54: BPM_TAT_TDCN | B54: SILVER_CONSUMER | C54: 2.1 | D54: Nhom 2 - Logic | E54: Chỉ lấy bản ghi active, loại bản ghi đã xóa (qua sts_hub) | F54: PASS | G54: Pass | H54: không dùng sts_hub_* (không có yêu cầu nghiệp vụ giữ bản ghi đã xóa) | I54: Theo Technical Document mục III.4.2.1: với mỗi hub_<ent> phải thêm 2 CTE — (1) <ent>_sts_del đọc sts_hub_<ent>, GROUP BY hashkey, HAVING max_by(cdc_status, source_event_date) = 'D'; (2) <ent>_active đọc hub_<ent> LEFT JOIN <ent>_sts_del rồi lọc d.<hashkey> IS NULL. Tuyệt đối KHÔNG lọc cdc_status trong satellite — trạng thái xóa chỉ lọc ở sts_hub. | J54: C:\ZoneC_DEV\zonec-datamart\tools\gold_review\input\sql\BPM_TAT_TDCN.sql
A55: BPM_TAT_TDCN | B55: SILVER_CONSUMER | C55: 2.2 | D55: Nhom 2 - Logic | E55: Thống nhất MỘT pattern duy nhất xác định bản ghi active mới nhất | F55: PASS | G55: Pass | H55: file này dùng: ['MAX_BY']; toàn batch dùng: ['MAX_BY'] | I55: Toàn bộ script trong batch phải dùng cùng một cách lấy bản ghi mới nhất: max_by(<cột>, source_event_date) + GROUP BY hashkey. Không để file này dùng ROW_NUMBER, file kia dùng max_by. Hướng lọc cdc_status cũng phải nhất quán (luôn là loại 'D', không có chỗ nào giữ 'D'). | J55: C:\ZoneC_DEV\zonec-datamart\tools\gold_review\input\sql\BPM_TAT_TDCN.sql
A56: BPM_TAT_TDCN | B56: SILVER_CONSUMER | C56: 2.3 | D56: Nhom 2 - Logic | E56: Điều kiện lọc trạng thái đặt SAU khi xác định bản ghi mới nhất | F56: PASS | G56: Pass | H56: không có điều kiện trạng thái nào lồng trong JOIN ON | I56: Chuyển các điều kiện cdc_status / rn = 1 ra khỏi phần ON của LEFT JOIN, đưa vào WHERE hoặc QUALIFY của chính subquery/CTE lấy dữ liệu. Đặt trong ON của LEFT JOIN thì khi không match sẽ ra NULL âm thầm, sai kết quả (Issue log #3). Riêng pattern PIT (sat.source_event_date = p.<sat>_src_ev_dt) và 49 bảng transaction được phép đặt trong ON. | J56: C:\ZoneC_DEV\zonec-datamart\tools\gold_review\input\sql\BPM_TAT_TDCN.sql
A57: BPM_TAT_TDCN | B57: SILVER_CONSUMER | C57: 2.4 | D57: Nhom 2 - Logic | E57: source_event_date áp dụng đúng dạng theo loại bảng | F57: PASS | G57: Pass | H57: 18 bảng đều đúng dạng điều kiện source_event_date | I57: Bảng thường: WHERE source_event_date <= TO_DATE(:DATADT,'yyyyMMdd') và KHÔNG đặt cận dưới (>= start_date) vì sẽ bỏ sót bản ghi mới nhất nằm trước khoảng thời gian. Riêng 49 bảng transaction ở mục 'Các trường hợp đặc biệt' của Technical Document (sat_stmt_entry_*, sat_categ_entry_*, sat_account_balance, sat_funds_transfer_*, sat_gl_trace_*, …) phải dùng source_event_date = :DATADT. Danh sách đầy đủ ở tools/gold_review/doc_standard.py. | J57: C:\ZoneC_DEV\zonec-datamart\tools\gold_review\input\sql\BPM_TAT_TDCN.sql
A58: BPM_TAT_TDCN | B58: SILVER_CONSUMER | C58: 2.5 | D58: Nhom 2 - Logic | E58: Không lặp lại lỗi logic cũ đã được DA Data Vault fix | F58: PASS | G58: Pass | H58: không trùng lỗi nào trong Issue log của DA Data Vault | I58: Sửa đúng các dòng được chỉ ra ở trên theo pattern chuẩn: lấy bản ghi mới nhất bằng max_by(<cột>, source_event_date) + GROUP BY hashkey; trạng thái xoá lọc ở sts_hub_* bằng HAVING max_by(cdc_status, source_event_date) = 'D' rồi anti-join IS NULL; không đặt cdc_status / rn = 1 trong ON hay trong subquery của JOIN; surrogate key DIM không sinh bằng MAX(<DIM_ID>) + ROW_NUMBER(). Danh sách lỗi lấy từ 'ZoneC Mapping - Iss log.xlsx' sheet Issue; OCB trả lỗi mới thì thêm 1 regex vào tools/gold_review/engine/known_issues.json để lần sau tự bắt được. | J58: C:\ZoneC_DEV\zonec-datamart\tools\gold_review\input\sql\BPM_TAT_TDCN.sql
A59: BPM_TAT_TDCN | B59: SILVER_CONSUMER | C59: 2.6 | D59: Nhom 2 - Logic | E59: SCD Type 2 cho bảng DIM áp dụng đúng kỹ thuật đã thống nhất | F59: N-A | G59: Pass | H59: object không phải bảng DIM nên không áp dụng SCD Type 2 | I59: Dùng APPLY CHANGES INTO <bảng>_scd FROM STREAM(stg_<ent>_changes) KEYS (<hashkey>) SEQUENCE BY source_event_date STORED AS SCD TYPE 2 TRACK HISTORY ON (...) — Databricks tự quản __START_AT/__END_AT. Nếu tự quản thì phải có cột effective_date/end_date/current_flag. TUYỆT ĐỐI không sinh surrogate key bằng MAX(<DIM_ID>) + ROW_NUMBER() vì trùng khi chạy song song hoặc load lại lịch sử (Issue log #4). | J59: C:\ZoneC_DEV\zonec-datamart\tools\gold_review\input\sql\BPM_TAT_TDCN.sql
A60: BPM_TAT_TDCN | B60: SILVER_CONSUMER | C60: 2.7 | D60: Nhom 2 - Logic | E60: CASE WHEN cover đủ nhánh như job on-prem | F60: FAIL | G60: Fail | H60: 68/107 CASE KHÔNG có nhánh ELSE -> rơi ra ngoài mọi WHEN sẽ trả NULL âm thầm, tại dòng []; bổ sung ELSE (giá trị mặc định hoặc giá trị nghiệp vụ đúng như job on-prem) | I60: Mở job on-prem tương ứng (DataStage DSX hoặc SQL cũ), đối chiếu từng nhánh WHEN và cả nhánh ELSE. CASE không có ELSE sẽ trả NULL âm thầm — xác nhận đó là ý muốn hay thiếu nhánh. | J60: C:\ZoneC_DEV\zonec-datamart\tools\gold_review\input\sql\BPM_TAT_TDCN.sql
A61: BPM_TAT_TDCN | B61: SILVER_CONSUMER | C61: 2.8 | D61: Nhom 2 - Logic | E61: Cột SUM/COUNT được COALESCE/NVL hợp lý | F61: WARN | G61: WARN | H61: 16 biểu thức tổng hợp chưa coalesce: SUM(CASE WHEN ((a.trang_thai_bat_dau IN (460, 466, 468, 474,; SUM(CASE WHEN (a.trang_thai_bat_dau IN (465, 0, 491, 0, 499,; SUM(CASE WHEN (a.trang_thai_bat_dau IN (465, 467, 0, 0, 0, 4; SUM(CASE WHEN (a.trang_thai_bat_dau IN (466, 476, 0, 488, 48; SUM(CASE WHEN loai = 0 THEN 1.0 ELSE loai END); SUM(loai); khi đối soát với hệ thống cũ phải bọc NVL/ISNULL CẢ HAI phía để không lệch khi trừ (Checklist RVN-OCB #11) | I61: Bọc COALESCE(SUM(...), 0) cho các cột tổng hợp cần trả 0 khi không có dòng. Nếu code cũ không bọc thì giữ nguyên logic nhưng khi đối soát số liệu với hệ thống cũ phải bọc NVL/ISNULL ở CẢ HAI phía để không lệch khi trừ. | J61: C:\ZoneC_DEV\zonec-datamart\tools\gold_review\input\sql\BPM_TAT_TDCN.sql
...
