Workbook

Sheet Hướng dẫn
B2: CHECKLIST REVIEW CODE MAPPING SILVER (DATA VAULT 2.0) SANG GOLD (DATA MART) – ZONE C OCB
B4: Mục đích
B5: Đội Data Engineer của Raffles dùng checklist này để tự rà soát code và mapping của từng bảng/khung nhìn Zone C trước khi gửi OCB review. Nội dung checklist lấy từ hai nguồn: các tiêu chí đã thống nhất với OCB (sheet "Checklist - Raffles" và "Quality check") và các lỗi thực tế ghi nhận trong quá trình review Batch 1 (Issue log). Cách kiểm tra của từng tiêu chí tham chiếu trực tiếp đến tài liệu OCB_DBX_ZONEC – Technical Document v1.1, mục III.4.2 "Quy tắc khi xử lí các bảng từ Silver".
B6: Cách sử dụng
B7: 1. Sheet "Checklist tiêu chí": mô tả điều kiện đạt và cách kiểm tra của từng tiêu chí, kèm mục tài liệu tham chiếu.
B8: 2. Sheet "Review theo bảng": mỗi dòng là một bảng/khung nhìn Gold. Với từng tiêu chí, DE chọn Pass / Fail / N/A từ danh sách chọn. Tiêu chí Fail phải ghi bằng chứng tại cột "Ghi chú / Bằng chứng lỗi" theo dạng: mã tiêu chí, tên file script, dòng code hoặc tên CTE liên quan.
B9: 3. Tỷ lệ lỗi tính tự động theo trọng số đã thống nhất với OCB: Nhóm 1 – Summary/Mapping 10%, Nhóm 2 – Logic 80%, Nhóm 3 – Optimization 10%. Một tiêu chí Fail thì cả nhóm đó tính là lỗi cho bảng đang xét.
B10: 4. Sheet "Tổng hợp Dashboard": tổng hợp số bảng Đạt / Không đạt theo batch và so với ngưỡng lỗi cho phép (Batch 1: 30%; Batch 2 và Batch 3: 20%).
B11: 5. Chỉ gửi code và mapping sang OCB khi bảng có kết luận "Đạt". Bảng "Không đạt" phải sửa theo pattern chuẩn nêu tại cột "Điều kiện đạt / Cách kiểm tra" rồi review lại.
B12: Bốn lỗi phải kiểm tra kỹ (rút từ Issue log Batch 1)
B13: - Điều kiện source_event_date <= :DATADT bị bỏ sót ở một vài bảng trong cùng script, hoặc đặt thêm cận dưới (>= start_date) làm bỏ sót bản ghi trạng thái mới nhất – Issue log #1.
B14: - Cùng một mục đích lấy bản ghi hiệu lực nhưng mỗi script lọc cdc_status một kiểu khác nhau – Issue log #2. Toàn bộ Zone C dùng một pattern duy nhất tại mục III.4.2.1.
... B16: - Bảng DIM sinh surrogate key bằng MAX(<DIM_ID>) + ROW_NUMBER(), trùng khóa khi chạy song song hoặc nạp lại lịch sử – Issue log #4. Dùng APPLY CHANGES … STORED AS SCD TYPE 2.

Sheet Checklist tiêu chí
A1: Nhóm | B1: Trọng số nhóm | C1: Mã | D1: Tiêu chí kiểm tra | E1: Điều kiện đạt / Cách kiểm tra | F1: Tham chiếu (Technical Document / Issue log / Checklist RVN-OCB)
A2: Nhóm 1 - Summary / Mapping | B2: 0.1 | C2: 1.1 | D2: Mapping đầy đủ từ Silver và nguồn upload sang Gold | E2: Đối chiếu tài liệu mapping source-to-target với script: đủ cột đầu ra, đủ bảng nguồn cần dùng, không thêm cột ngoài đặc tả. Ghi dữ liệu vào đúng catalog/schema đích ocb_datavault_${env}_curated.<schema>, không hard-code tên catalog. | F2: TDD mục III.4.1 Quy ước chung; Quality check tiêu chí 1
A3: Nhóm 1 - Summary / Mapping | B3: 0.1 | C3: 1.2 | D3: Danh sách bảng và khung nhìn khớp tài liệu thiết kế | E3: Danh sách đối tượng triển khai trong batch khớp danh sách đã thống nhất với OCB. Thay đổi phạm vi hoặc mô hình dữ liệu phải được thống nhất và cập nhật vào tài liệu trước khi triển khai. | F3: TDD v1.1 mục I.3 Phạm vi tài liệu; Plan điều chỉnh 5.3.3
A4: Nhóm 2 - Logic | B4: 0.8 | C4: 2.1 | D4: Chỉ lấy bản ghi Hub đang có hiệu lực | E4: Join hub_* với sts_hub_* theo pattern tại mục III.4.2.1: GROUP BY hashkey, HAVING max_by(cdc_status, source_event_date) = 'D' để lấy tập khóa đã xóa, sau đó LEFT JOIN và loại các khóa này khỏi kết quả. Chỉ giữ bản ghi đã xóa khi có yêu cầu nghiệp vụ và phải ghi rõ trong mapping. | F4: TDD v1.1 mục III.4.2.1; Checklist RVN-OCB #1; Issue log #3
A5: Nhóm 2 - Logic | B5: 0.8 | C5: 2.2 | D5: Dùng một pattern thống nhất để lấy bản ghi hiệu lực | E5: Toàn bộ script Zone C dùng chung một pattern max_by(cdc_status, source_event_date) trên sts_hub. Không để hai script cùng xử lý một loại logic theo hai cách khác nhau, ví dụ một script lọc cdc_status <> 'D' trực tiếp trên satellite, script khác lọc = 'D' trên sts_hub. | F5: TDD v1.1 mục III.4.2.1; Issue log #2
A6: Nhóm 2 - Logic | B6: 0.8 | C6: 2.3 | D6: Điều kiện trạng thái đặt ở lớp ngoài, không đặt trong ON của LEFT JOIN | E6: Điều kiện lọc trạng thái và điều kiện lấy bản ghi mới nhất đặt tại WHERE hoặc QUALIFY của lớp ngoài. Đặt trong ON của LEFT JOIN sẽ sai kết quả khi không match. Ngoại lệ được phép: join PIT với satellite theo source_event_date = <sat>_src_ev_dt là equi-join nên đặt trong ON. | F6: TDD v1.1 mục III.4.2.3 và III.4.2.4; Issue log #3
A7: Nhóm 2 - Logic | B7: 0.8 | C7: 2.4 | D7: Điều kiện source_event_date áp dụng nhất quán trong cùng script | E7: Mọi hub, satellite, link, effsat trong cùng một script đều chặn source_event_date <= TO_DATE(:DATADT,'yyyyMMdd'), không đặt cận dưới. Riêng nhóm bảng transaction tại mục "Các trường hợp đặc biệt" lọc source_event_date = :DATADT. Bảng PIT lọc theo snapshot_date. | F7: TDD v1.1 mục III.4.2 và mục "Các trường hợp đặc biệt"; Issue log #1
A8: Nhóm 2 - Logic | B8: 0.8 | C8: 2.5 | D8: Không lặp lại lỗi logic đã được xử lý trước đó | E8: Đối chiếu với các lỗi mà DA Data Vault đã xác nhận sửa ở các lần review trước; script viết lại trên nền tảng mới không quay lại logic cũ. Ghi rõ trong ghi chú các điểm đã từng bị sửa để reviewer đối chiếu nhanh. | F8: Issue log #1
A9: Nhóm 2 - Logic | B9: 0.8 | C9: 2.6 | D9: Bảng DIM áp dụng SCD Type 2 theo cơ chế APPLY CHANGES | E9: Bảng DIM dùng APPLY CHANGES INTO … KEYS (…) SEQUENCE BY … STORED AS SCD TYPE 2 trên streaming table. Không tự sinh surrogate key bằng MAX(<DIM_ID>) + ROW_NUMBER() vì trùng khóa khi chạy song song hoặc nạp lại dữ liệu lịch sử. | F9: TDD v1.1 mục III.2.3 và III.2.4; Issue log #4 | G9: đang pending
A10: Nhóm 2 - Logic | B10: 0.8 | C10: 2.7 | D10: CASE WHEN đủ nhánh so với job hiện hữu | E10: So từng nhánh CASE WHEN với job on-prem tương ứng, gồm cả nhánh ELSE và giá trị mặc định. Giữ nguyên logic cũ nếu chưa có thay đổi được thống nhất; thay đổi phải ghi vào tài liệu mapping. | F10: Checklist RVN-OCB #10
A11: Nhóm 2 - Logic | B11: 0.8 | C11: 2.8 | D11: Cột SUM và COUNT xử lý giá trị NULL đúng | E11: Cột tổng hợp coalesce về 0 khi nghiệp vụ yêu cầu. Nếu code hiện hữu không dùng NVL thì giữ nguyên hành vi của code cũ và bổ sung NVL ở script đối soát để không lệch khi lấy hiệu số. | F11: Checklist RVN-OCB #11
A12: Nhóm 2 - Logic | B12: 0.8 | C12: 2.9 | D12: Subquery, custom function và điều kiện LIKE đúng ý nghĩa nghiệp vụ | E12: Đọc lại logic bên trong subquery, custom function và các điều kiện LIKE, xác nhận đúng ý nghĩa nghiệp vụ so với job hiện hữu, không chỉ đúng cú pháp. Ghi lại cách hiểu nghiệp vụ trong mapping để OCB xác nhận. | F12: Checklist RVN-OCB #6
A13: Nhóm 2 - Logic | B13: 0.8 | C13: 2.10 | D13: Aggregation lọc đúng kỳ dữ liệu | E13: Điều kiện lọc kỳ báo cáo đi kèm SUM/COUNT/AVG đúng phạm vi ngày hoặc tháng cần xử lý. Bảng nạp theo tháng lọc theo kỳ đang chạy, không quét toàn bộ lịch sử. | F13: Checklist RVN-OCB #7
A14: Nhóm 2 - Logic | B14: 0.8 | C14: 2.11 | D14: Join theo key đúng, không lạm dụng UNION ALL kết hợp EXISTS | E14: LEFT JOIN theo hashkey hoặc business key. Link phải rút về quan hệ hiện hành trước khi join vào fact/dim: quan hệ 1:N lấy theo driving key, quan hệ M:N khử trùng ở mức link_hashkey. Thay union all kết hợp exists/not exists bằng join khi đã có key phù hợp. | F14: TDD v1.1 mục III.4.2.3; Checklist RVN-OCB #4
A15: Nhóm 2 - Logic | B15: 0.8 | C15: 2.12 | D15: Bảng Gold build từ CTE snapshot dữ liệu Silver | E15: Mỗi bảng Silver được đọc một lần trong CTE snapshot theo :DATADT rồi dùng lại trong script. Không đọc lại cùng một bảng ở nhiều nhánh với điều kiện thời điểm khác nhau, tránh lệch thời điểm dữ liệu giữa các phần của cùng một script. | F15: TDD v1.1 mục III.4.2; Checklist RVN-OCB #4
A16: Nhóm 3 - Optimization | B16: 0.1 | C16: 3.1 | D16: Không dùng SELECT * | E16: Chỉ select các cột thực sự dùng ở Gold, kể cả trong CTE trung gian. Nhánh sts_hub chỉ lấy cột hashkey để join gọn. | F16: TDD v1.1 mục III.4.2.2; Checklist RVN-OCB #2
A17: Nhóm 3 - Optimization | B17: 0.1 | C17: 3.2 | D17: CTE không bị tính lại nhiều lần | E17: CTE nặng chỉ được tham chiếu một lần. Nếu buộc phải dùng lại nhiều lần thì tách thành bảng trung gian hoặc cache để không tính lại. | F17: Checklist RVN-OCB #4
A18: Nhóm 3 - Optimization | B18: 0.1 | C18: 3.3 | D18: Lọc trước khi join, tận dụng partition pruning | E18: Đặt điều kiện ngày dữ liệu ngay trong CTE nguồn trước khi join, để giới hạn dữ liệu quét theo partition và giảm shuffle. | F18: Checklist RVN-OCB #5
A19: Nhóm 3 - Optimization | B19: 0.1 | C19: 3.4 | D19: Cache kết quả được dùng lại trong cùng luồng | E19: Truy vấn dùng lại ở nhiều bước trong cùng một luồng thì cache hoặc vật chất hóa thành Materialized View thay vì tính lại từng lần. | F19: TDD v1.1 mục III.2.2; Checklist RVN-OCB #3
A20: Nhóm 3 - Optimization | B20: 0.1 | C20: 3.5 | D20: Dùng MAX_BY thay ROW_NUMBER() kết hợp rn = 1 | E20: Lấy bản ghi mới nhất bằng max_by(<cột>, source_event_date) với GROUP BY theo pattern chuẩn, thay cho ROW_NUMBER() OVER (…) kết hợp WHERE rn = 1. | F20: TDD v1.1 mục III.4.2; Issue log #5
A21: Nhóm 3 - Optimization | B21: 0.1 | C21: 3.6 | D21: Window function dùng có chủ đích và có comment | E21: Chỉ dùng window function khi max_by hoặc QUALIFY không đáp ứng được yêu cầu nghiệp vụ. Khi dùng phải ghi comment nêu lý do ngay tại chỗ dùng. | F21: Checklist RVN-OCB #8

Sheet Review theo bảng
A1: STT | B1: Tên bảng / khung nhìn (Gold) | C1: Batch | D1: PIC review | E1: Ngày review | F1: NHÓM 1 - SUMMARY / MAPPING (trọng số 10%) | H1: NHÓM 2 - LOGIC (trọng số 80%) | T1: NHÓM 3 - OPTIMIZATION (trọng số 10%) | Z1: KẾT QUẢ TỔNG HỢP (tự động tính)
F2: Đủ mapping Silver → Gold (1.1) | G2: Danh sách bảng khớp thiết kế (1.2) | H2: Hub hiệu lực qua sts_hub (2.1) | I2: Một pattern lấy bản ghi hiệu lực (2.2) | J2: Điều kiện trạng thái ở lớp ngoài (2.3) | K2: source_event_date nhất quán (2.4) | L2: Không lặp lỗi đã xử lý (2.5) | M2: DIM SCD2 bằng APPLY CHANGES (2.6) | N2: CASE WHEN đủ nhánh (2.7) | O2: SUM/COUNT xử lý NULL (2.8) | P2: Subquery/function/ LIKE đúng nghiệp vụ (2.9) | Q2: Aggregation đúng kỳ dữ liệu (2.10) | R2: Join đúng key, link về hiện hành (2.11) | S2: Build từ CTE snapshot Silver (2.12) | T2: Không SELECT * (3.1) | U2: CTE không tính lại nhiều lần (3.2) | V2: Lọc trước join, partition pruning (3.3) | W2: Cache truy vấn dùng lại (3.4) | X2: MAX_BY thay ROW_NUMBER (3.5) | Y2: Window function có comment (3.6) | Z2: N1 Fail? | AA2: N2 Fail? | AB2: N3 Fail? | AC2: Tỷ lệ lỗi bảng | AD2: Ngưỡng cho phép | AE2: Kết luận | AF2: Ghi rõ: mã tiêu chí – file script – dòng/CTE
A3: 1 | Z3: =IF(B3="","",IF(COUNTIF(F3:G3,"Fail")>0,1,0)) | AA3: =IF(B3="","",IF(COUNTIF(H3:S3,"Fail")>0,1,0)) | AB3: =IF(B3="","",IF(COUNTIF(T3:Y3,"Fail")>0,1,0)) | AC3: =IF(B3="","",0.1*Z3+0.8*AA3+0.1*AB3) | AD3: =IF(B3="","",IF(C3="Batch 1",0.3,0.2)) | AE3: =IF(B3="","",IF(AC3<=AD3,"Đạt","Không đạt"))
A4: 2 | B4: TCKH.AR_DIM | C4: Batch 2 | D4: HOP | E4: 2026-08-05 | F4: Pass | G4: Pass | H4: Pass | I4: Pass | J4: Pass | K4: Fail | L4: Fail | M4: Fail | N4: Pass | O4: Pass | P4: Pass | Q4: WARN | R4: Pass | S4: Fail | T4: Fail | U4: WARN | V4: Pass | W4: WARN | X4: Pass | Y4: Pass | Z4: =IF(B4="","",IF(COUNTIF(F4:G4,"Fail")>0,1,0)) -> 0 | AA4: =IF(B4="","",IF(COUNTIF(H4:S4,"Fail")>0,1,0)) -> 1 | AB4: =IF(B4="","",IF(COUNTIF(T4:Y4,"Fail")>0,1,0)) -> 1 | AC4: =IF(B4="","",0.1*Z4+0.8*AA4+0.1*AB4) -> 0.9 | AD4: =IF(B4="","",IF(C4="Batch 1",0.3,0.2)) -> 0.2 | AE4: =IF(B4="","",IF(AC4<=AD4,"Đạt","Không đạt")) -> Không đạt | AF4: ╔══ FAIL: 7 tiêu chí — 2.4, 2.5, 2.6, 2.12, 3.1, X.3, X.8 ▼ 2.4 — source_event_date áp dụng đúng dạng theo loại bảng • Lý do: 16 satellite không có điều kiện source_event_date nào: sat_account_information (dong 123), sat_account_locked_events_information (dong 183), sat_collateral_information (dong 139), sat_consumer_loan_information (dong 171), sat_drawings_information (dong 189), sat_forex_information (dong 147), sat_letter_of_credit_information (dong 155), sat_limit_information (dong 163), sat_loans_information (dong 131), sat_loans_payment_due_information (dong 231), sat_md_deal_information (dong 216), sat_money_market_information (dong 224), sat_passbook_information (dong 177), sat_repo_information (dong 195), sat_sc_trading_position_information (dong 202), sat_sec_trade_information (dong 208) → Cách sửa: Bảng thường: WHERE source_event_date <= TO_DATE(:DATADT,'yyyyMMdd') và KHÔNG đặt cận dưới (>= start_date) vì sẽ bỏ sót bản ghi mới nhất nằm trước khoảng thời gian. Riêng 49 bảng transaction ở mục 'Các trường hợp đặc biệt' của Technical Document (sat_stmt_entry_*, sat_categ_entry_*, sat_account_balance, sat_funds_transfer_*, sat_gl_trace_*, …) phải dùng source_event_date = :DATADT. Danh sách đầy đủ ở tools/gold_review/doc_standard.py. ▼ 2.5 — Không lặp lại lỗi logic cũ đã được DA Data Vault fix • Lý do: lặp lại 1 lỗi DA Data Vault đã nêu ở Issue log: Issue#5 ROW_NUMBER()+WHERE rn=1 thay vi MAX_BY (cham hon) @ dòng [412] → Cách sửa: Sửa đúng các dòng được chỉ ra ở trên theo pattern chuẩn: lấy bản ghi mới nhất bằng max_by(<cột>, source_event_date) + GROUP BY hashkey; trạng thái xoá lọc ở sts_hub_* bằng HAVING max_by(cdc_status, source_event_date) = 'D' rồi anti-join IS NULL; không đặt cdc_status / rn = 1 trong ON hay trong subquery của JOIN; surrogate key DIM không sinh bằng MAX(<DIM_ID>) + ROW_NUMBER(). Danh sách lỗi lấy từ 'ZoneC Mapping - Iss log.xlsx' sheet Issue; OCB trả lỗi mới thì thêm 1 regex vào tools/gold_review/engine/known_issues.json để lần sau tự bắt được. ▼ 2.6 — SCD Type 2 cho bảng DIM áp dụng đúng kỹ thuật đã thống nhất • Lý do: không dùng APPLY CHANGES ... SCD TYPE 2 và cũng không có cột effective_date/end_date/current_flag để tự quản hiệu lực → Cách sửa: Dùng APPLY CHANGES INTO <bảng>_scd FROM STREAM(stg_<ent>_changes) KEYS (<hashkey>) SEQUENCE BY source_event_date STORED AS SCD TYPE 2 TRACK HISTORY ON (...) — Databricks tự quản __START_AT/__END_AT. Nếu tự quản thì phải có cột effective_date/end_date/current_flag. TUYỆT ĐỐI không sinh surrogate key bằng MAX(<DIM_ID>) + ROW_NUMBER() vì trùng khi chạy song song hoặc load lại lịch sử (Issue log #4). ▼ 2.12 — Build Gold từ CTE snapshot Silver, không build nhiều tầng chồng chéo • Lý do: bảng Silver bị đọc ở nhiều khối SELECT khác nhau thay vì snapshot 1 CTE: raw_vault.hub_account ở 2 khối → Cách sửa: Mỗi bảng Silver chỉ đọc MỘT lần, snapshot vào một CTE ở đầu script rồi dùng lại. Đọc trực tiếp cùng một bảng raw_vault ở 2 chỗ khác nhau làm lệch thời điểm dữ liệu giữa các phần của cùng một script. ▼ 3.1 — Không SELECT * • Lý do: có 1 lần SELECT * ở dòng [392] → Cách sửa: Liệt kê tường minh các cột cần dùng, kể cả trong CTE trung gian. SELECT * làm tăng IO/memory và vỡ script khi bảng nguồn thêm cột. ▼ X.3 — [Bổ sung] INSERT INTO phải liệt kê cột khớp DDL [không tính điểm OCB] • Lý do: 1 câu INSERT không liệt kê cột, ở dòng [28] → Cách sửa: Viết INSERT INTO <bảng> (COT_1, COT_2, ...) SELECT ... Nếu không liệt kê cột, chỉ cần thêm một cột vào DDL là toàn bộ dữ liệu lệch cột mà không có lỗi nào báo ra. ▼ X.8 — [Bổ sung] JOIN SCHEMA trong thiết kế khớp bảng nguồn trong SQL [không tính điểm OCB] • Lý do: 3/3 bảng khai báo trong JOIN SCHEMA nhưng KHÔNG thấy trong SQL: ['hub_* (18 blocks)', 'sts_hub_* (14 blocks có sts)', 'sat_*_information'] → Cách sửa: Bảng khai báo ở block JOIN SCHEMA của workbook phải xuất hiện trong SQL và ngược lại. Lệch tên (thiếu tiền tố TB_, sai chính tả) nghĩa là thiết kế và code đi hai đường — phải xác nhận tên bảng thật rồi sửa một trong hai bên. ╔══ CẢNH BÁO — KHÔNG tính lỗi: 3 tiêu chí — 2.10, 3.2, 3.4 (ô ghi 'Pass', tô vàng nhạt. Chưa sai kết quả, nhưng nếu job chạy chậm thì xem lại đúng các chỗ này để tối ưu) ▼ 2.10 — Aggregation kèm filter date range chính xác • Ghi nhận: 16 khối tổng hợp không thấy filter theo ngày/tham số: sat_account, sat_loans, sat_collateral, sat_forex, sat_lc, sat_limit → Nếu cần tối ưu: Mỗi khối SUM/COUNT/AVG phải có điều kiện lọc theo kỳ dữ liệu (CDR_DT_ID, DATA_DATE, :DATADT…). Nếu điều kiện nằm ở CTE nguồn thì ghi rõ trong comment để người review không phải truy ngược. ▼ 3.2 — CTE không bị scan lại nhiều lần • Ghi nhận: CTE bị tham chiếu lại nhiều lần: sts_account x2, sat_account x2 → Nếu cần tối ưu: Với CTE nặng (đọc nhiều bảng Silver) bị tham chiếu từ 2 chỗ trở lên: gom lại còn một lần dùng, hoặc vật chất hóa (CACHE / bảng tạm). CTE nhẹ chỉ chứa tham số thì bỏ qua được — tự tick Pass. ▼ 3.4 — Sử dụng CACHE cho query lặp lại trong cùng luồng • Ghi nhận: 2 CTE nặng dùng lại >= 2 lần mà không có CACHE: sat_account, sts_account → Nếu cần tối ưu: Nếu một kết quả nặng được dùng lại nhiều bước trong cùng luồng, thêm CACHE TABLE / CACHE SELECT. Kết quả nhỏ thì cache còn chậm hơn — tự tick Pass.
A5: 3 | B5: TCKH.BRANCH_LIST | C5: Batch 2 | D5: HOP | E5: 2026-08-05 | F5: Pass | G5: Pass | H5: Pass | I5: Pass | J5: Pass | K5: Pass | L5: Pass | M5: Pass | N5: Pass | O5: Pass | P5: Pass | Q5: Pass | R5: Pass | S5: Pass | T5: Pass | U5: Pass | V5: Pass | W5: Pass | X5: Pass | Y5: Pass | Z5: =IF(B5="","",IF(COUNTIF(F5:G5,"Fail")>0,1,0)) -> 0 | AA5: =IF(B5="","",IF(COUNTIF(H5:S5,"Fail")>0,1,0)) -> 0 | AB5: =IF(B5="","",IF(COUNTIF(T5:Y5,"Fail")>0,1,0)) -> 0 | AC5: =IF(B5="","",0.1*Z5+0.8*AA5+0.1*AB5) -> 0 | AD5: =IF(B5="","",IF(C5="Batch 1",0.3,0.2)) -> 0.2 | AE5: =IF(B5="","",IF(AC5<=AD5,"Đạt","Không đạt")) -> Đạt | AF5: ╔══ CẢNH BÁO — KHÔNG tính lỗi: 1 tiêu chí — X.8 (ô ghi 'Pass', tô vàng nhạt. Chưa sai kết quả, nhưng nếu job chạy chậm thì xem lại đúng các chỗ này để tối ưu) ▼ X.8 — [Bổ sung] JOIN SCHEMA trong thiết kế khớp bảng nguồn trong SQL [không tính điểm OCB] • Ghi nhận: SQL đọc 1 bảng mà JOIN SCHEMA không khai báo: ['CB_OU_DIM'] → Nếu cần tối ưu: Bảng khai báo ở block JOIN SCHEMA của workbook phải xuất hiện trong SQL và ngược lại. Lệch tên (thiếu tiền tố TB_, sai chính tả) nghĩa là thiết kế và code đi hai đường — phải xác nhận tên bảng thật rồi sửa một trong hai bên.
A6: 4 | B6: TCKH.CB_OU_DIM | C6: Batch 2 | D6: HOP | E6: 2026-08-05 | F6: Pass | G6: Pass | H6: Pass | I6: Pass | J6: Pass | K6: Pass | L6: Fail | M6: Fail | N6: Pass | O6: Pass | P6: Pass | Q6: WARN | R6: Pass | S6: Pass | T6: Fail | U6: WARN | V6: WARN | W6: WARN | X6: Pass | Y6: WARN | Z6: =IF(B6="","",IF(COUNTIF(F6:G6,"Fail")>0,1,0)) -> 0 | AA6: =IF(B6="","",IF(COUNTIF(H6:S6,"Fail")>0,1,0)) -> 1 | AB6: =IF(B6="","",IF(COUNTIF(T6:Y6,"Fail")>0,1,0)) -> 1 | AC6: =IF(B6="","",0.1*Z6+0.8*AA6+0.1*AB6) -> 0.9 | AD6: =IF(B6="","",IF(C6="Batch 1",0.3,0.2)) -> 0.2 | AE6: =IF(B6="","",IF(AC6<=AD6,"Đạt","Không đạt")) -> Không đạt | AF6: ╔══ FAIL: 3 tiêu chí — 2.5, 2.6, 3.1 ▼ 2.5 — Không lặp lại lỗi logic cũ đã được DA Data Vault fix • Lý do: lặp lại 2 lỗi DA Data Vault đã nêu ở Issue log: Issue#4 surrogate key DIM sinh bang MAX(<DIM_ID>) + ROW_NUMBER (trung khi chay song song) @ dòng [5]; Issue#4 COALESCE(MAX(<DIM_ID>),0) lam moc tang dan cho surrogate key @ dòng [97] → Cách sửa: Sửa đúng các dòng được chỉ ra ở trên theo pattern chuẩn: lấy bản ghi mới nhất bằng max_by(<cột>, source_event_date) + GROUP BY hashkey; trạng thái xoá lọc ở sts_hub_* bằng HAVING max_by(cdc_status, source_event_date) = 'D' rồi anti-join IS NULL; không đặt cdc_status / rn = 1 trong ON hay trong subquery của JOIN; surrogate key DIM không sinh bằng MAX(<DIM_ID>) + ROW_NUMBER(). Danh sách lỗi lấy từ 'ZoneC Mapping - Iss log.xlsx' sheet Issue; OCB trả lỗi mới thì thêm 1 regex vào tools/gold_review/engine/known_issues.json để lần sau tự bắt được. ▼ 2.6 — SCD Type 2 cho bảng DIM áp dụng đúng kỹ thuật đã thống nhất • Lý do: dùng antipattern MAX(ID) + ROW_NUMBER để sinh surrogate key ở dòng [5, 130] (Issue log #4) → Cách sửa: Dùng APPLY CHANGES INTO <bảng>_scd FROM STREAM(stg_<ent>_changes) KEYS (<hashkey>) SEQUENCE BY source_event_date STORED AS SCD TYPE 2 TRACK HISTORY ON (...) — Databricks tự quản __START_AT/__END_AT. Nếu tự quản thì phải có cột effective_date/end_date/current_flag. TUYỆT ĐỐI không sinh surrogate key bằng MAX(<DIM_ID>) + ROW_NUMBER() vì trùng khi chạy song song hoặc load lại lịch sử (Issue log #4). ▼ 3.1 — Không SELECT * • Lý do: có 2 lần SELECT * ở dòng [165, 167] → Cách sửa: Liệt kê tường minh các cột cần dùng, kể cả trong CTE trung gian. SELECT * làm tăng IO/memory và vỡ script khi bảng nguồn thêm cột. ╔══ CẢNH BÁO — KHÔNG tính lỗi: 5 tiêu chí — 2.10, 3.2, 3.3, 3.4, 3.6 (ô ghi 'Pass', tô vàng nhạt. Chưa sai kết quả, nhưng nếu job chạy chậm thì xem lại đúng các chỗ này để tối ưu) ▼ 2.10 — Aggregation kèm filter date range chính xác • Ghi nhận: 1 khối tổng hợp không thấy filter theo ngày/tham số: max_id → Nếu cần tối ưu: Mỗi khối SUM/COUNT/AVG phải có điều kiện lọc theo kỳ dữ liệu (CDR_DT_ID, DATA_DATE, :DATADT…). Nếu điều kiện nằm ở CTE nguồn thì ghi rõ trong comment để người review không phải truy ngược. ▼ 3.2 — CTE không bị scan lại nhiều lần • Ghi nhận: CTE bị tham chiếu lại nhiều lần: hub_active x2, sat_latest x2, source_data x3, changed x2 → Nếu cần tối ưu: Với CTE nặng (đọc nhiều bảng Silver) bị tham chiếu từ 2 chỗ trở lên: gom lại còn một lần dùng, hoặc vật chất hóa (CACHE / bảng tạm). CTE nhẹ chỉ chứa tham số thì bỏ qua được — tự tick Pass. ▼ 3.3 — Filter trước khi join, tận dụng partition pruning • Ghi nhận: 1 bảng join trực tiếp mà không có filter riêng: ou_area_mapping (am) → Nếu cần tối ưu: Đưa điều kiện lọc (ngày dữ liệu, trạng thái) vào subquery của từng bảng TRƯỚC khi join, để tận dụng partition pruning. Bảng dim nhỏ không partition thì không cần — tự tick Pass. ▼ 3.4 — Sử dụng CACHE cho query lặp lại trong cùng luồng • Ghi nhận: 4 CTE nặng dùng lại >= 2 lần mà không có CACHE: changed, hub_active, sat_latest, source_data → Nếu cần tối ưu: Nếu một kết quả nặng được dùng lại nhiều bước trong cùng luồng, thêm CACHE TABLE / CACHE SELECT. Kết quả nhỏ thì cache còn chậm hơn — tự tick Pass. ▼ 3.6 — Không lạm dụng window function; có comment khi dùng • Ghi nhận: 1/1 window function không có comment giải thích, ở dòng [130] → Nếu cần tối ưu: Mỗi window function cần một comment ngay trên khối CTE chứa nó, nói rõ vì sao không dùng được max_by/QUALIFY đơn giản hơn. ╔══ CHƯA CÓ SỐ LIỆU: 2 tiêu chí — 2.7, 2.9 (chưa có con số để kết luận, sẽ có sau khi UAT test; đang ghi tạm Pass — cập nhật lại ô sau khi có số) ▼ 2.7 — CASE WHEN cover đủ nhánh như job on-prem • Hiện trạng: có 1 CASE, trong đó 0 CASE không có nhánh ELSE (trả NULL âm thầm) • Hiện trạng: chưa so từng nhánh WHEN với job on-prem → Cần làm: Mở job on-prem tương ứng (DataStage DSX hoặc SQL cũ), đối chiếu từng nhánh WHEN và cả nhánh ELSE. CASE không có ELSE sẽ trả NULL âm thầm — xác nhận đó là ý muốn hay thiếu nhánh. ▼ 2.9 — Subquery / custom function / điều kiện LIKE đúng ý nghĩa nghiệp vụ • Hiện trạng: 2 subquery nằm trong điều kiện • Hiện trạng: chỉ kiểm được cú pháp; ý nghĩa nghiệp vụ cần đối chiếu job on-prem → Cần làm: Đọc lại từng điều kiện LIKE và từng subquery, đối chiếu ý nghĩa nghiệp vụ với on-prem — đúng cú pháp không đủ. Chú ý pattern LIKE có ký tự % ở đầu/cuối và phân biệt chữ hoa/thường.
A7: 5 | B7: TCKH.CST_DIM_NEW | C7: Batch 2 | D7: HOP | E7: 2026-08-05 | F7: Pass | G7: Pass | H7: Pass | I7: Pass | J7: Pass | K7: Fail | L7: Pass | M7: Pass | N7: Pass | O7: Pass | P7: Pass | Q7: Pass | R7: Pass | S7: Fail | T7: Pass | U7: Pass | V7: Pass | W7: Pass | X7: Pass | Y7: Pass | Z7: =IF(B7="","",IF(COUNTIF(F7:G7,"Fail")>0,1,0)) -> 0 | AA7: =IF(B7="","",IF(COUNTIF(H7:S7,"Fail")>0,1,0)) -> 1 | AB7: =IF(B7="","",IF(COUNTIF(T7:Y7,"Fail")>0,1,0)) -> 0 | AC7: =IF(B7="","",0.1*Z7+0.8*AA7+0.1*AB7) -> 0.8 | AD7: =IF(B7="","",IF(C7="Batch 1",0.3,0.2)) -> 0.2 | AE7: =IF(B7="","",IF(AC7<=AD7,"Đạt","Không đạt")) -> Không đạt | AF7: ╔══ FAIL: 5 tiêu chí — 2.4, 2.12, X.3, X.4, X.8 ▼ 2.4 — source_event_date áp dụng đúng dạng theo loại bảng • Lý do: sat_customer_contact (dong 59): dùng = :DATADT nhưng KHÔNG thuộc danh sách 49 bảng transaction, sẽ bỏ sót bản ghi mới nhất nằm trước ngày chạy (Issue log #1) • Lý do: sat_customer_contact (dong 59): dùng = :DATADT nhưng KHÔNG thuộc danh sách 49 bảng transaction, sẽ bỏ sót bản ghi mới nhất nằm trước ngày chạy (Issue log #1) → Cách sửa: Bảng thường: WHERE source_event_date <= TO_DATE(:DATADT,'yyyyMMdd') và KHÔNG đặt cận dưới (>= start_date) vì sẽ bỏ sót bản ghi mới nhất nằm trước khoảng thời gian. Riêng 49 bảng transaction ở mục 'Các trường hợp đặc biệt' của Technical Document (sat_stmt_entry_*, sat_categ_entry_*, sat_account_balance, sat_funds_transfer_*, sat_gl_trace_*, …) phải dùng source_event_date = :DATADT. Danh sách đầy đủ ở tools/gold_review/doc_standard.py. ▼ 2.12 — Build Gold từ CTE snapshot Silver, không build nhiều tầng chồng chéo • Lý do: bảng Silver bị đọc ở nhiều khối SELECT khác nhau thay vì snapshot 1 CTE: raw_vault.sat_customer_contact ở 2 khối → Cách sửa: Mỗi bảng Silver chỉ đọc MỘT lần, snapshot vào một CTE ở đầu script rồi dùng lại. Đọc trực tiếp cùng một bảng raw_vault ở 2 chỗ khác nhau làm lệch thời điểm dữ liệu giữa các phần của cùng một script. ▼ X.3 — [Bổ sung] INSERT INTO phải liệt kê cột khớp DDL [không tính điểm OCB] • Lý do: 1 câu INSERT không liệt kê cột, ở dòng [36] → Cách sửa: Viết INSERT INTO <bảng> (COT_1, COT_2, ...) SELECT ... Nếu không liệt kê cột, chỉ cần thêm một cột vào DDL là toàn bộ dữ liệu lệch cột mà không có lỗi nào báo ra. ▼ X.4 — [Bổ sung] Idempotent: có DELETE/TRUNCATE khớp khóa trước INSERT [không tính điểm OCB] • Lý do: có INSERT mà không có DELETE/TRUNCATE, chạy lại lần 2 sẽ nhân đôi dữ liệu → Cách sửa: Trước INSERT phải có DELETE theo đúng khóa kỳ dữ liệu (hoặc TRUNCATE / INSERT OVERWRITE) để chạy lại không nhân đôi dữ liệu. Chú ý khóa DELETE phải là khóa thực sự phân vùng dữ liệu — ví dụ RT_PL_DTL_ADJ đổi CDR_DT_ID nên phải DELETE theo PST_ENTR_DT. ▼ X.8 — [Bổ sung] JOIN SCHEMA trong thiết kế khớp bảng nguồn trong SQL [không tính điểm OCB] • Lý do: 8/8 bảng khai báo trong JOIN SCHEMA nhưng KHÔNG thấy trong SQL: ['cust_active (CTE)', 'sts_deleted (CTE)', 'sat_info (CTE)', 'sat_kyc (CTE)', 'sat_cls (CTE)', 'cte_pst (CTE)'] → Cách sửa: Bảng khai báo ở block JOIN SCHEMA của workbook phải xuất hiện trong SQL và ngược lại. Lệch tên (thiếu tiền tố TB_, sai chính tả) nghĩa là thiết kế và code đi hai đường — phải xác nhận tên bảng thật rồi sửa một trong hai bên. ╔══ CHƯA CÓ SỐ LIỆU: 1 tiêu chí — 2.7 (chưa có con số để kết luận, sẽ có sau khi UAT test; đang ghi tạm Pass — cập nhật lại ô sau khi có số) ▼ 2.7 — CASE WHEN cover đủ nhánh như job on-prem • Hiện trạng: có 1 CASE, trong đó 0 CASE không có nhánh ELSE (trả NULL âm thầm) • Hiện trạng: chưa so từng nhánh WHEN với job on-prem → Cần làm: Mở job on-prem tương ứng (DataStage DSX hoặc SQL cũ), đối chiếu từng nhánh WHEN và cả nhánh ELSE. CASE không có ELSE sẽ trả NULL âm thầm — xác nhận đó là ý muốn hay thiếu nhánh.
A8: 6 | B8: TCKH.FTP_CONTRACT_HIST | C8: Batch 2 | D8: HOP | E8: 2026-08-05 | F8: Pass | G8: Pass | H8: Pass | I8: Pass | J8: Pass | K8: Pass | L8: Pass | M8: Pass | N8: Pass | O8: Pass | P8: Pass | Q8: Pass | R8: Pass | S8: Pass | T8: Pass | U8: Pass | V8: Pass | W8: Pass | X8: Pass | Y8: Pass | Z8: =IF(B8="","",IF(COUNTIF(F8:G8,"Fail")>0,1,0)) -> 0 | AA8: =IF(B8="","",IF(COUNTIF(H8:S8,"Fail")>0,1,0)) -> 0 | AB8: =IF(B8="","",IF(COUNTIF(T8:Y8,"Fail")>0,1,0)) -> 0 | AC8: =IF(B8="","",0.1*Z8+0.8*AA8+0.1*AB8) -> 0 | AD8: =IF(B8="","",IF(C8="Batch 1",0.3,0.2)) -> 0.2 | AE8: =IF(B8="","",IF(AC8<=AD8,"Đạt","Không đạt")) -> Đạt | AF8: Đạt toàn bộ tiêu chí.
A9: 7 | B9: TCKH.FTP_RATE_LIST_HIST | C9: Batch 2 | D9: HOP | E9: 2026-08-05 | F9: Pass | G9: Pass | H9: Pass | I9: Pass | J9: Pass | K9: Pass | L9: Pass | M9: Pass | N9: Pass | O9: Pass | P9: Pass | Q9: Pass | R9: Pass | S9: Pass | T9: Pass | U9: Pass | V9: Pass | W9: Pass | X9: Pass | Y9: Pass | Z9: =IF(B9="","",IF(COUNTIF(F9:G9,"Fail")>0,1,0)) -> 0 | AA9: =IF(B9="","",IF(COUNTIF(H9:S9,"Fail")>0,1,0)) -> 0 | AB9: =IF(B9="","",IF(COUNTIF(T9:Y9,"Fail")>0,1,0)) -> 0 | AC9: =IF(B9="","",0.1*Z9+0.8*AA9+0.1*AB9) -> 0 | AD9: =IF(B9="","",IF(C9="Batch 1",0.3,0.2)) -> 0.2 | AE9: =IF(B9="","",IF(AC9<=AD9,"Đạt","Không đạt")) -> Đạt | AF9: ╔══ FAIL: 1 tiêu chí — X.9 ▼ X.9 — [Bổ sung] Mọi bảng phải dev lại từ Silver [không tính điểm OCB] • Lý do: 1 nguồn nằm trong lượt chạy nhưng KHÔNG truy được về Silver: ['ftp_rate_list_hist'] • Lý do: nếu là bảng upload/thủ công thì khai ở cột NOTE của JOIN SCHEMA trong workbook → Cách sửa: Quy định đã chốt: tất cả bảng Gold đều dev lại từ Silver. Script phải đọc raw_vault/business_vault, hoặc đọc bảng Gold khác mà bảng đó cũng dev từ Silver (tool truy theo chuỗi, ví dụ v_cdtk_daily → holiday → calendar). Bảng upload/thủ công (có DDL + data nạp tay) LÀ nguồn hợp lệ, nhưng phải khai rõ ở cột NOTE của dòng JOIN SCHEMA tương ứng, ví dụ "TABLE upload thu cong (khong qua ETL/Silver)" — khai rồi thì tool tự chấp nhận. Không khai thì tool không phân biệt được với trường hợp quên dev từ Silver. Lưu ý tên bảng trong SQL phải khớp tên khai ở JOIN SCHEMA, lệch một ký tự là không ghép được.
A10: 8 | B10: TCKH.GL_ACCT_DIM | C10: Batch 2 | D10: BAOANH | E10: 2026-08-05 | F10: Pass | G10: Pass | H10: Pass | I10: Pass | J10: Pass | K10: Pass | L10: Pass | M10: Fail | N10: Pass | O10: Pass | P10: Pass | Q10: Pass | R10: Pass | S10: Pass | T10: Pass | U10: Pass | V10: Pass | W10: Pass | X10: Pass | Y10: Pass | Z10: =IF(B10="","",IF(COUNTIF(F10:G10,"Fail")>0,1,0)) -> 0 | AA10: =IF(B10="","",IF(COUNTIF(H10:S10,"Fail")>0,1,0)) -> 1 | AB10: =IF(B10="","",IF(COUNTIF(T10:Y10,"Fail")>0,1,0)) -> 0 | AC10: =IF(B10="","",0.1*Z10+0.8*AA10+0.1*AB10) -> 0.8 | AD10: =IF(B10="","",IF(C10="Batch 1",0.3,0.2)) -> 0.2 | AE10: =IF(B10="","",IF(AC10<=AD10,"Đạt","Không đạt")) -> Không đạt | AF10: ╔══ FAIL: 1 tiêu chí — 2.6 ▼ 2.6 — SCD Type 2 cho bảng DIM áp dụng đúng kỹ thuật đã thống nhất • Lý do: không dùng APPLY CHANGES ... SCD TYPE 2 và cũng không có cột effective_date/end_date/current_flag để tự quản hiệu lực → Cách sửa: Dùng APPLY CHANGES INTO <bảng>_scd FROM STREAM(stg_<ent>_changes) KEYS (<hashkey>) SEQUENCE BY source_event_date STORED AS SCD TYPE 2 TRACK HISTORY ON (...) — Databricks tự quản __START_AT/__END_AT. Nếu tự quản thì phải có cột effective_date/end_date/current_flag. TUYỆT ĐỐI không sinh surrogate key bằng MAX(<DIM_ID>) + ROW_NUMBER() vì trùng khi chạy song song hoặc load lại lịch sử (Issue log #4).
A11: 9 | B11: GSTX.GSTX_INTF_DUPL_CIF | C11: Batch 2 | D11: Huy | E11: 2026-08-05 | F11: Pass | G11: Pass | H11: Pass | I11: Pass | J11: Pass | K11: Pass | L11: Pass | M11: Pass | N11: Pass | O11: Pass | P11: Pass | Q11: Pass | R11: Pass | S11: Pass | T11: Pass | U11: Pass | V11: Pass | W11: Pass | X11: Pass | Y11: Pass | Z11: =IF(B11="","",IF(COUNTIF(F11:G11,"Fail")>0,1,0)) -> 0 | AA11: =IF(B11="","",IF(COUNTIF(H11:S11,"Fail")>0,1,0)) -> 0 | AB11: =IF(B11="","",IF(COUNTIF(T11:Y11,"Fail")>0,1,0)) -> 0 | AC11: =IF(B11="","",0.1*Z11+0.8*AA11+0.1*AB11) -> 0 | AD11: =IF(B11="","",IF(C11="Batch 1",0.3,0.2)) -> 0.2 | AE11: =IF(B11="","",IF(AC11<=AD11,"Đạt","Không đạt")) -> Đạt | AF11: ╔══ CHƯA CÓ SỐ LIỆU: 20 tiêu chí — 1.1, 1.2, 2.1, 2.2, 2.3, 2.4, 2.5, 2.6, 2.7, 2.8, 2.9, 2.10, 2.11, 2.12, 3.1, 3.2, 3.3, 3.4, 3.5, 3.6 (chưa có con số để kết luận, sẽ có sau khi UAT test; đang ghi tạm Pass — cập nhật lại ô sau khi có số) ▼ 1.1 — Đầy đủ mapping từ Silver/manual sang Gold • Hiện trạng: TAM HOAN CHAM - schema 'gstx' chua ton tai tren moi truong nen chua deploy/test duoc - tam hoan cham, phai cham lai sau khi tao schema → Cần làm: Mở workbook thiết kế, đối chiếu block FIELD MAPPING với danh sách cột trong câu SELECT/INSERT của file SQL. Cột nào thiếu thì bổ sung vào SQL; cột nào SQL có mà thiết kế không có thì bổ sung vào workbook hoặc bỏ khỏi SQL. ▼ 1.2 — Danh sách bảng/view Gold khớp tài liệu thiết kế đã duyệt • Hiện trạng: TAM HOAN CHAM - schema 'gstx' chua ton tai tren moi truong nen chua deploy/test duoc - tam hoan cham, phai cham lai sau khi tao schema → Cần làm: Đảm bảo object có workbook thiết kế tương ứng trong thư mục --mapping-dir. Muốn đối chiếu với danh sách đã duyệt thì chạy thêm tham số --gold-list "<file danh sách Gold>.xlsx". ▼ 2.1 — Chỉ lấy bản ghi active, loại bản ghi đã xóa (qua sts_hub) • Hiện trạng: TAM HOAN CHAM - schema 'gstx' chua ton tai tren moi truong nen chua deploy/test duoc - tam hoan cham, phai cham lai sau khi tao schema → Cần làm: Theo Technical Document mục III.4.2.1: với mỗi hub_<ent> phải thêm 2 CTE — (1) <ent>_sts_del đọc sts_hub_<ent>, GROUP BY hashkey, HAVING max_by(cdc_status, source_event_date) = 'D'; (2) <ent>_active đọc hub_<ent> LEFT JOIN <ent>_sts_del rồi lọc d.<hashkey> IS NULL. Tuyệt đối KHÔNG lọc cdc_status trong satellite — trạng thái xóa chỉ lọc ở sts_hub. ▼ 2.2 — Thống nhất MỘT pattern duy nhất xác định bản ghi active mới nhất • Hiện trạng: TAM HOAN CHAM - schema 'gstx' chua ton tai tren moi truong nen chua deploy/test duoc - tam hoan cham, phai cham lai sau khi tao schema → Cần làm: Toàn bộ script trong batch phải dùng cùng một cách lấy bản ghi mới nhất: max_by(<cột>, source_event_date) + GROUP BY hashkey. Không để file này dùng ROW_NUMBER, file kia dùng max_by. Hướng lọc cdc_status cũng phải nhất quán (luôn là loại 'D', không có chỗ nào giữ 'D'). ▼ 2.3 — Điều kiện lọc trạng thái đặt SAU khi xác định bản ghi mới nhất • Hiện trạng: TAM HOAN CHAM - schema 'gstx' chua ton tai tren moi truong nen chua deploy/test duoc - tam hoan cham, phai cham lai sau khi tao schema → Cần làm: Chuyển các điều kiện cdc_status / rn = 1 ra khỏi phần ON của LEFT JOIN, đưa vào WHERE hoặc QUALIFY của chính subquery/CTE lấy dữ liệu. Đặt trong ON của LEFT JOIN thì khi không match sẽ ra NULL âm thầm, sai kết quả (Issue log #3). Riêng pattern PIT (sat.source_event_date = p.<sat>_src_ev_dt) và 49 bảng transaction được phép đặt trong ON. ▼ 2.4 — source_event_date áp dụng đúng dạng theo loại bảng • Hiện trạng: TAM HOAN CHAM - schema 'gstx' chua ton tai tren moi truong nen chua deploy/test duoc - tam hoan cham, phai cham lai sau khi tao schema → Cần làm: Bảng thường: WHERE source_event_date <= TO_DATE(:DATADT,'yyyyMMdd') và KHÔNG đặt cận dưới (>= start_date) vì sẽ bỏ sót bản ghi mới nhất nằm trước khoảng thời gian. Riêng 49 bảng transaction ở mục 'Các trường hợp đặc biệt' của Technical Document (sat_stmt_entry_*, sat_categ_entry_*, sat_account_balance, sat_funds_transfer_*, sat_gl_trace_*, …) phải dùng source_event_date = :DATADT. Danh sách đầy đủ ở tools/gold_review/doc_standard.py. ▼ 2.5 — Không lặp lại lỗi logic cũ đã được DA Data Vault fix • Hiện trạng: TAM HOAN CHAM - schema 'gstx' chua ton tai tren moi truong nen chua deploy/test duoc - tam hoan cham, phai cham lai sau khi tao schema → Cần làm: Sửa đúng các dòng được chỉ ra ở trên theo pattern chuẩn: lấy bản ghi mới nhất bằng max_by(<cột>, source_event_date) + GROUP BY hashkey; trạng thái xoá lọc ở sts_hub_* bằng HAVING max_by(cdc_status, source_event_date) = 'D' rồi anti-join IS NULL; không đặt cdc_status / rn = 1 trong ON hay trong subquery của JOIN; surrogate key DIM không sinh bằng MAX(<DIM_ID>) + ROW_NUMBER(). Danh sách lỗi lấy từ 'ZoneC Mapping - Iss log.xlsx' sheet Issue; OCB trả lỗi mới thì thêm 1 regex vào tools/gold_review/engine/known_issues.json để lần sau tự bắt được. ▼ 2.6 — SCD Type 2 cho bảng DIM áp dụng đúng kỹ thuật đã thống nhất • Hiện trạng: TAM HOAN CHAM - schema 'gstx' chua ton tai tren moi truong nen chua deploy/test duoc - tam hoan cham, phai cham lai sau khi tao schema → Cần làm: Dùng APPLY CHANGES INTO <bảng>_scd FROM STREAM(stg_<ent>_changes) KEYS (<hashkey>) SEQUENCE BY source_event_date STORED AS SCD TYPE 2 TRACK HISTORY ON (...) — Databricks tự quản __START_AT/__END_AT. Nếu tự quản thì phải có cột effective_date/end_date/current_flag. TUYỆT ĐỐI không sinh surrogate key bằng MAX(<DIM_ID>) + ROW_NUMBER() vì trùng khi chạy song song hoặc load lại lịch sử (Issue log #4). ▼ 2.7 — CASE WHEN cover đủ nhánh như job on-prem • Hiện trạng: TAM HOAN CHAM - schema 'gstx' chua ton tai tren moi truong nen chua deploy/test duoc - tam hoan cham, phai cham lai sau khi tao schema → Cần làm: Mở job on-prem tương ứng (DataStage DSX hoặc SQL cũ), đối chiếu từng nhánh WHEN và cả nhánh ELSE. CASE không có ELSE sẽ trả NULL âm thầm — xác nhận đó là ý muốn hay thiếu nhánh. ▼ 2.8 — Cột SUM/COUNT được COALESCE/NVL hợp lý • Hiện trạng: TAM HOAN CHAM - schema 'gstx' chua ton tai tren moi truong nen chua deploy/test duoc - tam hoan cham, phai cham lai sau khi tao schema → Cần làm: Bọc COALESCE(SUM(...), 0) cho các cột tổng hợp cần trả 0 khi không có dòng. Nếu code cũ không bọc thì giữ nguyên logic nhưng khi đối soát số liệu với hệ thống cũ phải bọc NVL/ISNULL ở CẢ HAI phía để không lệch khi trừ. ▼ 2.9 — Subquery / custom function / điều kiện LIKE đúng ý nghĩa nghiệp vụ • Hiện trạng: TAM HOAN CHAM - schema 'gstx' chua ton tai tren moi truong nen chua deploy/test duoc - tam hoan cham, phai cham lai sau khi tao schema → Cần làm: Đọc lại từng điều kiện LIKE và từng subquery, đối chiếu ý nghĩa nghiệp vụ với on-prem — đúng cú pháp không đủ. Chú ý pattern LIKE có ký tự % ở đầu/cuối và phân biệt chữ hoa/thường. ▼ 2.10 — Aggregation kèm filter date range chính xác • Hiện trạng: TAM HOAN CHAM - schema 'gstx' chua ton tai tren moi truong nen chua deploy/test duoc - tam hoan cham, phai cham lai sau khi tao schema → Cần làm: Mỗi khối SUM/COUNT/AVG phải có điều kiện lọc theo kỳ dữ liệu (CDR_DT_ID, DATA_DATE, :DATADT…). Nếu điều kiện nằm ở CTE nguồn thì ghi rõ trong comment để người review không phải truy ngược. ▼ 2.11 — Join dùng key hợp lý, không lạm dụng UNION ALL + EXISTS/NOT EXISTS • Hiện trạng: TAM HOAN CHAM - schema 'gstx' chua ton tai tren moi truong nen chua deploy/test duoc - tam hoan cham, phai cham lai sau khi tao schema → Cần làm: Ưu tiên LEFT JOIN theo business key hoặc hashkey. Xem lại các chỗ dùng UNION ALL kết hợp EXISTS/NOT EXISTS — thường thay được bằng một LEFT JOIN. Join không có điều kiện bằng (=) dễ tạo tích Descartes. ▼ 2.12 — Build Gold từ CTE snapshot Silver, không build nhiều tầng chồng chéo • Hiện trạng: TAM HOAN CHAM - schema 'gstx' chua ton tai tren moi truong nen chua deploy/test duoc - tam hoan cham, phai cham lai sau khi tao schema → Cần làm: Mỗi bảng Silver chỉ đọc MỘT lần, snapshot vào một CTE ở đầu script rồi dùng lại. Đọc trực tiếp cùng một bảng raw_vault ở 2 chỗ khác nhau làm lệch thời điểm dữ liệu giữa các phần của cùng một script. ▼ 3.1 — Không SELECT * • Hiện trạng: TAM HOAN CHAM - schema 'gstx' chua ton tai tren moi truong nen chua deploy/test duoc - tam hoan cham, phai cham lai sau khi tao schema → Cần làm: Liệt kê tường minh các cột cần dùng, kể cả trong CTE trung gian. SELECT * làm tăng IO/memory và vỡ script khi bảng nguồn thêm cột. ▼ 3.2 — CTE không bị scan lại nhiều lần • Hiện trạng: TAM HOAN CHAM - schema 'gstx' chua ton tai tren moi truong nen chua deploy/test duoc - tam hoan cham, phai cham lai sau khi tao schema → Cần làm: Với CTE nặng (đọc nhiều bảng Silver) bị tham chiếu từ 2 chỗ trở lên: gom lại còn một lần dùng, hoặc vật chất hóa (CACHE / bảng tạm). CTE nhẹ chỉ chứa tham số thì bỏ qua được — tự tick Pass. ▼ 3.3 — Filter trước khi join, tận dụng partition pruning • Hiện trạng: TAM HOAN CHAM - schema 'gstx' chua ton tai tren moi truong nen chua deploy/test duoc - tam hoan cham, phai cham lai sau khi tao schema → Cần làm: Đưa điều kiện lọc (ngày dữ liệu, trạng thái) vào subquery của từng bảng TRƯỚC khi join, để tận dụng partition pruning. Bảng dim nhỏ không partition thì không cần — tự tick Pass. ▼ 3.4 — Sử dụng CACHE cho query lặp lại trong cùng luồng • Hiện trạng: TAM HOAN CHAM - schema 'gstx' chua ton tai tren moi truong nen chua deploy/test duoc - tam hoan cham, phai cham lai sau khi tao schema → Cần làm: Nếu một kết quả nặng được dùng lại nhiều bước trong cùng luồng, thêm CACHE TABLE / CACHE SELECT. Kết quả nhỏ thì cache còn chậm hơn — tự tick Pass. ▼ 3.5 — Ưu tiên MAX_BY + QUALIFY thay ROW_NUMBER() + WHERE rn = 1 • Hiện trạng: TAM HOAN CHAM - schema 'gstx' chua ton tai tren moi truong nen chua deploy/test duoc - tam hoan cham, phai cham lai sau khi tao schema → Cần làm: Thay ROW_NUMBER() OVER (PARTITION BY hk ORDER BY source_event_date DESC) + WHERE rn = 1 bằng max_by(<cột>, source_event_date) + GROUP BY hk (Issue log #5). Nếu buộc phải lấy nhiều cột của CÙNG một dòng mới nhất thì dùng QUALIFY ROW_NUMBER() ... = 1 và ghi comment giải thích lý do. ▼ 3.6 — Không lạm dụng window function; có comment khi dùng • Hiện trạng: TAM HOAN CHAM - schema 'gstx' chua ton tai tren moi truong nen chua deploy/test duoc - tam hoan cham, phai cham lai sau khi tao schema → Cần làm: Mỗi window function cần một comment ngay trên khối CTE chứa nó, nói rõ vì sao không dùng được max_by/QUALIFY đơn giản hơn.
A12: 10 | B12: GSTX.GSTX_INTF_NOT_UPLOADED_CIF | C12: Batch 2 | D12: Huy | E12: 2026-08-05 | F12: Pass | G12: Pass | H12: Pass | I12: Pass | J12: Pass | K12: Pass | L12: Pass | M12: Pass | N12: Pass | O12: Pass | P12: Pass | Q12: Pass | R12: Pass | S12: Pass | T12: Pass | U12: Pass | V12: Pass | W12: Pass | X12: Pass | Y12: Pass | Z12: =IF(B12="","",IF(COUNTIF(F12:G12,"Fail")>0,1,0)) -> 0 | AA12: =IF(B12="","",IF(COUNTIF(H12:S12,"Fail")>0,1,0)) -> 0 | AB12: =IF(B12="","",IF(COUNTIF(T12:Y12,"Fail")>0,1,0)) -> 0 | AC12: =IF(B12="","",0.1*Z12+0.8*AA12+0.1*AB12) -> 0 | AD12: =IF(B12="","",IF(C12="Batch 1",0.3,0.2)) -> 0.2 | AE12: =IF(B12="","",IF(AC12<=AD12,"Đạt","Không đạt")) -> Đạt | AF12: ╔══ CHƯA CÓ SỐ LIỆU: 20 tiêu chí — 1.1, 1.2, 2.1, 2.2, 2.3, 2.4, 2.5, 2.6, 2.7, 2.8, 2.9, 2.10, 2.11, 2.12, 3.1, 3.2, 3.3, 3.4, 3.5, 3.6 (chưa có con số để kết luận, sẽ có sau khi UAT test; đang ghi tạm Pass — cập nhật lại ô sau khi có số) ▼ 1.1 — Đầy đủ mapping từ Silver/manual sang Gold • Hiện trạng: TAM HOAN CHAM - schema 'gstx' chua ton tai tren moi truong nen chua deploy/test duoc - tam hoan cham, phai cham lai sau khi tao schema → Cần làm: Mở workbook thiết kế, đối chiếu block FIELD MAPPING với danh sách cột trong câu SELECT/INSERT của file SQL. Cột nào thiếu thì bổ sung vào SQL; cột nào SQL có mà thiết kế không có thì bổ sung vào workbook hoặc bỏ khỏi SQL. ▼ 1.2 — Danh sách bảng/view Gold khớp tài liệu thiết kế đã duyệt • Hiện trạng: TAM HOAN CHAM - schema 'gstx' chua ton tai tren moi truong nen chua deploy/test duoc - tam hoan cham, phai cham lai sau khi tao schema → Cần làm: Đảm bảo object có workbook thiết kế tương ứng trong thư mục --mapping-dir. Muốn đối chiếu với danh sách đã duyệt thì chạy thêm tham số --gold-list "<file danh sách Gold>.xlsx". ▼ 2.1 — Chỉ lấy bản ghi active, loại bản ghi đã xóa (qua sts_hub) • Hiện trạng: TAM HOAN CHAM - schema 'gstx' chua ton tai tren moi truong nen chua deploy/test duoc - tam hoan cham, phai cham lai sau khi tao schema → Cần làm: Theo Technical Document mục III.4.2.1: với mỗi hub_<ent> phải thêm 2 CTE — (1) <ent>_sts_del đọc sts_hub_<ent>, GROUP BY hashkey, HAVING max_by(cdc_status, source_event_date) = 'D'; (2) <ent>_active đọc hub_<ent> LEFT JOIN <ent>_sts_del rồi lọc d.<hashkey> IS NULL. Tuyệt đối KHÔNG lọc cdc_status trong satellite — trạng thái xóa chỉ lọc ở sts_hub. ▼ 2.2 — Thống nhất MỘT pattern duy nhất xác định bản ghi active mới nhất • Hiện trạng: TAM HOAN CHAM - schema 'gstx' chua ton tai tren moi truong nen chua deploy/test duoc - tam hoan cham, phai cham lai sau khi tao schema → Cần làm: Toàn bộ script trong batch phải dùng cùng một cách lấy bản ghi mới nhất: max_by(<cột>, source_event_date) + GROUP BY hashkey. Không để file này dùng ROW_NUMBER, file kia dùng max_by. Hướng lọc cdc_status cũng phải nhất quán (luôn là loại 'D', không có chỗ nào giữ 'D'). ▼ 2.3 — Điều kiện lọc trạng thái đặt SAU khi xác định bản ghi mới nhất • Hiện trạng: TAM HOAN CHAM - schema 'gstx' chua ton tai tren moi truong nen chua deploy/test duoc - tam hoan cham, phai cham lai sau khi tao schema → Cần làm: Chuyển các điều kiện cdc_status / rn = 1 ra khỏi phần ON của LEFT JOIN, đưa vào WHERE hoặc QUALIFY của chính subquery/CTE lấy dữ liệu. Đặt trong ON của LEFT JOIN thì khi không match sẽ ra NULL âm thầm, sai kết quả (Issue log #3). Riêng pattern PIT (sat.source_event_date = p.<sat>_src_ev_dt) và 49 bảng transaction được phép đặt trong ON. ▼ 2.4 — source_event_date áp dụng đúng dạng theo loại bảng • Hiện trạng: TAM HOAN CHAM - schema 'gstx' chua ton tai tren moi truong nen chua deploy/test duoc - tam hoan cham, phai cham lai sau khi tao schema → Cần làm: Bảng thường: WHERE source_event_date <= TO_DATE(:DATADT,'yyyyMMdd') và KHÔNG đặt cận dưới (>= start_date) vì sẽ bỏ sót bản ghi mới nhất nằm trước khoảng thời gian. Riêng 49 bảng transaction ở mục 'Các trường hợp đặc biệt' của Technical Document (sat_stmt_entry_*, sat_categ_entry_*, sat_account_balance, sat_funds_transfer_*, sat_gl_trace_*, …) phải dùng source_event_date = :DATADT. Danh sách đầy đủ ở tools/gold_review/doc_standard.py. ▼ 2.5 — Không lặp lại lỗi logic cũ đã được DA Data Vault fix • Hiện trạng: TAM HOAN CHAM - schema 'gstx' chua ton tai tren moi truong nen chua deploy/test duoc - tam hoan cham, phai cham lai sau khi tao schema → Cần làm: Sửa đúng các dòng được chỉ ra ở trên theo pattern chuẩn: lấy bản ghi mới nhất bằng max_by(<cột>, source_event_date) + GROUP BY hashkey; trạng thái xoá lọc ở sts_hub_* bằng HAVING max_by(cdc_status, source_event_date) = 'D' rồi anti-join IS NULL; không đặt cdc_status / rn = 1 trong ON hay trong subquery của JOIN; surrogate key DIM không sinh bằng MAX(<DIM_ID>) + ROW_NUMBER(). Danh sách lỗi lấy từ 'ZoneC Mapping - Iss log.xlsx' sheet Issue; OCB trả lỗi mới thì thêm 1 regex vào tools/gold_review/engine/known_issues.json để lần sau tự bắt được. ▼ 2.6 — SCD Type 2 cho bảng DIM áp dụng đúng kỹ thuật đã thống nhất • Hiện trạng: TAM HOAN CHAM - schema 'gstx' chua ton tai tren moi truong nen chua deploy/test duoc - tam hoan cham, phai cham lai sau khi tao schema → Cần làm: Dùng APPLY CHANGES INTO <bảng>_scd FROM STREAM(stg_<ent>_changes) KEYS (<hashkey>) SEQUENCE BY source_event_date STORED AS SCD TYPE 2 TRACK HISTORY ON (...) — Databricks tự quản __START_AT/__END_AT. Nếu tự quản thì phải có cột effective_date/end_date/current_flag. TUYỆT ĐỐI không sinh surrogate key bằng MAX(<DIM_ID>) + ROW_NUMBER() vì trùng khi chạy song song hoặc load lại lịch sử (Issue log #4). ▼ 2.7 — CASE WHEN cover đủ nhánh như job on-prem • Hiện trạng: TAM HOAN CHAM - schema 'gstx' chua ton tai tren moi truong nen chua deploy/test duoc - tam hoan cham, phai cham lai sau khi tao schema → Cần làm: Mở job on-prem tương ứng (DataStage DSX hoặc SQL cũ), đối chiếu từng nhánh WHEN và cả nhánh ELSE. CASE không có ELSE sẽ trả NULL âm thầm — xác nhận đó là ý muốn hay thiếu nhánh. ▼ 2.8 — Cột SUM/COUNT được COALESCE/NVL hợp lý • Hiện trạng: TAM HOAN CHAM - schema 'gstx' chua ton tai tren moi truong nen chua deploy/test duoc - tam hoan cham, phai cham lai sau khi tao schema → Cần làm: Bọc COALESCE(SUM(...), 0) cho các cột tổng hợp cần trả 0 khi không có dòng. Nếu code cũ không bọc thì giữ nguyên logic nhưng khi đối soát số liệu với hệ thống cũ phải bọc NVL/ISNULL ở CẢ HAI phía để không lệch khi trừ. ▼ 2.9 — Subquery / custom function / điều kiện LIKE đúng ý nghĩa nghiệp vụ • Hiện trạng: TAM HOAN CHAM - schema 'gstx' chua ton tai tren moi truong nen chua deploy/test duoc - tam hoan cham, phai cham lai sau khi tao schema → Cần làm: Đọc lại từng điều kiện LIKE và từng subquery, đối chiếu ý nghĩa nghiệp vụ với on-prem — đúng cú pháp không đủ. Chú ý pattern LIKE có ký tự % ở đầu/cuối và phân biệt chữ hoa/thường. ▼ 2.10 — Aggregation kèm filter date range chính xác • Hiện trạng: TAM HOAN CHAM - schema 'gstx' chua ton tai tren moi truong nen chua deploy/test duoc - tam hoan cham, phai cham lai sau khi tao schema → Cần làm: Mỗi khối SUM/COUNT/AVG phải có điều kiện lọc theo kỳ dữ liệu (CDR_DT_ID, DATA_DATE, :DATADT…). Nếu điều kiện nằm ở CTE nguồn thì ghi rõ trong comment để người review không phải truy ngược. ▼ 2.11 — Join dùng key hợp lý, không lạm dụng UNION ALL + EXISTS/NOT EXISTS • Hiện trạng: TAM HOAN CHAM - schema 'gstx' chua ton tai tren moi truong nen chua deploy/test duoc - tam hoan cham, phai cham lai sau khi tao schema → Cần làm: Ưu tiên LEFT JOIN theo business key hoặc hashkey. Xem lại các chỗ dùng UNION ALL kết hợp EXISTS/NOT EXISTS — thường thay được bằng một LEFT JOIN. Join không có điều kiện bằng (=) dễ tạo tích Descartes. ▼ 2.12 — Build Gold từ CTE snapshot Silver, không build nhiều tầng chồng chéo • Hiện trạng: TAM HOAN CHAM - schema 'gstx' chua ton tai tren moi truong nen chua deploy/test duoc - tam hoan cham, phai cham lai sau khi tao schema → Cần làm: Mỗi bảng Silver chỉ đọc MỘT lần, snapshot vào một CTE ở đầu script rồi dùng lại. Đọc trực tiếp cùng một bảng raw_vault ở 2 chỗ khác nhau làm lệch thời điểm dữ liệu giữa các phần của cùng một script. ▼ 3.1 — Không SELECT * • Hiện trạng: TAM HOAN CHAM - schema 'gstx' chua ton tai tren moi truong nen chua deploy/test duoc - tam hoan cham, phai cham lai sau khi tao schema → Cần làm: Liệt kê tường minh các cột cần dùng, kể cả trong CTE trung gian. SELECT * làm tăng IO/memory và vỡ script khi bảng nguồn thêm cột. ▼ 3.2 — CTE không bị scan lại nhiều lần • Hiện trạng: TAM HOAN CHAM - schema 'gstx' chua ton tai tren moi truong nen chua deploy/test duoc - tam hoan cham, phai cham lai sau khi tao schema → Cần làm: Với CTE nặng (đọc nhiều bảng Silver) bị tham chiếu từ 2 chỗ trở lên: gom lại còn một lần dùng, hoặc vật chất hóa (CACHE / bảng tạm). CTE nhẹ chỉ chứa tham số thì bỏ qua được — tự tick Pass. ▼ 3.3 — Filter trước khi join, tận dụng partition pruning • Hiện trạng: TAM HOAN CHAM - schema 'gstx' chua ton tai tren moi truong nen chua deploy/test duoc - tam hoan cham, phai cham lai sau khi tao schema → Cần làm: Đưa điều kiện lọc (ngày dữ liệu, trạng thái) vào subquery của từng bảng TRƯỚC khi join, để tận dụng partition pruning. Bảng dim nhỏ không partition thì không cần — tự tick Pass. ▼ 3.4 — Sử dụng CACHE cho query lặp lại trong cùng luồng • Hiện trạng: TAM HOAN CHAM - schema 'gstx' chua ton tai tren moi truong nen chua deploy/test duoc - tam hoan cham, phai cham lai sau khi tao schema → Cần làm: Nếu một kết quả nặng được dùng lại nhiều bước trong cùng luồng, thêm CACHE TABLE / CACHE SELECT. Kết quả nhỏ thì cache còn chậm hơn — tự tick Pass. ▼ 3.5 — Ưu tiên MAX_BY + QUALIFY thay ROW_NUMBER() + WHERE rn = 1 • Hiện trạng: TAM HOAN CHAM - schema 'gstx' chua ton tai tren moi truong nen chua deploy/test duoc - tam hoan cham, phai cham lai sau khi tao schema → Cần làm: Thay ROW_NUMBER() OVER (PARTITION BY hk ORDER BY source_event_date DESC) + WHERE rn = 1 bằng max_by(<cột>, source_event_date) + GROUP BY hk (Issue log #5). Nếu buộc phải lấy nhiều cột của CÙNG một dòng mới nhất thì dùng QUALIFY ROW_NUMBER() ... = 1 và ghi comment giải thích lý do. ▼ 3.6 — Không lạm dụng window function; có comment khi dùng • Hiện trạng: TAM HOAN CHAM - schema 'gstx' chua ton tai tren moi truong nen chua deploy/test duoc - tam hoan cham, phai cham lai sau khi tao schema → Cần làm: Mỗi window function cần một comment ngay trên khối CTE chứa nó, nói rõ vì sao không dùng được max_by/QUALIFY đơn giản hơn.
A13: 11 | B13: TCKH.HOLIDAY | C13: Batch 2 | D13: BAOANH | E13: 2026-08-05 | F13: Pass | G13: Pass | H13: Pass | I13: Pass | J13: Pass | K13: Pass | L13: Pass | M13: Pass | N13: Pass | O13: Pass | P13: Pass | Q13: Pass | R13: Pass | S13: Pass | T13: Pass | U13: Pass | V13: Pass | W13: Pass | X13: Pass | Y13: Pass | Z13: =IF(B13="","",IF(COUNTIF(F13:G13,"Fail")>0,1,0)) -> 0 | AA13: =IF(B13="","",IF(COUNTIF(H13:S13,"Fail")>0,1,0)) -> 0 | AB13: =IF(B13="","",IF(COUNTIF(T13:Y13,"Fail")>0,1,0)) -> 0 | AC13: =IF(B13="","",0.1*Z13+0.8*AA13+0.1*AB13) -> 0 | AD13: =IF(B13="","",IF(C13="Batch 1",0.3,0.2)) -> 0.2 | AE13: =IF(B13="","",IF(AC13<=AD13,"Đạt","Không đạt")) -> Đạt | AF13: Đạt toàn bộ tiêu chí.
A14: 12 | B14: TCKH.LD_FTP_RATE | C14: Batch 2 | D14: HOP | E14: 2026-08-05 | F14: Pass | G14: Pass | H14: Pass | I14: Pass | J14: Pass | K14: Pass | L14: Pass | M14: Pass | N14: Pass | O14: Pass | P14: Pass | Q14: Pass | R14: Pass | S14: Pass | T14: Pass | U14: Pass | V14: Pass | W14: Pass | X14: Pass | Y14: Pass | Z14: =IF(B14="","",IF(COUNTIF(F14:G14,"Fail")>0,1,0)) -> 0 | AA14: =IF(B14="","",IF(COUNTIF(H14:S14,"Fail")>0,1,0)) -> 0 | AB14: =IF(B14="","",IF(COUNTIF(T14:Y14,"Fail")>0,1,0)) -> 0 | AC14: =IF(B14="","",0.1*Z14+0.8*AA14+0.1*AB14) -> 0 | AD14: =IF(B14="","",IF(C14="Batch 1",0.3,0.2)) -> 0.2 | AE14: =IF(B14="","",IF(AC14<=AD14,"Đạt","Không đạt")) -> Đạt | AF14: ╔══ FAIL: 1 tiêu chí — X.8 ▼ X.8 — [Bổ sung] JOIN SCHEMA trong thiết kế khớp bảng nguồn trong SQL [không tính điểm OCB] • Lý do: 1/1 bảng khai báo trong JOIN SCHEMA nhưng KHÔNG thấy trong SQL: ['V_LD_FTP_RATE'] → Cách sửa: Bảng khai báo ở block JOIN SCHEMA của workbook phải xuất hiện trong SQL và ngược lại. Lệch tên (thiếu tiền tố TB_, sai chính tả) nghĩa là thiết kế và code đi hai đường — phải xác nhận tên bảng thật rồi sửa một trong hai bên.
A15: 13 | B15: TCKH.OPEX_DTL | C15: Batch 2 | D15: HOP | E15: 2026-08-05 | F15: Pass | G15: Pass | H15: Pass | I15: Pass | J15: Pass | K15: Pass | L15: Pass | M15: Pass | N15: Pass | O15: Pass | P15: Pass | Q15: Pass | R15: Pass | S15: Pass | T15: Pass | U15: Pass | V15: Pass | W15: Pass | X15: Pass | Y15: Pass | Z15: =IF(B15="","",IF(COUNTIF(F15:G15,"Fail")>0,1,0)) -> 0 | AA15: =IF(B15="","",IF(COUNTIF(H15:S15,"Fail")>0,1,0)) -> 0 | AB15: =IF(B15="","",IF(COUNTIF(T15:Y15,"Fail")>0,1,0)) -> 0 | AC15: =IF(B15="","",0.1*Z15+0.8*AA15+0.1*AB15) -> 0 | AD15: =IF(B15="","",IF(C15="Batch 1",0.3,0.2)) -> 0.2 | AE15: =IF(B15="","",IF(AC15<=AD15,"Đạt","Không đạt")) -> Đạt | AF15: ╔══ FAIL: 1 tiêu chí — X.3 ▼ X.3 — [Bổ sung] INSERT INTO phải liệt kê cột khớp DDL [không tính điểm OCB] • Lý do: 1 câu INSERT không liệt kê cột, ở dòng [16] → Cách sửa: Viết INSERT INTO <bảng> (COT_1, COT_2, ...) SELECT ... Nếu không liệt kê cột, chỉ cần thêm một cột vào DDL là toàn bộ dữ liệu lệch cột mà không có lỗi nào báo ra.
... A48: 46 | B48: TCKH.WORKING_DAY | C48: Batch 2 | D48: BAOANH | E48: 2026-08-05 | F48: Pass | G48: Pass | H48: Pass | I48: Pass | J48: Pass | K48: Pass | L48: Pass | M48: Pass | N48: Pass | O48: Pass | P48: Pass | Q48: Pass | R48: Pass | S48: WARN | T48: Pass | U48: Pass | V48: Pass | W48: Pass | X48: Pass | Y48: Pass | Z48: =IF(B48="","",IF(COUNTIF(F48:G48,"Fail")>0,1,0)) -> 0 | AA48: =IF(B48="","",IF(COUNTIF(H48:S48,"Fail")>0,1,0)) -> 0 | AB48: =IF(B48="","",IF(COUNTIF(T48:Y48,"Fail")>0,1,0)) -> 0 | AC48: =IF(B48="","",0.1*Z48+0.8*AA48+0.1*AB48) -> 0 | AD48: =IF(B48="","",IF(C48="Batch 1",0.3,0.2)) -> 0.2 | AE48: =IF(B48="","",IF(AC48<=AD48,"Đạt","Không đạt")) -> Đạt | AF48: ╔══ CẢNH BÁO — KHÔNG tính lỗi: 1 tiêu chí — 2.12 (ô ghi 'Pass', tô vàng nhạt. Chưa sai kết quả, nhưng nếu job chạy chậm thì xem lại đúng các chỗ này để tối ưu) ▼ 2.12 — Build Gold từ CTE snapshot Silver, không build nhiều tầng chồng chéo • Ghi nhận: bảng bị đọc lại ở nhiều khối SELECT, xét gom thành 1 CTE: calendar ở 2 khối → Nếu cần tối ưu: Mỗi bảng Silver chỉ đọc MỘT lần, snapshot vào một CTE ở đầu script rồi dùng lại. Đọc trực tiếp cùng một bảng raw_vault ở 2 chỗ khác nhau làm lệch thời điểm dữ liệu giữa các phần của cùng một script. ╔══ CHƯA CÓ SỐ LIỆU: 1 tiêu chí — 2.7 (chưa có con số để kết luận, sẽ có sau khi UAT test; đang ghi tạm Pass — cập nhật lại ô sau khi có số) ▼ 2.7 — CASE WHEN cover đủ nhánh như job on-prem • Hiện trạng: có 4 CASE, trong đó 0 CASE không có nhánh ELSE (trả NULL âm thầm) • Hiện trạng: chưa so từng nhánh WHEN với job on-prem → Cần làm: Mở job on-prem tương ứng (DataStage DSX hoặc SQL cũ), đối chiếu từng nhánh WHEN và cả nhánh ELSE. CASE không có ELSE sẽ trả NULL âm thầm — xác nhận đó là ý muốn hay thiếu nhánh.
A49: 47 | Z49: =IF(B49="","",IF(COUNTIF(F49:G49,"Fail")>0,1,0)) | AA49: =IF(B49="","",IF(COUNTIF(H49:S49,"Fail")>0,1,0)) | AB49: =IF(B49="","",IF(COUNTIF(T49:Y49,"Fail")>0,1,0)) | AC49: =IF(B49="","",0.1*Z49+0.8*AA49+0.1*AB49) | AD49: =IF(B49="","",IF(C49="Batch 1",0.3,0.2)) | AE49: =IF(B49="","",IF(AC49<=AD49,"Đạt","Không đạt"))
A50: 48 | Z50: =IF(B50="","",IF(COUNTIF(F50:G50,"Fail")>0,1,0)) | AA50: =IF(B50="","",IF(COUNTIF(H50:S50,"Fail")>0,1,0)) | AB50: =IF(B50="","",IF(COUNTIF(T50:Y50,"Fail")>0,1,0)) | AC50: =IF(B50="","",0.1*Z50+0.8*AA50+0.1*AB50) | AD50: =IF(B50="","",IF(C50="Batch 1",0.3,0.2)) | AE50: =IF(B50="","",IF(AC50<=AD50,"Đạt","Không đạt"))
A51: 49 | Z51: =IF(B51="","",IF(COUNTIF(F51:G51,"Fail")>0,1,0)) | AA51: =IF(B51="","",IF(COUNTIF(H51:S51,"Fail")>0,1,0)) | AB51: =IF(B51="","",IF(COUNTIF(T51:Y51,"Fail")>0,1,0)) | AC51: =IF(B51="","",0.1*Z51+0.8*AA51+0.1*AB51) | AD51: =IF(B51="","",IF(C51="Batch 1",0.3,0.2)) | AE51: =IF(B51="","",IF(AC51<=AD51,"Đạt","Không đạt"))
A52: 50 | Z52: =IF(B52="","",IF(COUNTIF(F52:G52,"Fail")>0,1,0)) | AA52: =IF(B52="","",IF(COUNTIF(H52:S52,"Fail")>0,1,0)) | AB52: =IF(B52="","",IF(COUNTIF(T52:Y52,"Fail")>0,1,0)) | AC52: =IF(B52="","",0.1*Z52+0.8*AA52+0.1*AB52) | AD52: =IF(B52="","",IF(C52="Batch 1",0.3,0.2)) | AE52: =IF(B52="","",IF(AC52<=AD52,"Đạt","Không đạt"))
A53: 51 | Z53: =IF(B53="","",IF(COUNTIF(F53:G53,"Fail")>0,1,0)) | AA53: =IF(B53="","",IF(COUNTIF(H53:S53,"Fail")>0,1,0)) | AB53: =IF(B53="","",IF(COUNTIF(T53:Y53,"Fail")>0,1,0)) | AC53: =IF(B53="","",0.1*Z53+0.8*AA53+0.1*AB53) | AD53: =IF(B53="","",IF(C53="Batch 1",0.3,0.2)) | AE53: =IF(B53="","",IF(AC53<=AD53,"Đạt","Không đạt"))
A54: 52 | Z54: =IF(B54="","",IF(COUNTIF(F54:G54,"Fail")>0,1,0)) | AA54: =IF(B54="","",IF(COUNTIF(H54:S54,"Fail")>0,1,0)) | AB54: =IF(B54="","",IF(COUNTIF(T54:Y54,"Fail")>0,1,0)) | AC54: =IF(B54="","",0.1*Z54+0.8*AA54+0.1*AB54) | AD54: =IF(B54="","",IF(C54="Batch 1",0.3,0.2)) | AE54: =IF(B54="","",IF(AC54<=AD54,"Đạt","Không đạt"))
A55: 53 | Z55: =IF(B55="","",IF(COUNTIF(F55:G55,"Fail")>0,1,0)) | AA55: =IF(B55="","",IF(COUNTIF(H55:S55,"Fail")>0,1,0)) | AB55: =IF(B55="","",IF(COUNTIF(T55:Y55,"Fail")>0,1,0)) | AC55: =IF(B55="","",0.1*Z55+0.8*AA55+0.1*AB55) | AD55: =IF(B55="","",IF(C55="Batch 1",0.3,0.2)) | AE55: =IF(B55="","",IF(AC55<=AD55,"Đạt","Không đạt"))
A56: 54 | Z56: =IF(B56="","",IF(COUNTIF(F56:G56,"Fail")>0,1,0)) | AA56: =IF(B56="","",IF(COUNTIF(H56:S56,"Fail")>0,1,0)) | AB56: =IF(B56="","",IF(COUNTIF(T56:Y56,"Fail")>0,1,0)) | AC56: =IF(B56="","",0.1*Z56+0.8*AA56+0.1*AB56) | AD56: =IF(B56="","",IF(C56="Batch 1",0.3,0.2)) | AE56: =IF(B56="","",IF(AC56<=AD56,"Đạt","Không đạt"))
A57: 55 | Z57: =IF(B57="","",IF(COUNTIF(F57:G57,"Fail")>0,1,0)) | AA57: =IF(B57="","",IF(COUNTIF(H57:S57,"Fail")>0,1,0)) | AB57: =IF(B57="","",IF(COUNTIF(T57:Y57,"Fail")>0,1,0)) | AC57: =IF(B57="","",0.1*Z57+0.8*AA57+0.1*AB57) | AD57: =IF(B57="","",IF(C57="Batch 1",0.3,0.2)) | AE57: =IF(B57="","",IF(AC57<=AD57,"Đạt","Không đạt"))
A58: 56 | Z58: =IF(B58="","",IF(COUNTIF(F58:G58,"Fail")>0,1,0)) | AA58: =IF(B58="","",IF(COUNTIF(H58:S58,"Fail")>0,1,0)) | AB58: =IF(B58="","",IF(COUNTIF(T58:Y58,"Fail")>0,1,0)) | AC58: =IF(B58="","",0.1*Z58+0.8*AA58+0.1*AB58) | AD58: =IF(B58="","",IF(C58="Batch 1",0.3,0.2)) | AE58: =IF(B58="","",IF(AC58<=AD58,"Đạt","Không đạt"))
A59: 57 | Z59: =IF(B59="","",IF(COUNTIF(F59:G59,"Fail")>0,1,0)) | AA59: =IF(B59="","",IF(COUNTIF(H59:S59,"Fail")>0,1,0)) | AB59: =IF(B59="","",IF(COUNTIF(T59:Y59,"Fail")>0,1,0)) | AC59: =IF(B59="","",0.1*Z59+0.8*AA59+0.1*AB59) | AD59: =IF(B59="","",IF(C59="Batch 1",0.3,0.2)) | AE59: =IF(B59="","",IF(AC59<=AD59,"Đạt","Không đạt"))
A60: 58 | Z60: =IF(B60="","",IF(COUNTIF(F60:G60,"Fail")>0,1,0)) | AA60: =IF(B60="","",IF(COUNTIF(H60:S60,"Fail")>0,1,0)) | AB60: =IF(B60="","",IF(COUNTIF(T60:Y60,"Fail")>0,1,0)) | AC60: =IF(B60="","",0.1*Z60+0.8*AA60+0.1*AB60) | AD60: =IF(B60="","",IF(C60="Batch 1",0.3,0.2)) | AE60: =IF(B60="","",IF(AC60<=AD60,"Đạt","Không đạt"))

Sheet Tổng hợp Dashboard
B2: TỔNG HỢP KẾT QUẢ REVIEW CODE THEO BATCH – ZONE C OCB
B4: Batch | C4: Ngưỡng lỗi cho phép | D4: Số bảng đã review | E4: Số bảng Đạt | F4: Số bảng Không đạt | G4: Tỷ lệ lỗi bình quân | H4: Tỷ lệ bảng Không đạt | I4: Kết luận Batch
